Workbook

Sheet Tracker
B2: Marketing Expenses Summary by Activity
B3: YTD Apr 2026
B5: Summary by Activity
D7: =B3 -> YTD Apr 2026 | K7: Budget 2025 | N7: Variance | Q7: FY Budget Utilization | T7: Mix %
B8: Activity | D8: Spend | E8: Committed | F8: Total Committed | H8: Y2024A | K8: =B3 -> YTD Apr 2026 | L8: Full Year | N8: vs. YTD | O8: vs. Full Year | Q8: =B3 -> YTD Apr 2026 | R8: Total Committed | T8: Total Committed Mix % | U8: FY Budget Mix %
B9: Outdoor Advertisement | D9: =SUMIFS('Activity & Sub Activity'!D:D,'Activity & Sub Activity'!$A:$A,$B9) -> 8415075 | E9: =SUMIFS('Activity & Sub Activity'!E:E,'Activity & Sub Activity'!$A:$A,$B9) -> 0 | F9: =SUM(D9:E9) -> 8415075 | H9: 23981254 | K9: =SUMIFS('Y2025B by Activities'!D:D,'Y2025B by Activities'!B:B,B9) -> 9000000 | L9: =SUMIFS('Y2025B by Activities'!C:C,'Y2025B by Activities'!B:B,B9) -> 23800000 | N9: =K9-D9 -> 584925 | O9: =L9-F9 -> 15384925 | Q9: =IFERROR(D9/L9,0) -> 0.35357458 | R9: =IFERROR(F9/L9,0) -> 0.35357458 | T9: =F9/$F$46 -> 0.38690928 | U9: =L9/$L$46 -> 0.35522388
B10: Leaflet | D10: =SUMIFS('Activity & Sub Activity'!D:D,'Activity & Sub Activity'!$A:$A,$B10) -> 5393879.2 | E10: =SUMIFS('Activity & Sub Activity'!E:E,'Activity & Sub Activity'!$A:$A,$B10) -> 0 | F10: =SUM(D10:E10) -> 5393879.2 | H10: 17131252 | K10: =SUMIFS('Y2025B by Activities'!D:D,'Y2025B by Activities'!B:B,B10) -> 5100000 | L10: =SUMIFS('Y2025B by Activities'!C:C,'Y2025B by Activities'!B:B,B10) -> 12000000 | N10: =K10-D10 -> -293879.2 | O10: =L10-F10 -> 6606120.8 | Q10: =IFERROR(D10/L10,0) -> 0.44948993 | R10: =IFERROR(F10/L10,0) -> 0.44948993 | T10: =F10/$F$46 -> 0.24800039 | U10: =L10/$L$46 -> 0.17910448
B11: Brand Operation | D11: =SUMIFS('Activity & Sub Activity'!D:D,'Activity & Sub Activity'!$A:$A,$B11) -> 1476071 | E11: =SUMIFS('Activity & Sub Activity'!E:E,'Activity & Sub Activity'!$A:$A,$B11) -> 70000 | F11: =SUM(D11:E11) -> 1546071 | H11: 16362289 | K11: =SUMIFS('Y2025B by Activities'!D:D,'Y2025B by Activities'!B:B,B11) -> 2863333.3 | L11: =SUMIFS('Y2025B by Activities'!C:C,'Y2025B by Activities'!B:B,B11) -> 8590000 | N11: =K11-D11 -> 1387262.3 | O11: =L11-F11 -> 7043929 | Q11: =IFERROR(D11/L11,0) -> 0.17183597 | R11: =IFERROR(F11/L11,0) -> 0.17998498 | T11: =F11/$F$46 -> 0.071085429 | U11: =L11/$L$46 -> 0.12820895
B12: Thematic Display | D12: =SUMIFS('Activity & Sub Activity'!D:D,'Activity & Sub Activity'!$A:$A,$B12) -> 1361139.5 | E12: =SUMIFS('Activity & Sub Activity'!E:E,'Activity & Sub Activity'!$A:$A,$B12) -> 45000 | F12: =SUM(D12:E12) -> 1406139.5 | H12: 7463474.2 | K12: =SUMIFS('Y2025B by Activities'!D:D,'Y2025B by Activities'!B:B,B12) -> 1600000 | L12: =SUMIFS('Y2025B by Activities'!C:C,'Y2025B by Activities'!B:B,B12) -> 4000000 | N12: =K12-D12 -> 238860.46 | O12: =L12-F12 -> 2593860.5 | Q12: =IFERROR(D12/L12,0) -> 0.34028489 | R12: =IFERROR(F12/L12,0) -> 0.35153489 | T12: =F12/$F$46 -> 0.064651644 | U12: =L12/$L$46 -> 0.059701493
B13: Digital Media | D13: =SUMIFS('Activity & Sub Activity'!D:D,'Activity & Sub Activity'!$A:$A,$B13) -> 1629589.3 | E13: =SUMIFS('Activity & Sub Activity'!E:E,'Activity & Sub Activity'!$A:$A,$B13) -> 175000 | F13: =SUM(D13:E13) -> 1804589.3 | H13: 4496816.3 | K13: =SUMIFS('Y2025B by Activities'!D:D,'Y2025B by Activities'!B:B,B13) -> 1700000 | L13: =SUMIFS('Y2025B by Activities'!C:C,'Y2025B by Activities'!B:B,B13) -> 3700000 | N13: =K13-D13 -> 70410.7 | O13: =L13-F13 -> 1895410.7 | Q13: =IFERROR(D13/L13,0) -> 0.44042954 | R13: =IFERROR(F13/L13,0) -> 0.48772684 | T13: =F13/$F$46 -> 0.082971612 | U13: =L13/$L$46 -> 0.055223881
B14: Communication Channel | D14: =SUMIFS('Activity & Sub Activity'!D:D,'Activity & Sub Activity'!$A:$A,$B14) -> 725520.83 | E14: =SUMIFS('Activity & Sub Activity'!E:E,'Activity & Sub Activity'!$A:$A,$B14) -> 200000 | F14: =SUM(D14:E14) -> 925520.83 | H14: 5393761.2 | K14: =SUMIFS('Y2025B by Activities'!D:D,'Y2025B by Activities'!B:B,B14) -> 2136665.3 | L14: =SUMIFS('Y2025B by Activities'!C:C,'Y2025B by Activities'!B:B,B14) -> 6410000 | N14: =K14-D14 -> 1411144.5 | O14: =L14-F14 -> 5484479.2 | Q14: =IFERROR(D14/L14,0) -> 0.11318578 | R14: =IFERROR(F14/L14,0) -> 0.14438702 | T14: =F14/$F$46 -> 0.042553702 | U14: =L14/$L$46 -> 0.095671642
B15: Marketing Concepts & Visuals | D15: =SUMIFS('Activity & Sub Activity'!D:D,'Activity & Sub Activity'!$A:$A,$B15) -> 49640 | E15: =SUMIFS('Activity & Sub Activity'!E:E,'Activity & Sub Activity'!$A:$A,$B15) -> 0 | F15: =SUM(D15:E15) -> 49640 | H15: 3048088.5 | K15: =SUMIFS('Y2025B by Activities'!D:D,'Y2025B by Activities'!B:B,B15) -> 1300000 | L15: =SUMIFS('Y2025B by Activities'!C:C,'Y2025B by Activities'!B:B,B15) -> 3500000 | N15: =K15-D15 -> 1250360 | O15: =L15-F15 -> 3450360 | Q15: =IFERROR(D15/L15,0) -> 0.014182857 | R15: =IFERROR(F15/L15,0) -> 0.014182857 | T15: =F15/$F$46 -> 0.0022823536 | U15: =L15/$L$46 -> 0.052238806
B16: PR & Event Management | D16: =SUMIFS('Activity & Sub Activity'!D:D,'Activity & Sub Activity'!$A:$A,$B16) -> 102823.61 | E16: =SUMIFS('Activity & Sub Activity'!E:E,'Activity & Sub Activity'!$A:$A,$B16) -> 45000 | F16: =SUM(D16:E16) -> 147823.61 | H16: 3027354.2 | K16: =SUMIFS('Y2025B by Activities'!D:D,'Y2025B by Activities'!B:B,B16) -> 291666 | L16: =SUMIFS('Y2025B by Activities'!C:C,'Y2025B by Activities'!B:B,B16) -> 1000000 | N16: =K16-D16 -> 188842.39 | O16: =L16-F16 -> 852176.39 | Q16: =IFERROR(D16/L16,0) -> 0.10282361 | R16: =IFERROR(F16/L16,0) -> 0.14782361 | T16: =F16/$F$46 -> 0.0067966508 | U16: =L16/$L$46 -> 0.014925373
B17: Customer Care | D17: =SUMIFS('Activity & Sub Activity'!D:D,'Activity & Sub Activity'!$A:$A,$B17) -> 1137741.3 | E17: =SUMIFS('Activity & Sub Activity'!E:E,'Activity & Sub Activity'!$A:$A,$B17) -> 0 | F17: =SUM(D17:E17) -> 1137741.3 | H17: 1866543 | K17: =SUMIFS('Y2025B by Activities'!D:D,'Y2025B by Activities'!B:B,B17) -> 500000 | L17: =SUMIFS('Y2025B by Activities'!C:C,'Y2025B by Activities'!B:B,B17) -> 1500000 | N17: =K17-D17 -> -637741.28 | O17: =L17-F17 -> 362258.72 | Q17: =IFERROR(D17/L17,0) -> 0.75849419 | R17: =IFERROR(F17/L17,0) -> 0.75849419 | T17: =F17/$F$46 -> 0.052311198 | U17: =L17/$L$46 -> 0.02238806
B18: Influencer | D18: =SUMIFS('Activity & Sub Activity'!D:D,'Activity & Sub Activity'!$A:$A,$B18) -> 379805 | E18: =SUMIFS('Activity & Sub Activity'!E:E,'Activity & Sub Activity'!$A:$A,$B18) -> 25000 | F18: =SUM(D18:E18) -> 404805 | H18: 1545671 | K18: =SUMIFS('Y2025B by Activities'!D:D,'Y2025B by Activities'!B:B,B18) -> 700000 | L18: =SUMIFS('Y2025B by Activities'!C:C,'Y2025B by Activities'!B:B,B18) -> 1500000 | N18: =K18-D18 -> 320195 | O18: =L18-F18 -> 1095195 | Q18: =IFERROR(D18/L18,0) -> 0.25320333 | R18: =IFERROR(F18/L18,0) -> 0.26987 | T18: =F18/$F$46 -> 0.01861217 | U18: =L18/$L$46 -> 0.02238806
B19: Research and Insights | D19: =SUMIFS('Activity & Sub Activity'!D:D,'Activity & Sub Activity'!$A:$A,$B19) -> 488193.75 | E19: =SUMIFS('Activity & Sub Activity'!E:E,'Activity & Sub Activity'!$A:$A,$B19) -> 30000 | F19: =SUM(D19:E19) -> 518193.75 | H19: 1081405.5 | K19: =SUMIFS('Y2025B by Activities'!D:D,'Y2025B by Activities'!B:B,B19) -> 500000 | L19: =SUMIFS('Y2025B by Activities'!C:C,'Y2025B by Activities'!B:B,B19) -> 1000000 | N19: =K19-D19 -> 11806.25 | O19: =L19-F19 -> 481806.25 | Q19: =IFERROR(D19/L19,0) -> 0.48819375 | R19: =IFERROR(F19/L19,0) -> 0.51819375 | T19: =F19/$F$46 -> 0.023825571 | U19: =L19/$L$46 -> 0.014925373
B20: CRM & Loyalty | D20: =SUMIFS('Activity & Sub Activity'!D:D,'Activity & Sub Activity'!$A:$A,$B20) -> 0 | E20: =SUMIFS('Activity & Sub Activity'!E:E,'Activity & Sub Activity'!$A:$A,$B20) -> 0 | F20: =SUM(D20:E20) -> 0 | H20: 701475 | K20: =SUMIFS('Y2025B by Activities'!D:D,'Y2025B by Activities'!B:B,B20) -> 0 | L20: =SUMIFS('Y2025B by Activities'!C:C,'Y2025B by Activities'!B:B,B20) -> 0 | N20: =K20-D20 -> 0 | O20: =L20-F20 -> 0 | Q20: =IFERROR(D20/L20,0) -> 0 | R20: =IFERROR(F20/L20,0) -> 0 | T20: =F20/$F$46 -> 0 | U20: =L20/$L$46 -> 0
... B22: Concept & Artwork | D22: =SUMIFS('Activity & Sub Activity'!D:D,'Activity & Sub Activity'!$A:$A,$B22) -> 0 | E22: =SUMIFS('Activity & Sub Activity'!E:E,'Activity & Sub Activity'!$A:$A,$B22) -> 0 | F22: =SUM(D22:E22) -> 0 | H22: 943645.62 | K22: =SUMIFS('Y2025B by Activities'!D:D,'Y2025B by Activities'!B:B,B22) -> 0 | L22: =SUMIFS('Y2025B by Activities'!C:C,'Y2025B by Activities'!B:B,B22) -> 0 | N22: =K22-D22 -> 0 | O22: =L22-F22 -> 0 | Q22: =IFERROR(D22/L22,0) -> 0 | R22: =IFERROR(F22/L22,0) -> 0 | T22: =F22/$F$46 -> 0 | U22: =L22/$L$46 -> 0
B23: Total | D23: =SUBTOTAL(9,D9:D22) -> 21159479 | E23: =SUBTOTAL(9,E9:E22) -> 590000 | F23: =SUBTOTAL(9,F9:F22) -> 21749479 | H23: =SUBTOTAL(9,H9:H22) -> 87467162 | K23: =SUBTOTAL(9,K9:K22) -> 25691665 | L23: =SUBTOTAL(9,L9:L22) -> 67000000 | N23: =SUBTOTAL(9,N9:N22) -> 4532186.1 | O23: =SUBTOTAL(9,O9:O22) -> 45250521 | Q23: =IFERROR(D23/L23,0) -> 0.31581311 | R23: =IFERROR(F23/L23,0) -> 0.32461908 | T23: =F23/$F$46 -> 1 | U23: =L23/$L$46 -> 1
B25: Reclass / Reversal | D25: 0 | E25: =E23-'Activity & Sub Activity'!E106 -> 0 | F25: =SUM(D25:E25) -> 0 | H25: 0 | K25: 0 | L25: 0 | N25: =K25-D25 -> 0 | O25: =L25-F25 -> 0 | Q25: =IFERROR(D25/L25,0) -> 0 | R25: =IFERROR(F25/L25,0) -> 0 | T25: 0 | U25: 0
B26: Summary by Activity Items
K28: Budget 2024 | N28: Var
B29: Outdoor | D29: Spend | E29: Committed | K29: YTD | L29: Full Year | N29: vs YTD | O29: vs Full Year
B30: Every Day lowest price
B31: Saudi Roshen League
K37: Budget 2024 | N37: Var
B38: Leaflet | D38: Spend | E38: Committed | K38: YTD | L38: Full Year | N38: vs YTD | O38: vs Full Year
B39: Leaflet
B40: Inserts
B41: Store Opening
B46: Grand Total | D46: =D23+D25 -> 21159479 | E46: =E23+E25 -> 590000 | F46: =F23+F25 -> 21749479 | H46: =H23+H25 -> 87467162 | K46: =K23+K25 -> 25691665 | L46: =L23+L25 -> 67000000 | N46: =N23+N25 -> 4532186.1 | O46: =O23+O25 -> 45250521 | Q46: =IFERROR(D46/L46,0) -> 0.31581311 | R46: =IFERROR(F46/L46,0) -> 0.32461908 | T46: =T23 -> 1 | U46: =U23 -> 1

Sheet Activity & Sub Activity
B2: Marketing Expense by Activity
B3: YTD Apr 2026
B5: Activity | C5: Sub Activity | D5: YTD Apr Actual | E5: Committed | F5: Total Committed | G5: YTD Apr Budget | H5: Y2025B | I5: vs YTD | J5: vs Full Year
A6: Outdoor Advertisement | B6: Outdoor Advertisement | C6: Full Year Outdoor Media Plan | D6: 8415075 | E6: 0 | F6: =D6+E6 -> 8415075 | G6: 0 | H6: 0 | I6: 0 | J6: 0
A7: Outdoor Advertisement | C7: Budget Y2025 | D7: 0 | E7: 0 | F7: =D7+E7 -> 0 | G7: =VLOOKUP(A7,'Y2025B by Activities'!B:D,3,0) -> 9000000 | H7: =VLOOKUP(A7,'Y2025B by Activities'!B:C,2,0) -> 23800000 | I7: 0 | J7: 0
B8: Outdoor Advertisement Total | D8: =SUBTOTAL(9,D6:D7) -> 8415075 | E8: =SUBTOTAL(9,E6:E7) -> 0 | F8: =SUBTOTAL(9,F6:F7) -> 8415075 | G8: =SUBTOTAL(9,G6:G7) -> 9000000 | H8: =SUBTOTAL(9,H6:H7) -> 23800000 | I8: =G8-D8 -> 584925 | J8: =H8-F8 -> 15384925
A9: Brand Operation | B9: Brand Operation | C9: Retail Leaders Circle Summit | D9: 616719 | E9: 0 | F9: =D9+E9 -> 616719 | G9: 0 | H9: 0 | I9: 0 | J9: 0
A10: Brand Operation | C10: PACE Event | D10: 348870 | E10: 20000 | F10: =D10+E10 -> 368870 | G10: 0 | H10: 0 | I10: 0 | J10: 0
A11: Brand Operation | C11: Brand Revamp Event | D11: 214771.5 | E11: 0 | F11: =D11+E11 -> 214771.5 | G11: 0 | H11: 0 | I11: 0 | J11: 0
A12: Brand Operation | C12: Best Value Testimonial Video | D12: 136000 | E12: 0 | F12: =D12+E12 -> 136000
A13: Brand Operation | C13: Fawazeer Prizes | D13: 100000 | E13: 50000 | F13: =D13+E13 -> 150000
A14: Brand Operation | C14: Sallati Cards | D14: 45600 | E14: 0 | F14: =D14+E14 -> 45600
A15: Brand Operation | C15: Al Raka Mall Event | D15: 15000 | E15: 0 | F15: =D15+E15 -> 15000 | G15: 0 | H15: 0 | I15: 0 | J15: 0
A16: Brand Operation | C16: abc Caravan | D16: 1160.5 | E16: 0 | F16: =D16+E16 -> 1160.5 | G16: 0 | H16: 0 | I16: 0 | J16: 0
A17: Brand Operation | C17: abc Riyadh Season Station | D17: -2050 | E17: 0 | F17: =D17+E17 -> -2050 | G17: 0 | H17: 0 | I17: 0 | J17: 0
A18: Brand Operation | C18: Budget Y2025 | D18: 0 | E18: 0 | F18: =D18+E18 -> 0 | G18: =VLOOKUP(A18,'Y2025B by Activities'!B:D,3,0) -> 2863333.3 | H18: =VLOOKUP(A18,'Y2025B by Activities'!B:C,2,0) -> 8590000 | I18: 0 | J18: 0
B19: Brand Operation Total | D19: =SUBTOTAL(9,D9:D18) -> 1476071 | E19: 0 | F19: =SUBTOTAL(9,F9:F18) -> 1546071 | G19: =SUBTOTAL(9,G9:G18) -> 2863333.3 | H19: =SUBTOTAL(9,H9:H18) -> 8590000 | I19: =G19-D19 -> 1387262.3 | J19: =H19-F19 -> 7043929
A20: Communication Channel | B20: Communication Channel | C20: WhatsApp Communication | D20: 725520.83 | E20: 200000 | F20: =D20+E20 -> 925520.83 | G20: 0 | H20: 0 | I20: 0 | J20: 0
A21: Communication Channel | C21: Budget Y2025 | D21: 0 | E21: 0 | F21: =D21+E21 -> 0 | G21: =VLOOKUP(A21,'Y2025B by Activities'!B:D,3,0) -> 2136665.3 | H21: =VLOOKUP(A21,'Y2025B by Activities'!B:C,2,0) -> 6410000 | I21: 0 | J21: 0
B22: Communication Channel Total | D22: =SUBTOTAL(9,D20:D21) -> 725520.83 | E22: 0 | F22: =SUBTOTAL(9,F20:F21) -> 925520.83 | G22: =SUBTOTAL(9,G20:G21) -> 2136665.3 | H22: =SUBTOTAL(9,H20:H21) -> 6410000 | I22: =G22-D22 -> 1411144.5 | J22: =H22-F22 -> 5484479.2
A23: Leaflet | B23: Leaflet | C23: Leaflet | D23: 5331129.2 | E23: 0 | F23: =D23+E23 -> 5331129.2 | G23: 0 | H23: 0 | I23: 0 | J23: 0
A24: Leaflet | C24: Store Opening | D24: 39800 | E24: 0 | F24: =D24+E24 -> 39800 | G24: 0 | H24: 0 | I24: 0 | J24: 0
A25: Leaflet | C25: Inserts | D25: 22950 | E25: 0 | F25: =D25+E25 -> 22950 | G25: 0 | H25: 0 | I25: 0 | J25: 0
A26: Leaflet | C26: Budget Y2025 | D26: 0 | E26: 0 | F26: =D26+E26 -> 0 | G26: =VLOOKUP(A26,'Y2025B by Activities'!B:D,3,0) -> 5100000 | H26: =VLOOKUP(A26,'Y2025B by Activities'!B:C,2,0) -> 12000000 | I26: 0 | J26: 0
B27: Leaflet Total | D27: =SUBTOTAL(9,D23:D26) -> 5393879.2 | E27: 0 | F27: =SUBTOTAL(9,F23:F26) -> 5393879.2 | G27: =SUBTOTAL(9,G23:G26) -> 5100000 | H27: =SUBTOTAL(9,H23:H26) -> 12000000 | I27: =G27-D27 -> -293879.2 | J27: =H27-F27 -> 6606120.8
A28: Digital Media | B28: Digital Media | C28: Ramadan | D28: 799200 | E28: 0 | F28: =D28+E28 -> 799200 | G28: 0 | H28: 0 | I28: 0 | J28: 0
A29: Digital Media | C29: Summer Campaign | D29: 335200 | E29: 0 | F29: =D29+E29 -> 335200 | G29: 0 | H29: 0 | I29: 0 | J29: 0
A30: Digital Media | C30: Social Media Scope | D30: 208566.67 | E30: 0 | F30: =D30+E30 -> 208566.67 | G30: 0 | H30: 0 | I30: 0 | J30: 0
A31: Digital Media | C31: Store Opening | D31: 68900 | E31: 100000 | F31: =D31+E31 -> 168900 | G31: 0 | H31: 0 | I31: 0 | J31: 0
A32: Digital Media | C32: Riyadh Chocolate Event | D32: 64800 | E32: 0 | F32: =D32+E32 -> 64800 | G32: 0 | H32: 0 | I32: 0 | J32: 0
A33: Digital Media | C33: Stores Reopening | D33: 30723 | E33: 0 | F33: =D33+E33 -> 30723 | G33: 0 | H33: 0 | I33: 0 | J33: 0
A34: Digital Media | C34: Makkah Store | D34: 23500 | E34: 0 | F34: =D34+E34 -> 23500 | G34: 0 | H34: 0 | I34: 0 | J34: 0
A35: Digital Media | C35: Digital Media | D35: 18789.63 | E35: 75000 | F35: =D35+E35 -> 93789.63 | G35: 0 | H35: 0 | I35: 0 | J35: 0
A36: Digital Media | C36: Mango | D36: 16500 | E36: 0 | F36: =D36+E36 -> 16500 | G36: 0 | H36: 0 | I36: 0 | J36: 0
A37: Digital Media | C37: Qarqean Campaign Media Plan | D37: 16200 | E37: 0 | F37: =D37+E37 -> 16200 | G37: 0 | H37: 0 | I37: 0 | J37: 0
A38: Digital Media | C38: Inhouse Bakery Event | D38: 13860 | E38: 0 | F38: =D38+E38 -> 13860 | G38: 0 | H38: 0 | I38: 0 | J38: 0
A39: Digital Media | C39: Social Media | D39: 10800 | E39: 0 | F39: =D39+E39 -> 10800 | G39: 0 | H39: 0 | I39: 0 | J39: 0
A40: Digital Media | C40: Agency Fees | D40: 8550 | E40: 0 | F40: =D40+E40 -> 8550 | G40: 0 | H40: 0 | I40: 0 | J40: 0
... A44: Digital Media | C44: Beauty Event | D44: 1500 | E44: 0 | F44: =D44+E44 -> 1500 | G44: 0 | H44: 0 | I44: 0 | J44: 0
A45: Digital Media | C45: Budget Y2025 | D45: 0 | E45: 0 | F45: =D45+E45 -> 0 | G45: =VLOOKUP(A45,'Y2025B by Activities'!B:D,3,0) -> 1700000 | H45: =VLOOKUP(A45,'Y2025B by Activities'!B:C,2,0) -> 3700000 | I45: 0 | J45: 0
...

Sheet Leaflet
B2: Leaflet by Month | J2: Leaflet by Type
B4: Activity | C4: Week | D4: Jan | E4: Feb | F4: Mar | G4: Apr | H4: Total | J4: Activity | K4: Week | L4: Leaflet | M4: Inserts | N4: Store Opening | O4: Total
B5: Leaflet | C5: 1 | D5: 243598.77 | E5: 0 | F5: 0 | G5: 0 | H5: =SUM(D5:G5) -> 243598.77 | J5: Leaflet | K5: 1 | L5: 235923.77 | M5: 7675 | N5: 0 | O5: =SUM(L5:N5) -> 243598.77
C6: 2 | D6: 243843.57 | E6: 705087.6 | F6: 0 | G6: 0 | H6: =SUM(D6:G6) -> 948931.17 | K6: 2 | L6: 940131.17 | M6: 8800 | N6: 0 | O6: =SUM(L6:N6) -> 948931.17
C7: 5 | D7: 0 | E7: 396671.17 | F7: 0 | G7: 0 | H7: =SUM(D7:G7) -> 396671.17 | K7: 5 | L7: 396671.17 | M7: 0 | N7: 0 | O7: =SUM(L7:N7) -> 396671.17
C8: 6 | D8: 0 | E8: 396671.17 | F8: 0 | G8: 0 | H8: =SUM(D8:G8) -> 396671.17 | K8: 6 | L8: 396671.17 | M8: 0 | N8: 0 | O8: =SUM(L8:N8) -> 396671.17
C9: 7 | D9: 0 | E9: 383697.02 | F9: 0 | G9: 0 | H9: =SUM(D9:G9) -> 383697.02 | K9: 7 | L9: 383697.02 | M9: 0 | N9: 0 | O9: =SUM(L9:N9) -> 383697.02
C10: 8 | D10: 0 | E10: 374505.39 | F10: 0 | G10: 0 | H10: =SUM(D10:G10) -> 374505.39 | K10: 8 | L10: 374505.39 | M10: 0 | N10: 0 | O10: =SUM(L10:N10) -> 374505.39
C11: 9 | D11: 0 | E11: 367144.26 | F11: 73816.64 | G11: 0 | H11: =SUM(D11:G11) -> 440960.9 | K11: 9 | L11: 440960.9 | M11: 0 | N11: 0 | O11: =SUM(L11:N11) -> 440960.9
C12: 10 | D12: 0 | E12: 0 | F12: 194910.98 | G12: 0 | H12: =SUM(D12:G12) -> 194910.98 | K12: 10 | L12: 194910.98 | M12: 0 | N12: 0 | O12: =SUM(L12:N12) -> 194910.98
C13: 11 | D13: 0 | E13: 0 | F13: 194910.97 | G13: 0 | H13: =SUM(D13:G13) -> 194910.97 | K13: 11 | L13: 194910.97 | M13: 0 | N13: 0 | O13: =SUM(L13:N13) -> 194910.97
C14: 12 | D14: 0 | E14: 0 | F14: 338548 | G14: -61886.16 | H14: =SUM(D14:G14) -> 276661.84 | K14: 12 | L14: 276661.84 | M14: 0 | N14: 0 | O14: =SUM(L14:N14) -> 276661.84
C15: 13 | D15: 0 | E15: 0 | F15: 0 | G15: 236987.34 | H15: =SUM(D15:G15) -> 236987.34 | K15: 13 | L15: 236987.34 | M15: 0 | N15: 0 | O15: =SUM(L15:N15) -> 236987.34
C16: 14 | D16: 0 | E16: 0 | F16: 0 | G16: 231343.47 | H16: =SUM(D16:G16) -> 231343.47 | K16: 14 | L16: 231343.47 | M16: 0 | N16: 0 | O16: =SUM(L16:N16) -> 231343.47
C17: 15 | D17: 0 | E17: 0 | F17: 0 | G17: 196277.86 | H17: =SUM(D17:G17) -> 196277.86 | K17: 15 | L17: 196277.86 | M17: 0 | N17: 0 | O17: =SUM(L17:N17) -> 196277.86
... C24: 0 | D24: 0 | E24: 0 | F24: 482331.36 | G24: 0 | H24: =SUM(D24:G24) -> 482331.36 | K24: 0 | L24: 482331.36 | M24: 0 | N24: 0 | O24: =SUM(L24:N24) -> 482331.36
B25: Total | E25: =SUBTOTAL(9,E5:E24) -> 2591776.6 | F25: =SUBTOTAL(9,F5:F24) -> 1307843 | G25: =SUBTOTAL(9,G5:G24) -> 1006817.3 | H25: =SUBTOTAL(9,H5:H24) -> 5393879.2 | J25: Total | L25: =SUBTOTAL(9,L5:L24) -> 5331129.2 | M25: =SUBTOTAL(9,M5:M24) -> 39800 | N25: =SUBTOTAL(9,N5:N24) -> 22950 | O25: =SUBTOTAL(9,O5:O24) -> 5393879.2

Sheet Y2025B by Activities
B2: Marketing Expenses Summary by Activity
B3: Budget Y2025
B5: Summary by Activity
B7: Activity | C7: Y2025B | D7: YTD Apr | E7: Jan | F7: Feb | G7: Mar | H7: April | I7: May | J7: June | K7: July | L7: Aug | M7: Sept | N7: Oct | O7: Nov | P7: Dec | Q7: Total | R7: Owner
B8: Outdoor Advertisement | C8: 23800000 | D8: =SUM(E8:H8) -> 9000000 | E8: 2500000 | F8: 2500000 | G8: 2150000 | H8: 1850000 | I8: 1850000 | J8: 1850000 | K8: 1850000 | L8: 1850000 | M8: 1850000 | N8: 1850000 | O8: 1850000 | P8: 1850000 | Q8: =SUM(E8:P8) -> 23800000 | R8: Amr Almadani
B9: Leaflet | C9: 12000000 | D9: =SUM(E9:H9) -> 5100000 | E9: 1200000 | F9: 1500000 | G9: 1500000 | H9: 900000 | I9: 900000 | J9: 900000 | K9: 850000 | L9: 850000 | M9: 850000 | N9: 850000 | O9: 850000 | P9: 850000 | Q9: =SUM(E9:P9) -> 12000000 | R9: Amr Almadani
B10: Brand Operation | C10: 8590000 | D10: =SUM(E10:H10) -> 2863333.3 | E10: 715833.33 | F10: 715833.33 | G10: 715833.33 | H10: 715833.33 | I10: 715833.33 | J10: 715833.33 | K10: 715833.33 | L10: 715833.33 | M10: 715833.33 | N10: 715833.33 | O10: 715833.33 | P10: 715833.33 | Q10: =SUM(E10:P10) -> 8590000 | R10: Amr Almadani
B11: Thematic Display | C11: 4000000 | D11: =SUM(E11:H11) -> 1600000 | E11: 500000 | F11: 500000 | G11: 300000 | H11: 300000 | I11: 200000 | J11: 200000 | K11: 200000 | L11: 400000 | M11: 400000 | N11: 400000 | O11: 300000 | P11: 300000 | Q11: =SUM(E11:P11) -> 4000000 | R11: Amr Almadani
B12: Digital Media | C12: 3700000 | D12: =SUM(E12:H12) -> 1700000 | E12: 500000 | F12: 500000 | G12: 400000 | H12: 300000 | I12: 200000 | J12: 200000 | K12: 200000 | L12: 300000 | M12: 300000 | N12: 250000 | O12: 250000 | P12: 300000 | Q12: =SUM(E12:P12) -> 3700000 | R12: Amr Almadani
B13: Communication Channel | C13: 6410000 | D13: =SUM(E13:H13) -> 2136665.3 | E13: 534166.33 | F13: 534166.33 | G13: 534166.33 | H13: 534166.33 | I13: 534166.33 | J13: 534166.33 | K13: 534166.33 | L13: 534166.33 | M13: 534166.33 | N13: 534166.33 | O13: 534166.37 | P13: 534170.33 | Q13: =SUM(E13:P13) -> 6410000 | R13: Ahmed Gabil
B14: Marketing Concepts & Visuals | C14: 3500000 | D14: =SUM(E14:H14) -> 1300000 | E14: 400000 | F14: 400000 | G14: 250000 | H14: 250000 | I14: 250000 | J14: 250000 | K14: 250000 | L14: 250000 | M14: 250000 | N14: 250000 | O14: 350000 | P14: 350000 | Q14: =SUM(E14:P14) -> 3500000 | R14: Amr Almadani
B15: PR & Event Management | C15: 1000000 | D15: =SUM(E15:H15) -> 291666 | E15: 0 | F15: 83333 | G15: 125000 | H15: 83333 | I15: 0 | J15: 208333 | K15: 0 | L15: 83333 | M15: 125000 | N15: 83335 | O15: 0 | P15: 208333 | Q15: =SUM(E15:P15) -> 1000000 | R15: Ahmed Gabil
B16: Customer Care | C16: 1500000 | D16: =SUM(E16:H16) -> 500000 | E16: 125000 | F16: 125000 | G16: 125000 | H16: 125000 | I16: 125000 | J16: 125000 | K16: 125000 | L16: 125000 | M16: 125000 | N16: 125000 | O16: 125000 | P16: 125000 | Q16: =SUM(E16:P16) -> 1500000 | R16: Ahmed Gabil
B17: Influencer | C17: 1500000 | D17: =SUM(E17:H17) -> 700000 | E17: 200000 | F17: 250000 | G17: 150000 | H17: 100000 | I17: 75000 | J17: 75000 | K17: 100000 | L17: 200000 | M17: 75000 | N17: 75000 | O17: 100000 | P17: 100000 | Q17: =SUM(E17:P17) -> 1500000 | R17: Amr Almadani
B18: Research and Insights | C18: 1000000 | D18: =SUM(E18:H18) -> 500000 | E18: 250000 | F18: 0 | G18: 0 | H18: 250000 | I18: 0 | J18: 0 | K18: 250000 | L18: 0 | M18: 0 | N18: 250000 | O18: 0 | P18: 0 | Q18: =SUM(E18:P18) -> 1000000 | R18: Ahmed Gabil
B19: CRM & Loyalty | C19: 0 | D19: =SUM(E19:H19) -> 0 | E19: 0 | F19: 0 | G19: 0 | H19: 0 | I19: 0 | J19: 0 | K19: 0 | L19: 0 | M19: 0 | N19: 0 | O19: 0 | P19: 0 | Q19: =SUM(E19:P19) -> 0 | R19: Ahmed Gabil
... B21: Concept & Artwork | C21: 0 | D21: =SUM(E21:H21) -> 0 | E21: 0 | F21: 0 | G21: 0 | H21: 0 | I21: 0 | J21: 0 | K21: 0 | L21: 0 | M21: 0 | N21: 0 | O21: 0 | P21: 0 | Q21: =SUM(E21:P21) -> 0 | R21: Amr Almadani
B22: Total | C22: =SUM(C8:C21) -> 67000000 | D22: =SUM(D8:D21) -> 25691665 | E22: =SUM(E8:E21) -> 6924999.7 | F22: =SUM(F8:F21) -> 7108332.7 | G22: =SUM(G8:G21) -> 6249999.7 | H22: =SUM(H8:H21) -> 5408332.7 | I22: =SUM(I8:I21) -> 4849999.7 | J22: =SUM(J8:J21) -> 5058332.7 | ... Q22: =SUM(Q8:Q21) -> 67000000
