Workbook
Name CaseSelection: #REF!
Name CountryCode: "OFFSET($B$1,0,0,COUNT($B:$B),1)"
Name EconList: #REF!
Name ExistGuideDatabase: #REF!
Name ExistingGuidanceStart: #REF!
Name Header2: #REF!
Name NewGuidanceStart: #REF!
Name NewLease1: #REF!
Name NewLease2: #REF!
Name NewLease3: #REF!
Name NewLease4: #REF!
Name NewLease5: #REF!
Name NewLease6: #REF!
Name SelectedCase: #REF!
Name Size: IF(#REF!<2500,TRUE,FALSE)
Name Tolerance: #REF!
Name Tolerancex: #REF!

Sheet Summary Budget Mapping
B2: IT Projects CAPEX Summary
B3: =Month!C4 -> 46053
B5: Summary by Projects
D7: Y2024 | J7: Y2025 | P7: Total
B8: Project | D8: CarryForward | E8: Spend | F8: Committed | G8: Total Commitment | H8: Remaining | J8: Budget | K8: Spend | L8: Committed | M8: Total Commitment | N8: Remaining | P8: Budget | Q8: Spend | R8: Committed | S8: Total Commitment | T8: Remaining
B9: Point of Sales | D9: 1043610.9 | E9: =SUMIFS('PR Data'!$T:$T,'PR Data'!$P:$P,$B9,'PR Data'!$O:$O,$D$7) -> 0 | F9: =SUMIFS('PR Data'!$V:$V,'PR Data'!$P:$P,$B9,'PR Data'!$O:$O,$D$7) -> 0 | G9: =SUM(E9:F9) -> 0 | H9: =D9-G9 -> 1043610.9 | J9: 45020000 | K9: =SUMIFS('PR Data'!$T:$T,'PR Data'!$P:$P,$B9,'PR Data'!$O:$O,$J$7) -> 0 | L9: =SUMIFS('PR Data'!$V:$V,'PR Data'!$P:$P,$B9,'PR Data'!$O:$O,$J$7) -> 45003001 | M9: =SUM(K9:L9) -> 45003001 | N9: =J9-M9 -> 16999 | P9: =D9+J9 -> 46063611 | Q9: =E9+K9 -> 0 | R9: =F9+L9 -> 45003001 | S9: =G9+M9 -> 45003001 | T9: =P9-S9 -> 1060609.9
B10: Ocado | D10: 0 | E10: =SUMIFS('PR Data'!$T:$T,'PR Data'!$P:$P,$B10,'PR Data'!$O:$O,$D$7) -> 388922.86 | F10: =SUMIFS('PR Data'!$V:$V,'PR Data'!$P:$P,$B10,'PR Data'!$O:$O,$D$7) -> 108900 | G10: =SUM(E10:F10) -> 497822.86 | H10: =D10-G10 -> -497822.86 | J10: 22500000 | K10: =SUMIFS('PR Data'!$T:$T,'PR Data'!$P:$P,$B10,'PR Data'!$O:$O,$J$7) -> 206037.36 | L10: =SUMIFS('PR Data'!$V:$V,'PR Data'!$P:$P,$B10,'PR Data'!$O:$O,$J$7) -> 618112.07 | M10: =SUM(K10:L10) -> 824149.43 | N10: =J10-M10 -> 21675851 | P10: =D10+J10 -> 22500000 | Q10: =E10+K10 -> 594960.21 | R10: =F10+L10 -> 727012.07 | S10: =G10+M10 -> 1321972.3 | T10: =P10-S10 -> 21178028
B11: WMS (Manhattan) | D11: =(SUMIFS('PR Data'!$N:$N,'PR Data'!$P:$P,$B11,'PR Data'!$O:$O,$D$7))*1000 -> 0 | E11: =SUMIFS('PR Data'!$T:$T,'PR Data'!$P:$P,$B11,'PR Data'!$O:$O,$D$7) -> 0 | F11: =SUMIFS('PR Data'!$V:$V,'PR Data'!$P:$P,$B11,'PR Data'!$O:$O,$D$7) -> 0 | G11: =SUM(E11:F11) -> 0 | H11: =D11-G11 -> 0 | J11: 22000000 | K11: =SUMIFS('PR Data'!$T:$T,'PR Data'!$P:$P,$B11,'PR Data'!$O:$O,$J$7) -> 0 | L11: =SUMIFS('PR Data'!$V:$V,'PR Data'!$P:$P,$B11,'PR Data'!$O:$O,$J$7) -> 0 | M11: =SUM(K11:L11) -> 0 | N11: =J11-M11 -> 22000000 | P11: =D11+J11 -> 22000000 | Q11: =E11+K11 -> 0 | R11: =F11+L11 -> 0 | S11: =G11+M11 -> 0 | T11: =P11-S11 -> 22000000
B12: Wireless Infrastructure | D12: =(SUMIFS('PR Data'!$N:$N,'PR Data'!$P:$P,$B12,'PR Data'!$O:$O,$D$7))*1000 -> 0 | E12: =SUMIFS('PR Data'!$T:$T,'PR Data'!$P:$P,$B12,'PR Data'!$O:$O,$D$7) -> 0 | F12: =SUMIFS('PR Data'!$V:$V,'PR Data'!$P:$P,$B12,'PR Data'!$O:$O,$D$7) -> 0 | G12: =SUM(E12:F12) -> 0 | H12: =D12-G12 -> 0 | J12: 21000000 | K12: =SUMIFS('PR Data'!$T:$T,'PR Data'!$P:$P,$B12,'PR Data'!$O:$O,$J$7) -> 0 | L12: =SUMIFS('PR Data'!$V:$V,'PR Data'!$P:$P,$B12,'PR Data'!$O:$O,$J$7) -> 0 | M12: =SUM(K12:L12) -> 0 | N12: =J12-M12 -> 21000000 | P12: =D12+J12 -> 21000000 | Q12: =E12+K12 -> 0 | R12: =F12+L12 -> 0 | S12: =G12+M12 -> 0 | T12: =P12-S12 -> 21000000
B13: Network Operations | D13: =(SUMIFS('PR Data'!$N:$N,'PR Data'!$P:$P,$B13,'PR Data'!$O:$O,$D$7))*1000 -> 0 | E13: =SUMIFS('PR Data'!$T:$T,'PR Data'!$P:$P,$B13,'PR Data'!$O:$O,$D$7) -> 0 | F13: =SUMIFS('PR Data'!$V:$V,'PR Data'!$P:$P,$B13,'PR Data'!$O:$O,$D$7) -> 0 | G13: =SUM(E13:F13) -> 0 | H13: =D13-G13 -> 0 | J13: 10800000 | K13: =SUMIFS('PR Data'!$T:$T,'PR Data'!$P:$P,$B13,'PR Data'!$O:$O,$J$7) -> 0 | L13: =SUMIFS('PR Data'!$V:$V,'PR Data'!$P:$P,$B13,'PR Data'!$O:$O,$J$7) -> 0 | M13: =SUM(K13:L13) -> 0 | N13: =J13-M13 -> 10800000 | P13: =D13+J13 -> 10800000 | Q13: =E13+K13 -> 0 | R13: =F13+L13 -> 0 | S13: =G13+M13 -> 0 | T13: =P13-S13 -> 10800000
B14: RMS | D14: 3970125 | E14: =SUMIFS('PR Data'!$T:$T,'PR Data'!$P:$P,$B14,'PR Data'!$O:$O,$D$7) -> 0 | F14: =SUMIFS('PR Data'!$V:$V,'PR Data'!$P:$P,$B14,'PR Data'!$O:$O,$D$7) -> 3576375 | G14: =SUM(E14:F14) -> 3576375 | H14: =D14-G14 -> 393750 | J14: 4315000 | K14: =SUMIFS('PR Data'!$T:$T,'PR Data'!$P:$P,$B14,'PR Data'!$O:$O,$J$7) -> 0 | L14: =SUMIFS('PR Data'!$V:$V,'PR Data'!$P:$P,$B14,'PR Data'!$O:$O,$J$7) -> 0 | M14: =SUM(K14:L14) -> 0 | N14: =J14-M14 -> 4315000 | P14: =D14+J14 -> 8285125 | Q14: =E14+K14 -> 0 | R14: =F14+L14 -> 3576375 | S14: =G14+M14 -> 3576375 | T14: =P14-S14 -> 4708750
B15: Cube 2.0 | D15: 0 | E15: =SUMIFS('PR Data'!$T:$T,'PR Data'!$P:$P,$B15,'PR Data'!$O:$O,$D$7) -> 126195 | F15: =SUMIFS('PR Data'!$V:$V,'PR Data'!$P:$P,$B15,'PR Data'!$O:$O,$D$7) -> 6105 | G15: =SUM(E15:F15) -> 132300 | H15: =D15-G15 -> -132300 | J15: 7500000 | K15: =SUMIFS('PR Data'!$T:$T,'PR Data'!$P:$P,$B15,'PR Data'!$O:$O,$J$7) -> 3361.68 | L15: =SUMIFS('PR Data'!$V:$V,'PR Data'!$P:$P,$B15,'PR Data'!$O:$O,$J$7) -> 245015.82 | M15: =SUM(K15:L15) -> 248377.5 | N15: =J15-M15 -> 7251622.5 | P15: =D15+J15 -> 7500000 | Q15: =E15+K15 -> 129556.68 | R15: =F15+L15 -> 251120.82 | S15: =G15+M15 -> 380677.5 | T15: =P15-S15 -> 7119322.5
B16: Fusion Re-Engineering | D16: 2197500 | E16: =SUMIFS('PR Data'!$T:$T,'PR Data'!$P:$P,$B16,'PR Data'!$O:$O,$D$7) -> 281250 | F16: =SUMIFS('PR Data'!$V:$V,'PR Data'!$P:$P,$B16,'PR Data'!$O:$O,$D$7) -> 1916250 | G16: =SUM(E16:F16) -> 2197500 | H16: =D16-G16 -> 0 | J16: 4000000 | K16: =SUMIFS('PR Data'!$T:$T,'PR Data'!$P:$P,$B16,'PR Data'!$O:$O,$J$7) -> 0 | L16: =SUMIFS('PR Data'!$V:$V,'PR Data'!$P:$P,$B16,'PR Data'!$O:$O,$J$7) -> 1083662 | M16: =SUM(K16:L16) -> 1083662 | N16: =J16-M16 -> 2916338 | P16: =D16+J16 -> 6197500 | Q16: =E16+K16 -> 281250 | R16: =F16+L16 -> 2999912 | S16: =G16+M16 -> 3281162 | T16: =P16-S16 -> 2916338
B17: Relex Project | D17: 774418.39 | E17: =SUMIFS('PR Data'!$T:$T,'PR Data'!$P:$P,$B17,'PR Data'!$O:$O,$D$7) -> 77435.888 | F17: =SUMIFS('PR Data'!$V:$V,'PR Data'!$P:$P,$B17,'PR Data'!$O:$O,$D$7) -> 75000 | G17: =SUM(E17:F17) -> 152435.89 | H17: =D17-G17 -> 621982.5 | J17: 3775000 | K17: =SUMIFS('PR Data'!$T:$T,'PR Data'!$P:$P,$B17,'PR Data'!$O:$O,$J$7) -> 58125 | L17: =SUMIFS('PR Data'!$V:$V,'PR Data'!$P:$P,$B17,'PR Data'!$O:$O,$J$7) -> 0 | M17: =SUM(K17:L17) -> 58125 | N17: =J17-M17 -> 3716875 | P17: =D17+J17 -> 4549418.4 | Q17: =E17+K17 -> 135560.89 | R17: =F17+L17 -> 75000 | S17: =G17+M17 -> 210560.89 | T17: =P17-S17 -> 4338857.5
B18: Buffer 2% | D18: =(SUMIFS('PR Data'!$N:$N,'PR Data'!$P:$P,$B18,'PR Data'!$O:$O,$D$7))*1000 -> 0 | E18: =SUMIFS('PR Data'!$T:$T,'PR Data'!$P:$P,$B18,'PR Data'!$O:$O,$D$7) -> 0 | F18: =SUMIFS('PR Data'!$V:$V,'PR Data'!$P:$P,$B18,'PR Data'!$O:$O,$D$7) -> 0 | G18: =SUM(E18:F18) -> 0 | H18: =D18-G18 -> 0 | J18: 2354649.1 | K18: =SUMIFS('PR Data'!$T:$T,'PR Data'!$P:$P,$B18,'PR Data'!$O:$O,$J$7) -> 0 | L18: =SUMIFS('PR Data'!$V:$V,'PR Data'!$P:$P,$B18,'PR Data'!$O:$O,$J$7) -> 0 | M18: =SUM(K18:L18) -> 0 | N18: =J18-M18 -> 2354649.1 | P18: =D18+J18 -> 2354649.1 | Q18: =E18+K18 -> 0 | R18: =F18+L18 -> 0 | S18: =G18+M18 -> 0 | T18: =P18-S18 -> 2354649.1
B19: MDM Solution | D19: =(SUMIFS('PR Data'!$N:$N,'PR Data'!$P:$P,$B19,'PR Data'!$O:$O,$D$7))*1000 -> 0 | E19: =SUMIFS('PR Data'!$T:$T,'PR Data'!$P:$P,$B19,'PR Data'!$O:$O,$D$7) -> 0 | F19: =SUMIFS('PR Data'!$V:$V,'PR Data'!$P:$P,$B19,'PR Data'!$O:$O,$D$7) -> 0 | G19: =SUM(E19:F19) -> 0 | H19: =D19-G19 -> 0 | J19: 2200000 | K19: =SUMIFS('PR Data'!$T:$T,'PR Data'!$P:$P,$B19,'PR Data'!$O:$O,$J$7) -> 0 | L19: =SUMIFS('PR Data'!$V:$V,'PR Data'!$P:$P,$B19,'PR Data'!$O:$O,$J$7) -> 0 | M19: =SUM(K19:L19) -> 0 | N19: =J19-M19 -> 2200000 | P19: =D19+J19 -> 2200000 | Q19: =E19+K19 -> 0 | R19: =F19+L19 -> 0 | S19: =G19+M19 -> 0 | T19: =P19-S19 -> 2200000
B20: Memory Project | D20: 1775143.6 | E20: =SUMIFS('PR Data'!$T:$T,'PR Data'!$P:$P,$B20,'PR Data'!$O:$O,$D$7) -> 75930.648 | F20: =SUMIFS('PR Data'!$V:$V,'PR Data'!$P:$P,$B20,'PR Data'!$O:$O,$D$7) -> 0 | G20: =SUM(E20:F20) -> 75930.648 | H20: =D20-G20 -> 1699213 | J20: 0 | K20: =SUMIFS('PR Data'!$T:$T,'PR Data'!$P:$P,$B20,'PR Data'!$O:$O,$J$7) -> 0 | L20: =SUMIFS('PR Data'!$V:$V,'PR Data'!$P:$P,$B20,'PR Data'!$O:$O,$J$7) -> 0 | M20: =SUM(K20:L20) -> 0 | N20: =J20-M20 -> 0 | P20: =D20+J20 -> 1775143.6 | Q20: =E20+K20 -> 75930.648 | R20: =F20+L20 -> 0 | S20: =G20+M20 -> 75930.648 | T20: =P20-S20 -> 1699213
B21: HR Performance Management | D21: =(SUMIFS('PR Data'!$N:$N,'PR Data'!$P:$P,$B21,'PR Data'!$O:$O,$D$7))*1000 -> 0 | E21: =SUMIFS('PR Data'!$T:$T,'PR Data'!$P:$P,$B21,'PR Data'!$O:$O,$D$7) -> 0 | F21: =SUMIFS('PR Data'!$V:$V,'PR Data'!$P:$P,$B21,'PR Data'!$O:$O,$D$7) -> 0 | G21: =SUM(E21:F21) -> 0 | H21: =D21-G21 -> 0 | J21: 1550000 | K21: =SUMIFS('PR Data'!$T:$T,'PR Data'!$P:$P,$B21,'PR Data'!$O:$O,$J$7) -> 0 | L21: =SUMIFS('PR Data'!$V:$V,'PR Data'!$P:$P,$B21,'PR Data'!$O:$O,$J$7) -> 0 | M21: =SUM(K21:L21) -> 0 | N21: =J21-M21 -> 1550000 | P21: =D21+J21 -> 1550000 | Q21: =E21+K21 -> 0 | R21: =F21+L21 -> 0 | S21: =G21+M21 -> 0 | T21: =P21-S21 -> 1550000
B22: HCM Core | D22: 0 | E22: =SUMIFS('PR Data'!$T:$T,'PR Data'!$P:$P,$B22,'PR Data'!$O:$O,$D$7) -> 898290 | F22: =SUMIFS('PR Data'!$V:$V,'PR Data'!$P:$P,$B22,'PR Data'!$O:$O,$D$7) -> 0 | G22: =SUM(E22:F22) -> 898290 | H22: =D22-G22 -> -898290 | J22: 0 | K22: =SUMIFS('PR Data'!$T:$T,'PR Data'!$P:$P,$B22,'PR Data'!$O:$O,$J$7) -> 337762 | L22: =SUMIFS('PR Data'!$V:$V,'PR Data'!$P:$P,$B22,'PR Data'!$O:$O,$J$7) -> 285938 | M22: =SUM(K22:L22) -> 623700 | N22: =J22-M22 -> -623700 | P22: =D22+J22 -> 0 | Q22: =E22+K22 -> 1236052 | R22: =F22+L22 -> 285938 | S22: =G22+M22 -> 1521990 | T22: =P22-S22 -> -1521990
B23: Others | D23: 2834498.5 | E23: =SUMIFS('PR Data'!$T:$T,'PR Data'!$P:$P,$B23,'PR Data'!$O:$O,$D$7) -> 1707933.7 | F23: =SUMIFS('PR Data'!$V:$V,'PR Data'!$P:$P,$B23,'PR Data'!$O:$O,$D$7) -> 1996100.9 | G23: =SUM(E23:F23) -> 3704034.5 | H23: =D23-G23 -> -869536 | J23: 10572457 | K23: =SUMIFS('PR Data'!$T:$T,'PR Data'!$P:$P,$B23,'PR Data'!$O:$O,$J$7) -> 0 | L23: =SUMIFS('PR Data'!$V:$V,'PR Data'!$P:$P,$B23,'PR Data'!$O:$O,$J$7) -> 1718037.5 | M23: =SUM(K23:L23) -> 1718037.5 | N23: =J23-M23 -> 8854419.5 | P23: =D23+J23 -> 13406956 | Q23: =E23+K23 -> 1707933.7 | R23: =F23+L23 -> 3714138.4 | S23: =G23+M23 -> 5422072 | T23: =P23-S23 -> 7984883.5
D24: =SUBTOTAL(9,D9:D23) -> 12595296 | E24: =SUBTOTAL(9,E9:E23) -> 3555958.1 | F24: =SUBTOTAL(9,F9:F23) -> 7678730.9 | G24: =SUBTOTAL(9,G9:G23) -> 11234689 | H24: =SUBTOTAL(9,H9:H23) -> 1360607.6 | I24: =SUBTOTAL(9,I9:I23) -> 0 | J24: =SUBTOTAL(9,J9:J23) -> 1.5758711e+08 | K24: =SUBTOTAL(9,K9:K23) -> 605286.04 | ... T24: =SUBTOTAL(9,T9:T23) -> 1.0938866e+08
B26: Summary by Activity Items
D28: Y2024 | J28: Y2025 | P28: Total
B29: Activity Item | D29: CarryForward | E29: Spend | F29: Committed | G29: Total Commitment | H29: Remaining | J29: Budget | K29: Spend | L29: Committed | M29: Total Commitment | N29: Remaining | P29: Budget | Q29: Spend | R29: Committed | S29: Total Commitment | T29: Remaining
B30: Implementation | D30: =SUMIFS('PR Data'!$N:$N,'PR Data'!$Q:$Q,$B30,'PR Data'!$O:$O,$D$28) -> 9772915.2 | E30: =SUMIFS('PR Data'!$T:$T,'PR Data'!$Q:$Q,$B30,'PR Data'!$O:$O,$D$28) -> 3191633.1 | F30: =SUMIFS('PR Data'!$V:$V,'PR Data'!$Q:$Q,$B30,'PR Data'!$O:$O,$D$28) -> 5698700.9 | G30: =SUM(E30:F30) -> 8890333.9 | H30: =D30-G30 -> 882581.28 | J30: =SUMIFS('PR Data'!$N:$N,'PR Data'!$Q:$Q,$B30,'PR Data'!$O:$O,$J$28) -> 0 | K30: =SUMIFS('PR Data'!$T:$T,'PR Data'!$Q:$Q,$B30,'PR Data'!$O:$O,$J$28) -> 605286.04 | L30: =SUMIFS('PR Data'!$V:$V,'PR Data'!$Q:$Q,$B30,'PR Data'!$O:$O,$J$28) -> 26664124 | M30: =SUM(K30:L30) -> 27269410 | N30: =J30-M30 -> -27269410 | P30: =D30+J30 -> 9772915.2 | Q30: =E30+K30 -> 3796919.1 | R30: =F30+L30 -> 32362825 | S30: =G30+M30 -> 36159744 | T30: =P30-S30 -> -26386829
B31: Integration | D31: =SUMIFS('PR Data'!$N:$N,'PR Data'!$Q:$Q,$B31,'PR Data'!$O:$O,$D$28) -> 0 | E31: =SUMIFS('PR Data'!$T:$T,'PR Data'!$Q:$Q,$B31,'PR Data'!$O:$O,$D$28) -> 0 | F31: =SUMIFS('PR Data'!$V:$V,'PR Data'!$Q:$Q,$B31,'PR Data'!$O:$O,$D$28) -> 0 | G31: =SUM(E31:F31) -> 0 | H31: =D31-G31 -> 0 | J31: =SUMIFS('PR Data'!$N:$N,'PR Data'!$Q:$Q,$B31,'PR Data'!$O:$O,$J$28) -> 0 | K31: =SUMIFS('PR Data'!$T:$T,'PR Data'!$Q:$Q,$B31,'PR Data'!$O:$O,$J$28) -> 0 | L31: =SUMIFS('PR Data'!$V:$V,'PR Data'!$Q:$Q,$B31,'PR Data'!$O:$O,$J$28) -> 0 | M31: =SUM(K31:L31) -> 0 | N31: =J31-M31 -> 0 | P31: =D31+J31 -> 0 | Q31: =E31+K31 -> 0 | R31: =F31+L31 -> 0 | S31: =G31+M31 -> 0 | T31: =P31-S31 -> 0
B32: Consultancy | D32: =SUMIFS('PR Data'!$N:$N,'PR Data'!$Q:$Q,$B32,'PR Data'!$O:$O,$D$28) -> 310750 | E32: =SUMIFS('PR Data'!$T:$T,'PR Data'!$Q:$Q,$B32,'PR Data'!$O:$O,$D$28) -> 3750 | F32: =SUMIFS('PR Data'!$V:$V,'PR Data'!$Q:$Q,$B32,'PR Data'!$O:$O,$D$28) -> 307000 | G32: =SUM(E32:F32) -> 310750 | H32: =D32-G32 -> 0 | J32: =SUMIFS('PR Data'!$N:$N,'PR Data'!$Q:$Q,$B32,'PR Data'!$O:$O,$J$28) -> 0 | K32: =SUMIFS('PR Data'!$T:$T,'PR Data'!$Q:$Q,$B32,'PR Data'!$O:$O,$J$28) -> 0 | L32: =SUMIFS('PR Data'!$V:$V,'PR Data'!$Q:$Q,$B32,'PR Data'!$O:$O,$J$28) -> 0 | M32: =SUM(K32:L32) -> 0 | N32: =J32-M32 -> 0 | P32: =D32+J32 -> 310750 | Q32: =E32+K32 -> 3750 | R32: =F32+L32 -> 307000 | S32: =G32+M32 -> 310750 | T32: =P32-S32 -> 0
B33: Hardware | D33: =SUMIFS('PR Data'!$N:$N,'PR Data'!$Q:$Q,$B33,'PR Data'!$O:$O,$D$28) -> 2069845 | E33: =SUMIFS('PR Data'!$T:$T,'PR Data'!$Q:$Q,$B33,'PR Data'!$O:$O,$D$28) -> 360575 | F33: =SUMIFS('PR Data'!$V:$V,'PR Data'!$Q:$Q,$B33,'PR Data'!$O:$O,$D$28) -> 1703030 | G33: =SUM(E33:F33) -> 2063605 | H33: =D33-G33 -> 6240 | J33: =SUMIFS('PR Data'!$N:$N,'PR Data'!$Q:$Q,$B33,'PR Data'!$O:$O,$J$28) -> 0 | K33: =SUMIFS('PR Data'!$T:$T,'PR Data'!$Q:$Q,$B33,'PR Data'!$O:$O,$J$28) -> 0 | L33: =SUMIFS('PR Data'!$V:$V,'PR Data'!$Q:$Q,$B33,'PR Data'!$O:$O,$J$28) -> 16167265 | M33: =SUM(K33:L33) -> 16167265 | N33: =J33-M33 -> -16167265 | P33: =D33+J33 -> 2069845 | Q33: =E33+K33 -> 360575 | R33: =F33+L33 -> 17870295 | S33: =G33+M33 -> 18230870 | T33: =P33-S33 -> -16161025
B34: Software License | D34: =SUMIFS('PR Data'!$N:$N,'PR Data'!$Q:$Q,$B34,'PR Data'!$O:$O,$D$28) -> 0 | E34: =SUMIFS('PR Data'!$T:$T,'PR Data'!$Q:$Q,$B34,'PR Data'!$O:$O,$D$28) -> 0 | F34: =SUMIFS('PR Data'!$V:$V,'PR Data'!$Q:$Q,$B34,'PR Data'!$O:$O,$D$28) -> 0 | G34: =SUM(E34:F34) -> 0 | H34: =D34-G34 -> 0 | J34: =SUMIFS('PR Data'!$N:$N,'PR Data'!$Q:$Q,$B34,'PR Data'!$O:$O,$J$28) -> 0 | K34: =SUMIFS('PR Data'!$T:$T,'PR Data'!$Q:$Q,$B34,'PR Data'!$O:$O,$J$28) -> 0 | L34: =SUMIFS('PR Data'!$V:$V,'PR Data'!$Q:$Q,$B34,'PR Data'!$O:$O,$J$28) -> 0 | M34: =SUM(K34:L34) -> 0 | N34: =J34-M34 -> 0 | P34: =D34+J34 -> 0 | Q34: =E34+K34 -> 0 | R34: =F34+L34 -> 0 | S34: =G34+M34 -> 0 | T34: =P34-S34 -> 0
B35: Y2024 Budget | D35: 0 | E35: 0 | F35: 0 | H35: 0 | J35: 34824100 | K35: 0 | L35: 0 | M35: =SUM(K35:L35) -> 0 | N35: =J35-M35 -> 34824100 | P35: =D35+J35 -> 34824100 | Q35: =E35+K35 -> 0 | R35: =F35+L35 -> 0 | S35: =G35+M35 -> 0 | T35: =P35-S35 -> 34824100
D36: =SUBTOTAL(9,D30:D35) -> 12153510 | E36: =SUBTOTAL(9,E30:E35) -> 3555958.1 | F36: =SUBTOTAL(9,F30:F35) -> 7708730.9 | G36: =SUBTOTAL(9,G30:G35) -> 11264689 | H36: =SUBTOTAL(9,H30:H35) -> 888821.28 | J36: =SUBTOTAL(9,J30:J35) -> 34824100 | K36: =SUBTOTAL(9,K30:K35) -> 605286.04 | L36: =SUBTOTAL(9,L30:L35) -> 42831389 | M36: =SUBTOTAL(9,M30:M35) -> 43436675 | N36: =SUBTOTAL(9,N30:N35) -> -8612575.4 | P36: =SUBTOTAL(9,P30:P35) -> 46977610 | Q36: =SUBTOTAL(9,Q30:Q35) -> 4161244.1 | R36: =SUBTOTAL(9,R30:R35) -> 50540120 | S36: =SUBTOTAL(9,S30:S35) -> 54701364 | T36: =SUBTOTAL(9,T30:T35) -> -7723754.1
B38: Ageing by Projects
D39: 1 | E39: 2 | F39: 3 | G39: 4 | H39: 5
D40: Ageing of Commitment
B41: Project | D41: 3 Months | E41: 6 Months | F41: 9 Months | G41: 12 Months | H41: > 12 Months | J41: Total
B42: Others | D42: =SUMIFS('PR Data'!$V:$V,'PR Data'!$P:$P,$B42,'PR Data'!$AA:$AA,D$39) -> 1623537.5 | E42: =SUMIFS('PR Data'!$V:$V,'PR Data'!$P:$P,$B42,'PR Data'!$AA:$AA,E$39) -> 1681130 | F42: =SUMIFS('PR Data'!$V:$V,'PR Data'!$P:$P,$B42,'PR Data'!$AA:$AA,F$39) -> 0 | G42: =SUMIFS('PR Data'!$V:$V,'PR Data'!$P:$P,$B42,'PR Data'!$AA:$AA,G$39) -> 109470.85 | H42: =SUMIFS('PR Data'!$V:$V,'PR Data'!$P:$P,$B42,'PR Data'!$AA:$AA,H$39) -> 300000 | J42: =SUM(D42:H42) -> 3714138.4
B43: HCM Core | D43: =SUMIFS('PR Data'!$V:$V,'PR Data'!$P:$P,$B43,'PR Data'!$AA:$AA,D$39) -> 0 | E43: =SUMIFS('PR Data'!$V:$V,'PR Data'!$P:$P,$B43,'PR Data'!$AA:$AA,E$39) -> 285938 | F43: =SUMIFS('PR Data'!$V:$V,'PR Data'!$P:$P,$B43,'PR Data'!$AA:$AA,F$39) -> 0 | G43: =SUMIFS('PR Data'!$V:$V,'PR Data'!$P:$P,$B43,'PR Data'!$AA:$AA,G$39) -> 0 | H43: =SUMIFS('PR Data'!$V:$V,'PR Data'!$P:$P,$B43,'PR Data'!$AA:$AA,H$39) -> 0 | J43: =SUM(D43:H43) -> 285938
B44: Relex Project | D44: =SUMIFS('PR Data'!$V:$V,'PR Data'!$P:$P,$B44,'PR Data'!$AA:$AA,D$39) -> 0 | E44: =SUMIFS('PR Data'!$V:$V,'PR Data'!$P:$P,$B44,'PR Data'!$AA:$AA,E$39) -> 0 | F44: =SUMIFS('PR Data'!$V:$V,'PR Data'!$P:$P,$B44,'PR Data'!$AA:$AA,F$39) -> 75000 | G44: =SUMIFS('PR Data'!$V:$V,'PR Data'!$P:$P,$B44,'PR Data'!$AA:$AA,G$39) -> 0 | H44: =SUMIFS('PR Data'!$V:$V,'PR Data'!$P:$P,$B44,'PR Data'!$AA:$AA,H$39) -> 0 | J44: =SUM(D44:H44) -> 75000
B45: Fusion Re-Engineering | D45: =SUMIFS('PR Data'!$V:$V,'PR Data'!$P:$P,$B45,'PR Data'!$AA:$AA,D$39) -> 1083662 | E45: =SUMIFS('PR Data'!$V:$V,'PR Data'!$P:$P,$B45,'PR Data'!$AA:$AA,E$39) -> 0 | F45: =SUMIFS('PR Data'!$V:$V,'PR Data'!$P:$P,$B45,'PR Data'!$AA:$AA,F$39) -> 0 | G45: =SUMIFS('PR Data'!$V:$V,'PR Data'!$P:$P,$B45,'PR Data'!$AA:$AA,G$39) -> 1916250 | H45: =SUMIFS('PR Data'!$V:$V,'PR Data'!$P:$P,$B45,'PR Data'!$AA:$AA,H$39) -> 0 | J45: =SUM(D45:H45) -> 2999912
B46: RMS | D46: =SUMIFS('PR Data'!$V:$V,'PR Data'!$P:$P,$B46,'PR Data'!$AA:$AA,D$39) -> 0 | E46: =SUMIFS('PR Data'!$V:$V,'PR Data'!$P:$P,$B46,'PR Data'!$AA:$AA,E$39) -> 0 | F46: =SUMIFS('PR Data'!$V:$V,'PR Data'!$P:$P,$B46,'PR Data'!$AA:$AA,F$39) -> 3281250 | G46: =SUMIFS('PR Data'!$V:$V,'PR Data'!$P:$P,$B46,'PR Data'!$AA:$AA,G$39) -> 295125 | H46: =SUMIFS('PR Data'!$V:$V,'PR Data'!$P:$P,$B46,'PR Data'!$AA:$AA,H$39) -> 0 | J46: =SUM(D46:H46) -> 3576375
...

Sheet PR Data
K2: =SUBTOTAL(9,K4:K99) -> 74017992 | L2: =SUBTOTAL(9,L4:L99) -> 25842027 | M2: =SUBTOTAL(9,M4:M99) -> 12952131 | N2: =SUBTOTAL(9,N4:N99) -> 12153510 | P2: =K2-L2 -> 48175964 | Q2: =L2-M2 -> 12889896 | R2: =SUBTOTAL(9,R4:R99) -> 47098228 | S2: =SUBTOTAL(9,S4:S99) -> 11005119 | T2: =SUBTOTAL(9,T4:T99) -> 4161244.1 | U2: =SUBTOTAL(9,U4:U99) -> -557440 | V2: =SUBTOTAL(9,V4:V99) -> 56662497 | W2: =SUBTOTAL(9,W4:W99) -> 0 | X2: =SUBTOTAL(9,X4:X99) -> 60823741 | Y2: =N2-X2 -> -48670231
C3: Code | D3: PR Number | E3: PO Number | F3: PR Line | G3: PO Line | H3: Budget Date | I3: PR Approved Date | J3: Status | K3: PR Amount | L3: PO Amount | M3: Received Amount | N3: Carryforward | O3: Year | P3: Project Name - Budget | Q3: Activity Item | R3: PR Not Converted to PO | S3: Outstanding PO's | T3: Spend | U3: Reversal PR | V3: Committed | W3: Cancelled | X3: Total Committed | Y3: Current Date | Z3: Aged Months | AA3: Intervals | AB3: Count Code | AC3: Var
C4: =D4&"-"&E4&"-"&F4&"-"&G4 -> 14022157-13011533-1-3 | D4: 14022157 | E4: 13011533 | F4: 1 | G4: 3 | H4: 44615 | I4: 44620.678 | J4: Closed | K4: 1635903.1 | L4: 1634160 | M4: 1563119.2 | N4: 71040.75 | O4: Y2024 | P4: Others | Q4: Implementation | R4: 0 | S4: =IF(N4>M4,N4-M4,0) -> 0 | T4: =N4 -> 71040.75 | U4: 0 | V4: {=_xlfn.IFS(J4="Closed",0,J4="Canceled",0,J4="Closed for Receiving",0,TRUE,SUM(R4:S4))+U4} -> 0 | X4: =+T4+V4+W4 -> 71040.75 | Z4: 0 | AB4: =(COUNTIF($E4:$E$4,$E4)=1)+0 -> 1 | AC4: =N4-M4 -> -1492078.5
C5: =D5&"-"&E5&"-"&F5&"-"&G5 -> 14022158-13011533-1-2 | D5: 14022158 | E5: 13011533 | F5: 1 | G5: 2 | H5: 44615 | I5: 44620.678 | J5: Closed | K5: 2451362 | L5: 2448750 | M5: 898290 | N5: 1550460 | O5: Y2024 | P5: HCM Core | Q5: Implementation | R5: 0 | S5: =IF(N5>M5,N5-M5,0) -> 652170 | T5: =M5 -> 898290 | U5: 0 | V5: {=_xlfn.IFS(J5="Closed",0,J5="Canceled",0,J5="Closed for Receiving",0,TRUE,SUM(R5:S5))+U5} -> 0 | X5: =+T5+V5+W5 -> 898290 | Z5: 0 | AB5: =(COUNTIF($E$4:$E5,$E5)=1)+0 -> 0 | AC5: =N5-M5 -> 652170
C6: =D6&"-"&E6&"-"&F6&"-"&G6 -> 14022159-13011533-1-1 | D6: 14022159 | E6: 13011533 | F6: 1 | G6: 1 | H6: 44615 | I6: 44620.677 | J6: Closed | K6: 900960 | L6: 900000 | M6: 337500 | N6: 562500 | O6: Y2024 | P6: Others | Q6: Implementation | R6: 0 | S6: =IF(N6>M6,N6-M6,0) -> 225000 | T6: =M6 -> 337500 | U6: 0 | V6: {=_xlfn.IFS(J6="Closed",0,J6="Canceled",0,J6="Closed for Receiving",0,TRUE,SUM(R6:S6))+U6} -> 0 | X6: =+T6+V6+W6 -> 337500 | Z6: 0 | AB6: =(COUNTIF($E$4:$E6,$E6)=1)+0 -> 0 | AC6: =N6-M6 -> 225000
C7: =D7&"-"&E7&"-"&F7&"-"&G7 -> 14032355-13019561-2-2 | D7: 14032355 | E7: 13019561 | F7: 2 | G7: 2 | H7: 44860 | I7: 44880.541 | J7: Closed | K7: 116550 | L7: 116550 | M7: 115915.35 | N7: 634.65025 | O7: Y2024 | P7: Relex Project | Q7: Implementation | R7: 0 | S7: =IF(N7>M7,N7-M7,0) -> 0 | T7: =N7 -> 634.65025 | U7: 0 | V7: {=_xlfn.IFS(J7="Closed",0,J7="Canceled",0,J7="Closed for Receiving",0,TRUE,SUM(R7:S7))+U7} -> 0 | X7: =+T7+V7+W7 -> 634.65025 | Z7: 0 | AB7: =(COUNTIF($E$4:$E7,$E7)=1)+0 -> 1 | AC7: =N7-M7 -> -115280.7
C8: =D8&"-"&E8&"-"&F8&"-"&G8 -> 14033775-13019904-1-1 | D8: 14033775 | E8: 13019904 | F8: 1 | G8: 1 | H8: 44886 | I8: 44901.376 | J8: Closed | K8: 112498.88 | L8: 112498.88 | M8: 111586.38 | N8: 912.49088 | O8: Y2024 | P8: Others | Q8: Implementation | R8: 0 | S8: =IF(N8>M8,N8-M8,0) -> 0 | T8: =N8 -> 912.49088 | U8: 0 | V8: {=_xlfn.IFS(J8="Closed",0,J8="Canceled",0,J8="Closed for Receiving",0,TRUE,SUM(R8:S8))+U8} -> 0 | X8: =+T8+V8+W8 -> 912.49088 | Z8: 0 | AB8: =(COUNTIF($E$4:$E8,$E8)=1)+0 -> 1 | AC8: =N8-M8 -> -110673.89
C9: =D9&"-"&E9&"-"&F9&"-"&G9 -> 14038250-13022718-9-4 | D9: 14038250 | E9: 13022718 | F9: 9 | G9: 4 | H9: 44977 | I9: 44978.607 | J9: Open | K9: 543750 | L9: 543750 | M9: 543635.62 | N9: 114.375 | O9: Y2024 | P9: Relex Project | Q9: Implementation | R9: 0 | S9: =IF(N9>M9,N9-M9,0) -> 0 | T9: =N9 -> 114.375 | U9: 0 | V9: {=_xlfn.IFS(J9="Closed",0,J9="Canceled",0,J9="Closed for Receiving",0,TRUE,SUM(R9:S9))+U9} -> 0 | X9: =+T9+V9+W9 -> 114.375 | Y9: 45777 | Z9: =IF(I9>0,_xlfn.DAYS(Y9,I9)/30,0) -> 26.633333 | AA9: 5 | AB9: =(COUNTIF($E$4:$E9,$E9)=1)+0 -> 1 | AC9: =N9-M9 -> -543521.25
C10: =D10&"-"&E10&"-"&F10&"-"&G10 -> 14038251-13023234-9-1 | D10: 14038251 | E10: 13023234 | F10: 9 | G10: 1 | H10: 44977 | I10: 44992.045 | J10: Open | K10: 1246875 | L10: 1246875 | M10: 1245631.9 | N10: 1243.125 | O10: Y2024 | P10: Relex Project | Q10: Implementation | R10: 0 | S10: =IF(N10>M10,N10-M10,0) -> 0 | T10: =N10 -> 1243.125 | U10: 0 | V10: {=_xlfn.IFS(J10="Closed",0,J10="Canceled",0,J10="Closed for Receiving",0,TRUE,SUM(R10:S10))+U10} -> 0 | X10: =+T10+V10+W10 -> 1243.125 | Y10: 45777 | Z10: =IF(I10>0,_xlfn.DAYS(Y10,I10)/30,0) -> 26.166667 | AA10: 5 | AB10: =(COUNTIF($E$4:$E10,$E10)=1)+0 -> 1 | AC10: =N10-M10 -> -1244388.8
C11: =D11&"-"&E11&"-"&F11&"-"&G11 -> 14039056-13022718-1-7 | D11: 14039056 | E11: 13022718 | F11: 1 | G11: 7 | H11: 44993 | I11: 44994.413 | J11: Open | K11: 281250 | L11: 281250 | M11: 255850.09 | N11: 25399.913 | O11: Y2024 | P11: Relex Project | Q11: Implementation | R11: 0 | S11: =IF(N11>M11,N11-M11,0) -> 0 | T11: =N11 -> 25399.913 | U11: 0 | V11: {=_xlfn.IFS(J11="Closed",0,J11="Canceled",0,J11="Closed for Receiving",0,TRUE,SUM(R11:S11))+U11} -> 0 | X11: =+T11+V11+W11 -> 25399.913 | Y11: 45777 | Z11: =IF(I11>0,_xlfn.DAYS(Y11,I11)/30,0) -> 26.1 | AA11: 5 | AB11: =(COUNTIF($E$4:$E11,$E11)=1)+0 -> 0 | AC11: =N11-M11 -> -230450.17
C12: =D12&"-"&E12&"-"&F12&"-"&G12 -> 14053646-13036926-2-2 | D12: 14053646 | E12: 13036926 | F12: 2 | G12: 2 | H12: 45305 | I12: 45396.26 | J12: Open | K12: 63750 | L12: 63750 | M12: 36642.188 | N12: 27107.812 | O12: Y2024 | P12: Relex Project | Q12: Implementation | R12: 0 | S12: =IF(N12>M12,N12-M12,0) -> 0 | T12: =N12 -> 27107.812 | U12: 0 | V12: {=_xlfn.IFS(J12="Closed",0,J12="Canceled",0,J12="Closed for Receiving",0,TRUE,SUM(R12:S12))+U12} -> 0 | X12: =+T12+V12+W12 -> 27107.812 | Y12: 45777 | Z12: =IF(I12>0,_xlfn.DAYS(Y12,I12)/30,0) -> 12.7 | AA12: 5 | AB12: =(COUNTIF($E$4:$E12,$E12)=1)+0 -> 1 | AC12: =N12-M12 -> -9534.375
C13: =D13&"-"&E13&"-"&F13&"-"&G13 -> 14056705-13034685-1-1 | D13: 14056705 | E13: 13034685 | F13: 1 | G13: 1 | H13: 45364 | I13: 45371.345 | J13: Open | K13: 761250 | L13: 761250 | M13: 738313.99 | N13: 22936.013 | O13: Y2024 | P13: Relex Project | Q13: Implementation | R13: 0 | S13: =IF(N13>M13,N13-M13,0) -> 0 | T13: =N13 -> 22936.013 | U13: 0 | V13: {=_xlfn.IFS(J13="Closed",0,J13="Canceled",0,J13="Closed for Receiving",0,TRUE,SUM(R13:S13))+U13} -> 0 | X13: =+T13+V13+W13 -> 22936.013 | Y13: 45777 | Z13: =IF(I13>0,_xlfn.DAYS(Y13,I13)/30,0) -> 13.533333 | AA13: 5 | AB13: =(COUNTIF($E$4:$E13,$E13)=1)+0 -> 1 | AC13: =N13-M13 -> -715377.97
C14: =D14&"-"&E14&"-"&F14&"-"&G14 -> 14056907-13035845-1-1 | D14: 14056907 | E14: 13035845 | F14: 1 | G14: 1 | H14: 45370 | I14: 45371.412 | J14: Open | K14: 30080 | L14: 28098 | M14: 25308 | N14: 2790 | O14: Y2024 | P14: Others | Q14: Implementation | R14: 0 | S14: =IF(N14>M14,N14-M14,0) -> 0 | T14: =N14 -> 2790 | U14: 0 | V14: {=_xlfn.IFS(J14="Closed",0,J14="Canceled",0,J14="Closed for Receiving",0,TRUE,SUM(R14:S14))+U14} -> 0 | X14: =+T14+V14+W14 -> 2790 | Y14: 45777 | Z14: =IF(I14>0,_xlfn.DAYS(Y14,I14)/30,0) -> 13.533333 | AA14: 5 | AB14: =(COUNTIF($E$4:$E14,$E14)=1)+0 -> 1 | AC14: =N14-M14 -> -22518
C15: =D15&"-"&E15&"-"&F15&"-"&G15 -> 14057082-13037619-2-1 | D15: 14057082 | E15: 13037619 | F15: 2 | G15: 1 | H15: 45375 | I15: 45375.403 | J15: Open | K15: 300000 | L15: 300000 | M15: 0 | N15: 300000 | O15: Y2024 | P15: Others | Q15: Consultancy | R15: 0 | S15: =IF(N15>M15,N15-M15,0) -> 300000 | T15: =M15 -> 0 | U15: 0 | V15: {=_xlfn.IFS(J15="Closed",0,J15="Canceled",0,J15="Closed for Receiving",0,TRUE,SUM(R15:S15))+U15} -> 300000 | X15: =+T15+V15+W15 -> 300000 | Y15: 45777 | Z15: =IF(I15>0,_xlfn.DAYS(Y15,I15)/30,0) -> 13.4 | AA15: 5 | AB15: =(COUNTIF($E$4:$E15,$E15)=1)+0 -> 1 | AC15: =N15-M15 -> 300000
C16: =D16&"-"&E16&"-"&F16&"-"&G16 -> 14057104-13039072-1-1 | D16: 14057104 | E16: 13039072 | F16: 1 | G16: 1 | H16: 45375 | I16: 45426.569 | J16: Open | K16: 562500 | L16: 375000 | M16: 243750 | N16: 63750 | O16: Y2024 | P16: Fusion Re-Engineering | Q16: Implementation | R16: 0 | S16: =IF(N16>M16,N16-M16,0) -> 0 | T16: =N16 -> 63750 | U16: 0 | V16: {=_xlfn.IFS(J16="Closed",0,J16="Canceled",0,J16="Closed for Receiving",0,TRUE,SUM(R16:S16))+U16} -> 0 | X16: =+T16+V16+W16 -> 63750 | Y16: 45777 | Z16: =IF(I16>0,_xlfn.DAYS(Y16,I16)/30,0) -> 11.7 | AA16: 4 | AB16: =(COUNTIF($E$4:$E16,$E16)=1)+0 -> 1 | AC16: =N16-M16 -> -180000
C17: =D17&"-"&E17&"-"&F17&"-"&G17 -> 14057104-13039072-2-2 | D17: 14057104 | E17: 13039072 | F17: 2 | G17: 2 | H17: 45375 | I17: 45426.569 | J17: Open | K17: 131250 | L17: 93750 | M17: 0 | N17: 93750 | O17: Y2024 | P17: Fusion Re-Engineering | Q17: Implementation | R17: 0 | S17: =IF(N17>M17,N17-M17,0) -> 93750 | T17: =M17 -> 0 | U17: 0 | V17: {=_xlfn.IFS(J17="Closed",0,J17="Canceled",0,J17="Closed for Receiving",0,TRUE,SUM(R17:S17))+U17} -> 93750 | X17: =+T17+V17+W17 -> 93750 | Y17: 45777 | Z17: =IF(I17>0,_xlfn.DAYS(Y17,I17)/30,0) -> 11.7 | AA17: 4 | AB17: =(COUNTIF($E$4:$E17,$E17)=1)+0 -> 0 | AC17: =N17-M17 -> 93750
C18: =D18&"-"&E18&"-"&F18&"-"&G18 -> 14057104-13039072-3-3 | D18: 14057104 | E18: 13039072 | F18: 3 | G18: 3 | H18: 45375 | I18: 45426.569 | J18: Open | K18: 187500 | L18: 150000 | M18: 0 | N18: 150000 | O18: Y2024 | P18: Fusion Re-Engineering | Q18: Implementation | R18: 0 | S18: =IF(N18>M18,N18-M18,0) -> 150000 | T18: =M18 -> 0 | U18: 0 | V18: {=_xlfn.IFS(J18="Closed",0,J18="Canceled",0,J18="Closed for Receiving",0,TRUE,SUM(R18:S18))+U18} -> 150000 | X18: =+T18+V18+W18 -> 150000 | Y18: 45777 | Z18: =IF(I18>0,_xlfn.DAYS(Y18,I18)/30,0) -> 11.7 | AA18: 4 | AB18: =(COUNTIF($E$4:$E18,$E18)=1)+0 -> 0 | AC18: =N18-M18 -> 150000
C19: =D19&"-"&E19&"-"&F19&"-"&G19 -> 14057104-13039072-4-4 | D19: 14057104 | E19: 13039072 | F19: 4 | G19: 4 | H19: 45375 | I19: 45426.569 | J19: Open | K19: 281250 | L19: 206250 | M19: 0 | N19: 206250 | O19: Y2024 | P19: Fusion Re-Engineering | Q19: Implementation | R19: 0 | S19: =IF(N19>M19,N19-M19,0) -> 206250 | T19: =M19 -> 0 | U19: 0 | V19: {=_xlfn.IFS(J19="Closed",0,J19="Canceled",0,J19="Closed for Receiving",0,TRUE,SUM(R19:S19))+U19} -> 206250 | X19: =+T19+V19+W19 -> 206250 | Y19: 45777 | Z19: =IF(I19>0,_xlfn.DAYS(Y19,I19)/30,0) -> 11.7 | AA19: 4 | AB19: =(COUNTIF($E$4:$E19,$E19)=1)+0 -> 0 | AC19: =N19-M19 -> 206250
C20: =D20&"-"&E20&"-"&F20&"-"&G20 -> 14057104-13039072-5-5 | D20: 14057104 | E20: 13039072 | F20: 5 | G20: 5 | H20: 45375 | I20: 45426.569 | J20: Open | K20: 468750 | L20: 450000 | M20: 67500 | N20: 450000 | O20: Y2024 | P20: Fusion Re-Engineering | Q20: Implementation | R20: 0 | S20: =IF(N20>M20,N20-M20,0) -> 382500 | T20: =M20 -> 67500 | U20: 0 | V20: {=_xlfn.IFS(J20="Closed",0,J20="Canceled",0,J20="Closed for Receiving",0,TRUE,SUM(R20:S20))+U20} -> 382500 | X20: =+T20+V20+W20 -> 450000 | Y20: 45777 | Z20: =IF(I20>0,_xlfn.DAYS(Y20,I20)/30,0) -> 11.7 | AA20: 4 | AB20: =(COUNTIF($E$4:$E20,$E20)=1)+0 -> 0 | AC20: =N20-M20 -> 382500
C21: =D21&"-"&E21&"-"&F21&"-"&G21 -> 14057104-13039072-6-6 | D21: 14057104 | E21: 13039072 | F21: 6 | G21: 6 | H21: 45375 | I21: 45426.569 | J21: Open | K21: 450000 | L21: 450000 | M21: 0 | N21: 450000 | O21: Y2024 | P21: Fusion Re-Engineering | Q21: Implementation | R21: 0 | S21: =IF(N21>M21,N21-M21,0) -> 450000 | T21: =M21 -> 0 | U21: 0 | V21: {=_xlfn.IFS(J21="Closed",0,J21="Canceled",0,J21="Closed for Receiving",0,TRUE,SUM(R21:S21))+U21} -> 450000 | X21: =+T21+V21+W21 -> 450000 | Y21: 45777 | Z21: =IF(I21>0,_xlfn.DAYS(Y21,I21)/30,0) -> 11.7 | AA21: 4 | AB21: =(COUNTIF($E$4:$E21,$E21)=1)+0 -> 0 | AC21: =N21-M21 -> 450000
C22: =D22&"-"&E22&"-"&F22&"-"&G22 -> 14057104-13039072-7-7 | D22: 14057104 | E22: 13039072 | F22: 7 | G22: 7 | H22: 45375 | I22: 45426.569 | J22: Open | K22: 337500 | L22: 337500 | M22: 0 | N22: 337500 | O22: Y2024 | P22: Fusion Re-Engineering | Q22: Implementation | R22: 0 | S22: =IF(N22>M22,N22-M22,0) -> 337500 | T22: =M22 -> 0 | U22: 0 | V22: {=_xlfn.IFS(J22="Closed",0,J22="Canceled",0,J22="Closed for Receiving",0,TRUE,SUM(R22:S22))+U22} -> 337500 | X22: =+T22+V22+W22 -> 337500 | Y22: 45777 | Z22: =IF(I22>0,_xlfn.DAYS(Y22,I22)/30,0) -> 11.7 | AA22: 4 | AB22: =(COUNTIF($E$4:$E22,$E22)=1)+0 -> 0 | AC22: =N22-M22 -> 337500
C23: =D23&"-"&E23&"-"&F23&"-"&G23 -> 14057104-13039072-8-8 | D23: 14057104 | E23: 13039072 | F23: 8 | G23: 8 | H23: 45375 | I23: 45426.569 | J23: Open | K23: 296250 | L23: 296250 | M23: 0 | N23: 296250 | O23: Y2024 | P23: Fusion Re-Engineering | Q23: Implementation | R23: 0 | S23: =IF(N23>M23,N23-M23,0) -> 296250 | T23: =M23 -> 0 | U23: 0 | V23: {=_xlfn.IFS(J23="Closed",0,J23="Canceled",0,J23="Closed for Receiving",0,TRUE,SUM(R23:S23))+U23} -> 296250 | X23: =+T23+V23+W23 -> 296250 | Y23: 45777 | Z23: =IF(I23>0,_xlfn.DAYS(Y23,I23)/30,0) -> 11.7 | AA23: 4 | AB23: =(COUNTIF($E$4:$E23,$E23)=1)+0 -> 0 | AC23: =N23-M23 -> 296250
C24: =D24&"-"&E24&"-"&F24&"-"&G24 -> 14057104-13039072-9-9 | D24: 14057104 | E24: 13039072 | F24: 9 | G24: 9 | H24: 45375 | I24: 45426.569 | J24: Open | K24: 243750 | L24: 56250 | M24: 56250 | N24: 56250 | O24: Y2024 | P24: Fusion Re-Engineering | Q24: Implementation | R24: 0 | S24: =IF(N24>M24,N24-M24,0) -> 0 | T24: =M24 -> 56250 | U24: 0 | V24: {=_xlfn.IFS(J24="Closed",0,J24="Canceled",0,J24="Closed for Receiving",0,TRUE,SUM(R24:S24))+U24} -> 0 | X24: =+T24+V24+W24 -> 56250 | Y24: 45777 | Z24: =IF(I24>0,_xlfn.DAYS(Y24,I24)/30,0) -> 11.7 | AA24: 4 | AB24: =(COUNTIF($E$4:$E24,$E24)=1)+0 -> 0 | AC24: =N24-M24 -> 0
C25: =D25&"-"&E25&"-"&F25&"-"&G25 -> 14057104-13039072-10-10 | D25: 14057104 | E25: 13039072 | F25: 10 | G25: 10 | H25: 45375 | I25: 45426.569 | J25: Open | K25: 93750 | L25: 93750 | M25: 93750 | N25: 93750 | O25: Y2024 | P25: Fusion Re-Engineering | Q25: Implementation | R25: 0 | S25: =IF(N25>M25,N25-M25,0) -> 0 | T25: =M25 -> 93750 | U25: 0 | V25: {=_xlfn.IFS(J25="Closed",0,J25="Canceled",0,J25="Closed for Receiving",0,TRUE,SUM(R25:S25))+U25} -> 0 | X25: =+T25+V25+W25 -> 93750 | Y25: 45777 | Z25: =IF(I25>0,_xlfn.DAYS(Y25,I25)/30,0) -> 11.7 | AA25: 4 | AB25: =(COUNTIF($E$4:$E25,$E25)=1)+0 -> 0 | AC25: =N25-M25 -> 0
C26: =D26&"-"&E26&"-"&F26&"-"&G26 -> 14058538-13038193-1-1 | D26: 14058538 | E26: 13038193 | F26: 1 | G26: 1 | H26: 45414 | I26: 45418.229 | J26: Open | K26: 423750 | L26: 295125 | M26: 0 | N26: 295125 | O26: Y2024 | P26: RMS | Q26: Implementation | R26: 0 | S26: =IF(N26>M26,N26-M26,0) -> 295125 | T26: =M26 -> 0 | U26: 0 | V26: {=_xlfn.IFS(J26="Closed",0,J26="Canceled",0,J26="Closed for Receiving",0,TRUE,SUM(R26:S26))+U26} -> 295125 | X26: =+T26+V26+W26 -> 295125 | Y26: 45777 | Z26: =IF(I26>0,_xlfn.DAYS(Y26,I26)/30,0) -> 11.966667 | AA26: 4 | AB26: =(COUNTIF($E$4:$E26,$E26)=1)+0 -> 1 | AC26: =N26-M26 -> 295125
C27: =D27&"-"&E27&"-"&F27&"-"&G27 -> 14058706-13037212-2-1 | D27: 14058706 | E27: 13037212 | F27: 2 | G27: 1 | H27: 45418 | I27: 45420.432 | J27: Open | K27: 104700 | L27: 104700 | M27: 4864.575 | N27: 99835.425 | O27: Y2024 | P27: Others | Q27: Implementation | R27: 0 | S27: =IF(N27>M27,N27-M27,0) -> 94970.85 | T27: =M27 -> 4864.575 | U27: 0 | V27: {=_xlfn.IFS(J27="Closed",0,J27="Canceled",0,J27="Closed for Receiving",0,TRUE,SUM(R27:S27))+U27} -> 94970.85 | X27: =+T27+V27+W27 -> 99835.425 | Y27: 45777 | Z27: =IF(I27>0,_xlfn.DAYS(Y27,I27)/30,0) -> 11.9 | AA27: 4 | AB27: =(COUNTIF($E$4:$E27,$E27)=1)+0 -> 1 | AC27: =N27-M27 -> 94970.85
C28: =D28&"-"&E28&"-"&F28&"-"&G28 -> 14060672-13038489-1-1 | D28: 14060672 | E28: 13038489 | F28: 1 | G28: 1 | H28: 45449 | I28: 45453.541 | J28: Open | K28: 14500 | L28: 14500 | M28: 0 | N28: 14500 | O28: Y2024 | P28: Others | Q28: Hardware | R28: 0 | S28: =IF(N28>M28,N28-M28,0) -> 14500 | T28: =M28 -> 0 | U28: 0 | V28: {=_xlfn.IFS(J28="Closed",0,J28="Canceled",0,J28="Closed for Receiving",0,TRUE,SUM(R28:S28))+U28} -> 14500 | X28: =+T28+V28+W28 -> 14500 | Y28: 45777 | Z28: =IF(I28>0,_xlfn.DAYS(Y28,I28)/30,0) -> 10.8 | AA28: 4 | AB28: =(COUNTIF($E$4:$E28,$E28)=1)+0 -> 1 | AC28: =N28-M28 -> 14500
C29: =D29&"-"&E29&"-"&F29&"-"&G29 -> 14061844-13039275-1-1 | D29: 14061844 | E29: 13039275 | F29: 1 | G29: 1 | H29: 45474 | I29: 45482.364 | J29: Closed | K29: 22987.114 | L29: 23181.396 | M29: 23181.396 | N29: 23181.396 | O29: Y2024 | P29: Memory Project | Q29: Implementation | R29: 0 | S29: =IF(N29>M29,N29-M29,0) -> 0 | T29: =M29 -> 23181.396 | U29: 0 | V29: {=_xlfn.IFS(J29="Closed",0,J29="Canceled",0,J29="Closed for Receiving",0,TRUE,SUM(R29:S29))+U29} -> 0 | X29: =+T29+V29+W29 -> 23181.396 | Z29: 0 | AB29: =(COUNTIF($E$4:$E29,$E29)=1)+0 -> 1 | AC29: =N29-M29 -> 0
C30: =D30&"-"&E30&"-"&F30&"-"&G30 -> 14062076-13039561-1-1 | D30: 14062076 | E30: 13039561 | F30: 1 | G30: 1 | H30: 45476 | I30: 45488.532 | J30: Open | K30: 937500 | L30: 937500 | M30: 750000 | N30: 187500 | O30: Y2024 | P30: Others | Q30: Hardware | R30: 0 | S30: =IF(N30>M30,N30-M30,0) -> 0 | T30: =N30 -> 187500 | U30: 0 | V30: {=_xlfn.IFS(J30="Closed",0,J30="Canceled",0,J30="Closed for Receiving",0,TRUE,SUM(R30:S30))+U30} -> 0 | X30: =+T30+V30+W30 -> 187500 | Y30: 45777 | Z30: =IF(I30>0,_xlfn.DAYS(Y30,I30)/30,0) -> 9.6333333 | AA30: 4 | AB30: =(COUNTIF($E$4:$E30,$E30)=1)+0 -> 1 | AC30: =N30-M30 -> -562500
C31: =D31&"-"&E31&"-"&F31&"-"&G31 -> 14064794-13041140-1-1 | D31: 14064794 | E31: 13041140 | F31: 1 | G31: 1 | H31: 45532 | I31: 45543.25 | J31: Closed | K31: 52772.619 | L31: 52749.252 | M31: 52749.252 | N31: 52749.252 | O31: Y2024 | P31: Memory Project | Q31: Implementation | R31: 0 | S31: =IF(N31>M31,N31-M31,0) -> 0 | T31: =M31 -> 52749.252 | U31: 0 | V31: {=_xlfn.IFS(J31="Closed",0,J31="Canceled",0,J31="Closed for Receiving",0,TRUE,SUM(R31:S31))+U31} -> 0 | X31: =+T31+V31+W31 -> 52749.252 | Z31: 0 | AB31: =(COUNTIF($E$4:$E31,$E31)=1)+0 -> 1 | AC31: =N31-M31 -> 0
C32: =D32&"-"&E32&"-"&F32&"-"&G32 -> 14064958-13044082-1-1 | D32: 14064958 | E32: 13044082 | F32: 1 | G32: 1 | H32: 45536 | I32: 45552.447 | J32: Open | K32: 3675000 | L32: 3281250 | M32: 0 | N32: 3281250 | O32: Y2024 | P32: RMS | Q32: Implementation | R32: 0 | S32: =IF(N32>M32,N32-M32,0) -> 3281250 | T32: =M32 -> 0 | U32: 0 | V32: {=_xlfn.IFS(J32="Closed",0,J32="Canceled",0,J32="Closed for Receiving",0,TRUE,SUM(R32:S32))+U32} -> 3281250 | X32: =+T32+V32+W32 -> 3281250 | Y32: 45777 | Z32: =IF(I32>0,_xlfn.DAYS(Y32,I32)/30,0) -> 7.5 | AA32: 3 | AB32: =(COUNTIF($E$4:$E32,$E32)=1)+0 -> 1 | AC32: =N32-M32 -> 3281250
C33: =D33&"-"&E33&"-"&F33&"-"&G33 -> 14065292-13041891-1-1 | D33: 14065292 | E33: 13041891 | F33: 1 | G33: 1 | H33: 45540 | I33: 45540.538 | J33: Open | K33: 75000 | L33: 75000 | M33: 0 | N33: 75000 | O33: Y2024 | P33: Relex Project | Q33: Implementation | R33: 0 | S33: =IF(N33>M33,N33-M33,0) -> 75000 | T33: =M33 -> 0 | U33: 0 | V33: {=_xlfn.IFS(J33="Closed",0,J33="Canceled",0,J33="Closed for Receiving",0,TRUE,SUM(R33:S33))+U33} -> 75000 | W33: 0 | X33: =+T33+V33+W33 -> 75000 | Y33: 45777 | Z33: =IF(I33>0,_xlfn.DAYS(Y33,I33)/30,0) -> 7.9 | AA33: 3 | AB33: =(COUNTIF($E$4:$E33,$E33)=1)+0 -> 1 | AC33: =N33-M33 -> 75000
C34: =D34&"-"&E34&"-"&F34&"-"&G34 -> 14066609-13042318-1-1 | D34: 14066609 | E34: 13042318 | F34: 1 | G34: 1 | H34: 45565 | I34: 45571.343 | J34: Closed | K34: 393750 | L34: 393750 | M34: 393750 | N34: 393750 | O34: Y2024 | P34: Others | Q34: Implementation | R34: 0 | S34: =IF(N34>M34,N34-M34,0) -> 0 | T34: =M34 -> 393750 | U34: 0 | V34: {=_xlfn.IFS(J34="Closed",0,J34="Canceled",0,J34="Closed for Receiving",0,TRUE,SUM(R34:S34))+U34} -> 0 | W34: 0 | X34: =+T34+V34+W34 -> 393750 | Z34: 0 | AB34: =(COUNTIF($E$4:$E34,$E34)=1)+0 -> 1 | AC34: =N34-M34 -> 0
C35: =D35&"-"&E35&"-"&F35&"-"&G35 -> 14070394-13044892-1-1 | D35: 14070394 | E35: 13044892 | F35: 1 | G35: 1 | H35: 45627 | I35: 45628.494 | J35: Open | K35: 19500 | L35: 19500 | M35: 9750 | N35: 9750 | O35: Y2024 | P35: Others | Q35: Implementation | R35: 0 | S35: 0 | T35: =M35 -> 9750 | U35: 0 | V35: {=_xlfn.IFS(J35="Closed",0,J35="Canceled",0,J35="Closed for Receiving",0,TRUE,SUM(R35:S35))+U35} -> 0 | W35: 0 | X35: =+T35+V35+W35 -> 9750 | Y35: 45777 | Z35: =IF(I35>0,_xlfn.DAYS(Y35,I35)/30,0) -> 4.9666667 | AA35: 2 | AB35: =(COUNTIF($E$4:$E35,$E35)=1)+0 -> 1 | AC35: =N35-M35 -> 0
C36: =D36&"-"&E36&"-"&F36&"-"&G36 -> 14071195-13046536-1-1 | D36: 14071195 | E36: 13046536 | F36: 1 | G36: 1 | H36: 45641 | I36: 45641.617 | J36: Open | K36: 108900 | L36: 107250 | M36: 0 | N36: 108900 | O36: Y2024 | P36: Ocado | Q36: Hardware | R36: 0 | S36: =IF(N36>M36,N36-M36,0) -> 108900 | T36: =M36 -> 0 | U36: 0 | V36: {=_xlfn.IFS(J36="Closed",0,J36="Canceled",0,J36="Closed for Receiving",0,TRUE,SUM(R36:S36))+U36} -> 108900 | X36: =+T36+V36+W36 -> 108900 | Y36: 45777 | Z36: =IF(I36>0,_xlfn.DAYS(Y36,I36)/30,0) -> 4.5333333 | AA36: 2 | AB36: =(COUNTIF($E$4:$E36,$E36)=1)+0 -> 1 | AC36: =N36-M36 -> 108900
C37: =D37&"-"&E37&"-"&F37&"-"&G37 -> 14071200-13045776-1-1 | D37: 14071200 | E37: 13045776 | F37: 1 | G37: 1 | H37: 45641 | I37: 45641.617 | J37: Closed | K37: 23100 | L37: 17820 | M37: 17820 | N37: 17820 | O37: Y2024 | P37: Ocado | Q37: Hardware | R37: 0 | S37: =IF(N37>M37,N37-M37,0) -> 0 | T37: =M37 -> 17820 | U37: 0 | V37: {=_xlfn.IFS(J37="Closed",0,J37="Canceled",0,J37="Closed for Receiving",0,TRUE,SUM(R37:S37))+U37} -> 0 | X37: =+T37+V37+W37 -> 17820 | Z37: 0 | AB37: =(COUNTIF($E$4:$E37,$E37)=1)+0 -> 1 | AC37: =N37-M37 -> 0
C38: =D38&"-"&E38&"-"&F38&"-"&G38 -> 14071220-13047214-1-1 | D38: 14071220 | E38: 13047214 | F38: 1 | G38: 1 | H38: 45641 | I38: 45648.267 | J38: Open | K38: 69930 | L38: 69930 | M38: 63825 | N38: 69930 | O38: Y2024 | P38: Cube 2.0 | Q38: Implementation | R38: 0 | S38: =IF(N38>M38,N38-M38,0) -> 6105 | T38: =M38 -> 63825 | U38: 0 | V38: {=_xlfn.IFS(J38="Closed",0,J38="Canceled",0,J38="Closed for Receiving",0,TRUE,SUM(R38:S38))+U38} -> 6105 | X38: =+T38+V38+W38 -> 69930 | Y38: 45777 | Z38: =IF(I38>0,_xlfn.DAYS(Y38,I38)/30,0) -> 4.3 | AA38: 2 | AB38: =(COUNTIF($E$4:$E38,$E38)=1)+0 -> 1 | AC38: =N38-M38 -> 6105
C39: =D39&"-"&E39&"-"&F39&"-"&G39 -> 14071220-13047214-2-2 | D39: 14071220 | E39: 13047214 | F39: 2 | G39: 2 | H39: 45641 | I39: 45648.267 | J39: Open | K39: 62370 | L39: 62370 | M39: 62370 | N39: 62370 | O39: Y2024 | P39: Cube 2.0 | Q39: Implementation | R39: 0 | S39: =IF(N39>M39,N39-M39,0) -> 0 | T39: =M39 -> 62370 | U39: 0 | V39: {=_xlfn.IFS(J39="Closed",0,J39="Canceled",0,J39="Closed for Receiving",0,TRUE,SUM(R39:S39))+U39} -> 0 | X39: =+T39+V39+W39 -> 62370 | Y39: 45777 | Z39: =IF(I39>0,_xlfn.DAYS(Y39,I39)/30,0) -> 4.3 | AA39: 2 | AB39: =(COUNTIF($E$4:$E39,$E39)=1)+0 -> 0 | AC39: =N39-M39 -> 0
C40: =D40&"-"&E40&"-"&F40&"-"&G40 -> 14071231-13046311-1-1 | D40: 14071231 | E40: 13046311 | F40: 1 | G40: 1 | H40: 45641 | I40: 45652.495 | J40: Open | K40: 1176000 | L40: 1176000 | M40: 0 | N40: 1176000 | O40: Y2024 | P40: Others | Q40: Hardware | R40: 0 | S40: =IF(N40>M40,N40-M40,0) -> 1176000 | T40: =M40 -> 0 | U40: 0 | V40: {=_xlfn.IFS(J40="Closed",0,J40="Canceled",0,J40="Closed for Receiving",0,TRUE,SUM(R40:S40))+U40} -> 1176000 | X40: =+T40+V40+W40 -> 1176000 | Y40: 45777 | Z40: =IF(I40>0,_xlfn.DAYS(Y40,I40)/30,0) -> 4.1666667 | AA40: 2 | AB40: =(COUNTIF($E$4:$E40,$E40)=1)+0 -> 1 | AC40: =N40-M40 -> 1176000
C41: =D41&"-"&E41&"-"&F41&"-"&G41 -> 14071231-13046311-2-2 | D41: 14071231 | E41: 13046311 | F41: 2 | G41: 2 | H41: 45641 | I41: 45652.495 | J41: Open | K41: 18600 | L41: 18600 | M41: 0 | N41: 18600 | O41: Y2024 | P41: Others | Q41: Hardware | R41: 0 | S41: =IF(N41>M41,N41-M41,0) -> 18600 | T41: =M41 -> 0 | U41: 0 | V41: {=_xlfn.IFS(J41="Closed",0,J41="Canceled",0,J41="Closed for Receiving",0,TRUE,SUM(R41:S41))+U41} -> 18600 | X41: =+T41+V41+W41 -> 18600 | Y41: 45777 | Z41: =IF(I41>0,_xlfn.DAYS(Y41,I41)/30,0) -> 4.1666667 | AA41: 2 | AB41: =(COUNTIF($E$4:$E41,$E41)=1)+0 -> 0 | AC41: =N41-M41 -> 18600
...

Sheet Month
B4: Date | C4: 46053
