Workbook
Name ___INDEX_SHEET___ASAP_Utilities: #REF!
Name ___INDEX_SHEET___ASAP_Utilities: #REF!
Name AccountType: #REF!
Name AccountType: #REF!
Name CountryCode: "OFFSET($B$1,0,0,COUNT($B:$B),1)"

Sheet Store P&L - Summary
B2: Stores P&L - YTD Apr 2025
B3: (SAR'000')
I4: Sales | Q4: Product Margin | Y4: Commercial Margin | AG4: Stock Loss | AO4: Supply Chain Expenses | AW4: Gross Profit | BE4: Staff Expense | BM4: Operating Expenses | BU4: Rent Expense | CC4: EBITDA | CK4: Depreciation & Interest | CS4: Net Income / (Loss)
B5: Region | C5: District | D5: Location | E5: Loc Name | F5: Format | G5: Status | I5: Actual | J5: Budget | K5: LY | L5: Var Vs. Bud | M5: Var vs. LY | N5: Var vs. Bud % | O5: Var vs. LY % | Q5: Actual | R5: Budget | S5: LY | T5: Var Vs. Bud | U5: Var vs. LY | V5: Var vs. Bud % | W5: Var vs. LY % | Y5: Actual | Z5: Budget | AA5: LY | AB5: Var Vs. Bud | AC5: Var vs. LY | AD5: Var vs. Bud % | AE5: Var vs. LY % | AG5: Actual | AH5: Budget | AI5: LY | AJ5: Var Vs. Bud | AK5: Var vs. LY | AL5: Var vs. Bud % | AM5: Var vs. LY % | AO5: Actual | AP5: Budget | AQ5: LY | AR5: Var Vs. Bud | AS5: Var vs. LY | AT5: Var vs. Bud % | AU5: Var vs. LY % | AW5: Actual | AX5: Budget | AY5: LY | AZ5: Var Vs. Bud | BA5: Var vs. LY | BB5: Var vs. Bud % | BC5: Var vs. LY % | BE5: Actual | BF5: Budget | BG5: LY | BH5: Var Vs. Bud | BI5: Var vs. LY | BJ5: Var vs. Bud % | BK5: Var vs. LY % | BM5: Actual | BN5: Budget | BO5: LY | BP5: Var Vs. Bud | BQ5: Var vs. LY | BR5: Var vs. Bud % | BS5: Var vs. LY % | BU5: Actual | BV5: Budget | BW5: LY | BX5: Var Vs. Bud | BY5: Var vs. LY | BZ5: Var vs. Bud % | CA5: Var vs. LY % | CC5: Actual | CD5: Budget | CE5: LY | CF5: Var Vs. Bud | CG5: Var vs. LY | CH5: Var vs. Bud % | CI5: Var vs. LY % | CK5: Actual | CL5: Budget | CM5: LY | CN5: Var Vs. Bud | CO5: Var vs. LY | CP5: Var vs. Bud % | CQ5: Var vs. LY % | CS5: Actual | CT5: Budget | CU5: LY | CV5: Var Vs. Bud | CW5: Var vs. LY | CX5: Var vs. Bud % | CY5: Var vs. LY %
B6: Central | C6: Riyadh - Crescent | D6: 110 | E6: Al Quds-Re Opened | F6: Super | G6: LFL | I6: =SUMIFS('P&L Data'!$N:$N,'P&L Data'!$B:$B,$D6,'P&L Data'!$C:$C,$I$4) -> 27870.318 | J6: =SUMIFS('P&L Data'!$P:$P,'P&L Data'!$B:$B,$D6,'P&L Data'!$C:$C,$I$4) -> 27368.313 | K6: =SUMIFS('P&L Data'!$T:$T,'P&L Data'!$B:$B,$D6,'P&L Data'!$C:$C,$I$4) -> 26172.75 | L6: =I6-J6 -> 502.0054 | M6: =I6-K6 -> 1697.5675 | N6: =IFERROR((I6-J6)/ABS(J6),0) -> 0.018342578 | O6: =IFERROR((I6-K6)/ABS(K6),0) -> 0.064860113 | Q6: =SUMIFS('P&L Data'!$N:$N,'P&L Data'!$B:$B,$D6,'P&L Data'!$C:$C,$Q$4) -> 2321.9001 | R6: =SUMIFS('P&L Data'!$P:$P,'P&L Data'!$B:$B,$D6,'P&L Data'!$C:$C,$Q$4) -> 2116.8049 | S6: =SUMIFS('P&L Data'!$T:$T,'P&L Data'!$B:$B,$D6,'P&L Data'!$C:$C,$Q$4) -> 2527.3581 | T6: =Q6-R6 -> 205.0952 | U6: =Q6-S6 -> -205.45799 | V6: =IFERROR((Q6-R6)/ABS(R6),0) -> 0.096889041 | W6: =IFERROR((Q6-S6)/ABS(S6),0) -> -0.081293582 | Y6: =SUMIFS('P&L Data'!$N:$N,'P&L Data'!$B:$B,$D6,'P&L Data'!$C:$C,$Y$4) -> 7660.7427 | Z6: =SUMIFS('P&L Data'!$P:$P,'P&L Data'!$B:$B,$D6,'P&L Data'!$C:$C,$Y$4) -> 7189.9922 | AA6: =SUMIFS('P&L Data'!$T:$T,'P&L Data'!$B:$B,$D6,'P&L Data'!$C:$C,$Y$4) -> 7029.3761 | AB6: =Y6-Z6 -> 470.75055 | AC6: =Y6-AA6 -> 631.36658 | AD6: =IFERROR((Y6-Z6)/ABS(Z6),0) -> 0.065473027 | AE6: =IFERROR((Y6-AA6)/ABS(AA6),0) -> 0.089818296 | AG6: =SUMIFS('P&L Data'!$N:$N,'P&L Data'!$B:$B,$D6,'P&L Data'!$C:$C,$AG$4) -> -130.1943 | AH6: =SUMIFS('P&L Data'!$P:$P,'P&L Data'!$B:$B,$D6,'P&L Data'!$C:$C,$AG$4) -> -149.21151 | AI6: =SUMIFS('P&L Data'!$T:$T,'P&L Data'!$B:$B,$D6,'P&L Data'!$C:$C,$AG$4) -> -125.05086 | AJ6: =AG6-AH6 -> 19.01721 | AK6: =AG6-AI6 -> -5.14344 | AL6: =IFERROR((AG6-AH6)/ABS(AH6),0) -> 0.12745136 | AM6: =IFERROR((AG6-AI6)/ABS(AI6),0) -> -0.041130785 | AO6: =SUMIFS('P&L Data'!$N:$N,'P&L Data'!$B:$B,$D6,'P&L Data'!$C:$C,$AO$4) -> -473.35512 | AP6: =SUMIFS('P&L Data'!$P:$P,'P&L Data'!$B:$B,$D6,'P&L Data'!$C:$C,$AO$4) -> -505.86612 | AQ6: =SUMIFS('P&L Data'!$T:$T,'P&L Data'!$B:$B,$D6,'P&L Data'!$C:$C,$AO$4) -> -401.52716 | AR6: =AO6-AP6 -> 32.511 | AS6: =AO6-AQ6 -> -71.827956 | AT6: =IFERROR((AO6-AP6)/ABS(AP6),0) -> 0.064267992 | AU6: =IFERROR((AO6-AQ6)/ABS(AQ6),0) -> -0.17888692 | AW6: =SUMIFS('P&L Data'!$N:$N,'P&L Data'!$B:$B,$D6,'P&L Data'!$C:$C,$AW$4) -> 7057.1933 | AX6: =SUMIFS('P&L Data'!$P:$P,'P&L Data'!$B:$B,$D6,'P&L Data'!$C:$C,$AW$4) -> 6534.9145 | AY6: =SUMIFS('P&L Data'!$T:$T,'P&L Data'!$B:$B,$D6,'P&L Data'!$C:$C,$AW$4) -> 6502.7981 | AZ6: =AW6-AX6 -> 522.27876 | BA6: =AW6-AY6 -> 554.39519 | BB6: =IFERROR((AW6-AX6)/ABS(AX6),0) -> 0.079921284 | BC6: =IFERROR((AW6-AY6)/ABS(AY6),0) -> 0.085254867 | BE6: =SUMIFS('P&L Data'!$N:$N,'P&L Data'!$B:$B,$D6,'P&L Data'!$C:$C,$BE$4) -> -1860.5426 | BF6: =SUMIFS('P&L Data'!$P:$P,'P&L Data'!$B:$B,$D6,'P&L Data'!$C:$C,$BE$4) -> -1796.469 | BG6: =SUMIFS('P&L Data'!$T:$T,'P&L Data'!$B:$B,$D6,'P&L Data'!$C:$C,$BE$4) -> -1761.5087 | BH6: =BE6-BF6 -> -64.07361 | BI6: =BE6-BG6 -> -99.0339 | BJ6: =IFERROR((BE6-BF6)/ABS(BF6),0) -> -0.035666415 | BK6: =IFERROR((BE6-BG6)/ABS(BG6),0) -> -0.056221067 | BM6: =SUMIFS('P&L Data'!$N:$N,'P&L Data'!$B:$B,$D6,'P&L Data'!$C:$C,$BM$4) -> -645.63852 | BN6: =SUMIFS('P&L Data'!$P:$P,'P&L Data'!$B:$B,$D6,'P&L Data'!$C:$C,$BM$4) -> -668.14439 | BO6: =SUMIFS('P&L Data'!$T:$T,'P&L Data'!$B:$B,$D6,'P&L Data'!$C:$C,$BM$4) -> -646.61741 | BP6: =BM6-BN6 -> 22.50587 | BQ6: =BM6-BO6 -> 0.97889 | BR6: =IFERROR((BM6-BN6)/ABS(BN6),0) -> 0.033684141 | BS6: =IFERROR((BM6-BO6)/ABS(BO6),0) -> 0.0015138627 | BU6: =SUMIFS('P&L Data'!$N:$N,'P&L Data'!$B:$B,$D6,'P&L Data'!$C:$C,$BU$4) -> -902.48856 | BV6: =SUMIFS('P&L Data'!$P:$P,'P&L Data'!$B:$B,$D6,'P&L Data'!$C:$C,$BU$4) -> -902.48856 | BW6: =SUMIFS('P&L Data'!$T:$T,'P&L Data'!$B:$B,$D6,'P&L Data'!$C:$C,$BU$4) -> -902.48856 | BX6: =BU6-BV6 -> 0 | BY6: =BU6-BW6 -> 0 | BZ6: =IFERROR((BU6-BV6)/ABS(BV6),0) -> 0 | CA6: =IFERROR((BU6-BW6)/ABS(BW6),0) -> 0 | CC6: =SUMIFS('P&L Data'!$N:$N,'P&L Data'!$B:$B,$D6,'P&L Data'!$C:$C,$CC$4) -> 3648.5236 | CD6: =SUMIFS('P&L Data'!$P:$P,'P&L Data'!$B:$B,$D6,'P&L Data'!$C:$C,$CC$4) -> 3167.8126 | CE6: =SUMIFS('P&L Data'!$T:$T,'P&L Data'!$B:$B,$D6,'P&L Data'!$C:$C,$CC$4) -> 3192.1834 | CF6: =CC6-CD6 -> 480.71102 | CG6: =CC6-CE6 -> 456.34018 | CH6: =IFERROR((CC6-CD6)/ABS(CD6),0) -> 0.15174857 | CI6: =IFERROR((CC6-CE6)/ABS(CE6),0) -> 0.1429555 | CK6: =SUMIFS('P&L Data'!$N:$N,'P&L Data'!$B:$B,$D6,'P&L Data'!$C:$C,$CK$4) -> -835.3406 | CL6: =SUMIFS('P&L Data'!$P:$P,'P&L Data'!$B:$B,$D6,'P&L Data'!$C:$C,$CK$4) -> -836.24459 | CM6: =SUMIFS('P&L Data'!$T:$T,'P&L Data'!$B:$B,$D6,'P&L Data'!$C:$C,$CK$4) -> -912.70721 | CN6: =CK6-CL6 -> 0.90399 | CO6: =CK6-CM6 -> 77.36661 | CP6: =IFERROR((CK6-CL6)/ABS(CL6),0) -> 0.0010810115 | CQ6: =IFERROR((CK6-CM6)/ABS(CM6),0) -> 0.084766077 | CS6: =SUMIFS('P&L Data'!$N:$N,'P&L Data'!$B:$B,$D6,'P&L Data'!$C:$C,$CS$4) -> 2813.183 | CT6: =SUMIFS('P&L Data'!$P:$P,'P&L Data'!$B:$B,$D6,'P&L Data'!$C:$C,$CS$4) -> 2331.568 | CU6: =SUMIFS('P&L Data'!$T:$T,'P&L Data'!$B:$B,$D6,'P&L Data'!$C:$C,$CS$4) -> 2279.4762 | CV6: =CS6-CT6 -> 481.61501 | CW6: =CS6-CU6 -> 533.70679 | CX6: =IFERROR((CS6-CT6)/ABS(CT6),0) -> 0.20656271 | CY6: =IFERROR((CS6-CU6)/ABS(CU6),0) -> 0.23413571
B7: Central | C7: Riyadh - Crescent | D7: 10002 | E7: Rimal Mall | F7: Hyper | G7: LFL | I7: =SUMIFS('P&L Data'!$N:$N,'P&L Data'!$B:$B,$D7,'P&L Data'!$C:$C,$I$4) -> 22333.226 | J7: =SUMIFS('P&L Data'!$P:$P,'P&L Data'!$B:$B,$D7,'P&L Data'!$C:$C,$I$4) -> 19298.603 | K7: =SUMIFS('P&L Data'!$T:$T,'P&L Data'!$B:$B,$D7,'P&L Data'!$C:$C,$I$4) -> 22005.441 | L7: =I7-J7 -> 3034.6223 | M7: =I7-K7 -> 327.78493 | N7: =IFERROR((I7-J7)/ABS(J7),0) -> 0.1572457 | O7: =IFERROR((I7-K7)/ABS(K7),0) -> 0.014895631 | Q7: =SUMIFS('P&L Data'!$N:$N,'P&L Data'!$B:$B,$D7,'P&L Data'!$C:$C,$Q$4) -> 83.63492 | R7: =SUMIFS('P&L Data'!$P:$P,'P&L Data'!$B:$B,$D7,'P&L Data'!$C:$C,$Q$4) -> 758.14798 | S7: =SUMIFS('P&L Data'!$T:$T,'P&L Data'!$B:$B,$D7,'P&L Data'!$C:$C,$Q$4) -> 264.96195 | T7: =Q7-R7 -> -674.51306 | U7: =Q7-S7 -> -181.32703 | V7: =IFERROR((Q7-R7)/ABS(R7),0) -> -0.88968523 | W7: =IFERROR((Q7-S7)/ABS(S7),0) -> -0.68435121 | Y7: =SUMIFS('P&L Data'!$N:$N,'P&L Data'!$B:$B,$D7,'P&L Data'!$C:$C,$Y$4) -> 4679.696 | Z7: =SUMIFS('P&L Data'!$P:$P,'P&L Data'!$B:$B,$D7,'P&L Data'!$C:$C,$Y$4) -> 4649.7724 | AA7: =SUMIFS('P&L Data'!$T:$T,'P&L Data'!$B:$B,$D7,'P&L Data'!$C:$C,$Y$4) -> 4442.2341 | AB7: =Y7-Z7 -> 29.92362 | AC7: =Y7-AA7 -> 237.4619 | AD7: =IFERROR((Y7-Z7)/ABS(Z7),0) -> 0.0064355021 | AE7: =IFERROR((Y7-AA7)/ABS(AA7),0) -> 0.053455511 | AG7: =SUMIFS('P&L Data'!$N:$N,'P&L Data'!$B:$B,$D7,'P&L Data'!$C:$C,$AG$4) -> -78.40686 | AH7: =SUMIFS('P&L Data'!$P:$P,'P&L Data'!$B:$B,$D7,'P&L Data'!$C:$C,$AG$4) -> -128.90878 | AI7: =SUMIFS('P&L Data'!$T:$T,'P&L Data'!$B:$B,$D7,'P&L Data'!$C:$C,$AG$4) -> -131.65797 | AJ7: =AG7-AH7 -> 50.50192 | AK7: =AG7-AI7 -> 53.25111 | AL7: =IFERROR((AG7-AH7)/ABS(AH7),0) -> 0.39176478 | AM7: =IFERROR((AG7-AI7)/ABS(AI7),0) -> 0.40446553 | AO7: =SUMIFS('P&L Data'!$N:$N,'P&L Data'!$B:$B,$D7,'P&L Data'!$C:$C,$AO$4) -> -363.2698 | AP7: =SUMIFS('P&L Data'!$P:$P,'P&L Data'!$B:$B,$D7,'P&L Data'!$C:$C,$AO$4) -> -366.80482 | AQ7: =SUMIFS('P&L Data'!$T:$T,'P&L Data'!$B:$B,$D7,'P&L Data'!$C:$C,$AO$4) -> -332.60495 | AR7: =AO7-AP7 -> 3.53502 | AS7: =AO7-AQ7 -> -30.664848 | AT7: =IFERROR((AO7-AP7)/ABS(AP7),0) -> 0.0096373325 | AU7: =IFERROR((AO7-AQ7)/ABS(AQ7),0) -> -0.092196007 | AW7: =SUMIFS('P&L Data'!$N:$N,'P&L Data'!$B:$B,$D7,'P&L Data'!$C:$C,$AW$4) -> 4238.0194 | AX7: =SUMIFS('P&L Data'!$P:$P,'P&L Data'!$B:$B,$D7,'P&L Data'!$C:$C,$AW$4) -> 4154.0588 | AY7: =SUMIFS('P&L Data'!$T:$T,'P&L Data'!$B:$B,$D7,'P&L Data'!$C:$C,$AW$4) -> 3977.9712 | AZ7: =AW7-AX7 -> 83.96056 | BA7: =AW7-AY7 -> 260.04816 | BB7: =IFERROR((AW7-AX7)/ABS(AX7),0) -> 0.020211693 | BC7: =IFERROR((AW7-AY7)/ABS(AY7),0) -> 0.065372057 | BE7: =SUMIFS('P&L Data'!$N:$N,'P&L Data'!$B:$B,$D7,'P&L Data'!$C:$C,$BE$4) -> -1905.4051 | BF7: =SUMIFS('P&L Data'!$P:$P,'P&L Data'!$B:$B,$D7,'P&L Data'!$C:$C,$BE$4) -> -1677.6926 | BG7: =SUMIFS('P&L Data'!$T:$T,'P&L Data'!$B:$B,$D7,'P&L Data'!$C:$C,$BE$4) -> -2013.0302 | BH7: =BE7-BF7 -> -227.71245 | BI7: =BE7-BG7 -> 107.62508 | BJ7: =IFERROR((BE7-BF7)/ABS(BF7),0) -> -0.13572954 | BK7: =IFERROR((BE7-BG7)/ABS(BG7),0) -> 0.053464216 | BM7: =SUMIFS('P&L Data'!$N:$N,'P&L Data'!$B:$B,$D7,'P&L Data'!$C:$C,$BM$4) -> -1162.8406 | BN7: =SUMIFS('P&L Data'!$P:$P,'P&L Data'!$B:$B,$D7,'P&L Data'!$C:$C,$BM$4) -> -1170.7327 | BO7: =SUMIFS('P&L Data'!$T:$T,'P&L Data'!$B:$B,$D7,'P&L Data'!$C:$C,$BM$4) -> -1233.3777 | BP7: =BM7-BN7 -> 7.8921 | BQ7: =BM7-BO7 -> 70.53715 | BR7: =IFERROR((BM7-BN7)/ABS(BN7),0) -> 0.0067411631 | BS7: =IFERROR((BM7-BO7)/ABS(BO7),0) -> 0.057190225 | BU7: =SUMIFS('P&L Data'!$N:$N,'P&L Data'!$B:$B,$D7,'P&L Data'!$C:$C,$BU$4) -> -1290.9067 | BV7: =SUMIFS('P&L Data'!$P:$P,'P&L Data'!$B:$B,$D7,'P&L Data'!$C:$C,$BU$4) -> -897.84528 | BW7: =SUMIFS('P&L Data'!$T:$T,'P&L Data'!$B:$B,$D7,'P&L Data'!$C:$C,$BU$4) -> -1288.7741 | BX7: =BU7-BV7 -> -393.06144 | BY7: =BU7-BW7 -> -2.13258 | BZ7: =IFERROR((BU7-BV7)/ABS(BV7),0) -> -0.43778304 | CA7: =IFERROR((BU7-BW7)/ABS(BW7),0) -> -0.0016547353 | CC7: =SUMIFS('P&L Data'!$N:$N,'P&L Data'!$B:$B,$D7,'P&L Data'!$C:$C,$CC$4) -> -121.13301 | CD7: =SUMIFS('P&L Data'!$P:$P,'P&L Data'!$B:$B,$D7,'P&L Data'!$C:$C,$CC$4) -> 407.78822 | CE7: =SUMIFS('P&L Data'!$T:$T,'P&L Data'!$B:$B,$D7,'P&L Data'!$C:$C,$CC$4) -> -557.21082 | CF7: =CC7-CD7 -> -528.92123 | CG7: =CC7-CE7 -> 436.07781 | CH7: =IFERROR((CC7-CD7)/ABS(CD7),0) -> -1.2970488 | CI7: =IFERROR((CC7-CE7)/ABS(CE7),0) -> 0.7826083 | CK7: =SUMIFS('P&L Data'!$N:$N,'P&L Data'!$B:$B,$D7,'P&L Data'!$C:$C,$CK$4) -> -361.59676 | CL7: =SUMIFS('P&L Data'!$P:$P,'P&L Data'!$B:$B,$D7,'P&L Data'!$C:$C,$CK$4) -> -345.63358 | CM7: =SUMIFS('P&L Data'!$T:$T,'P&L Data'!$B:$B,$D7,'P&L Data'!$C:$C,$CK$4) -> -431.18724 | CN7: =CK7-CL7 -> -15.96318 | CO7: =CK7-CM7 -> 69.59048 | CP7: =IFERROR((CK7-CL7)/ABS(CL7),0) -> -0.046185269 | CQ7: =IFERROR((CK7-CM7)/ABS(CM7),0) -> 0.16139272 | CS7: =SUMIFS('P&L Data'!$N:$N,'P&L Data'!$B:$B,$D7,'P&L Data'!$C:$C,$CS$4) -> -482.72977 | CT7: =SUMIFS('P&L Data'!$P:$P,'P&L Data'!$B:$B,$D7,'P&L Data'!$C:$C,$CS$4) -> 62.15464 | CU7: =SUMIFS('P&L Data'!$T:$T,'P&L Data'!$B:$B,$D7,'P&L Data'!$C:$C,$CS$4) -> -988.39806 | CV7: =CS7-CT7 -> -544.88441 | CW7: =CS7-CU7 -> 505.66829 | CX7: =IFERROR((CS7-CT7)/ABS(CT7),0) -> -8.7665926 | CY7: =IFERROR((CS7-CU7)/ABS(CU7),0) -> 0.51160389
B8: Central | C8: Riyadh - Crescent Total | I8: =SUBTOTAL(9,I6:I7) -> 50203.544 | J8: =SUBTOTAL(9,J6:J7) -> 46666.916 | K8: =SUBTOTAL(9,K6:K7) -> 48178.191 | L8: =I8-J8 -> 3536.6277 | M8: =I8-K8 -> 2025.3525 | N8: =IFERROR((I8-J8)/ABS(J8),0) -> 0.075784475 | O8: =IFERROR((I8-K8)/ABS(K8),0) -> 0.042038782 | Q8: =SUBTOTAL(9,Q6:Q7) -> 2405.5351 | R8: =SUBTOTAL(9,R6:R7) -> 2874.9529 | S8: =SUBTOTAL(9,S6:S7) -> 2792.3201 | T8: =Q8-R8 -> -469.41786 | U8: =Q8-S8 -> -386.78503 | V8: =IFERROR((Q8-R8)/ABS(R8),0) -> -0.16327845 | W8: =IFERROR((Q8-S8)/ABS(S8),0) -> -0.13851744 | Y8: =SUBTOTAL(9,Y6:Y7) -> 12340.439 | Z8: =SUBTOTAL(9,Z6:Z7) -> 11839.765 | AA8: =SUBTOTAL(9,AA6:AA7) -> 11471.61 | AB8: =Y8-Z8 -> 500.67417 | AC8: =Y8-AA8 -> 868.82848 | AD8: =IFERROR((Y8-Z8)/ABS(Z8),0) -> 0.042287511 | AE8: =IFERROR((Y8-AA8)/ABS(AA8),0) -> 0.075737273 | AG8: =SUBTOTAL(9,AG6:AG7) -> -208.60116 | AH8: =SUBTOTAL(9,AH6:AH7) -> -278.12029 | AI8: =SUBTOTAL(9,AI6:AI7) -> -256.70883 | AJ8: =AG8-AH8 -> 69.51913 | AK8: =AG8-AI8 -> 48.10767 | AL8: =IFERROR((AG8-AH8)/ABS(AH8),0) -> 0.24996066 | AM8: =IFERROR((AG8-AI8)/ABS(AI8),0) -> 0.1874017 | AO8: =SUBTOTAL(9,AO6:AO7) -> -836.62492 | AP8: =SUBTOTAL(9,AP6:AP7) -> -872.67094 | AQ8: =SUBTOTAL(9,AQ6:AQ7) -> -734.13212 | AR8: =AO8-AP8 -> 36.04602 | AS8: =AO8-AQ8 -> -102.4928 | AT8: =IFERROR((AO8-AP8)/ABS(AP8),0) -> 0.041305397 | AU8: =IFERROR((AO8-AQ8)/ABS(AQ8),0) -> -0.13961084 | AW8: =SUBTOTAL(9,AW6:AW7) -> 11295.213 | AX8: =SUBTOTAL(9,AX6:AX7) -> 10688.973 | AY8: =SUBTOTAL(9,AY6:AY7) -> 10480.769 | AZ8: =AW8-AX8 -> 606.23932 | BA8: =AW8-AY8 -> 814.44335 | BB8: =IFERROR((AW8-AX8)/ABS(AX8),0) -> 0.056716328 | BC8: =IFERROR((AW8-AY8)/ABS(AY8),0) -> 0.077708355 | BE8: =SUBTOTAL(9,BE6:BE7) -> -3765.9477 | BF8: =SUBTOTAL(9,BF6:BF7) -> -3474.1617 | BG8: =SUBTOTAL(9,BG6:BG7) -> -3774.5389 | BH8: =BE8-BF8 -> -291.78606 | BI8: =BE8-BG8 -> 8.59118 | BJ8: =IFERROR((BE8-BF8)/ABS(BF8),0) -> -0.083987474 | BK8: =IFERROR((BE8-BG8)/ABS(BG8),0) -> 0.0022760873 | BM8: =SUBTOTAL(9,BM6:BM7) -> -1808.4791 | BN8: =SUBTOTAL(9,BN6:BN7) -> -1838.8771 | BO8: =SUBTOTAL(9,BO6:BO7) -> -1879.9951 | BP8: =BM8-BN8 -> 30.39797 | BQ8: =BM8-BO8 -> 71.51604 | BR8: =IFERROR((BM8-BN8)/ABS(BN8),0) -> 0.016530724 | BS8: =IFERROR((BM8-BO8)/ABS(BO8),0) -> 0.038040545 | BU8: =SUBTOTAL(9,BU6:BU7) -> -2193.3953 | BV8: =SUBTOTAL(9,BV6:BV7) -> -1800.3338 | BW8: =SUBTOTAL(9,BW6:BW7) -> -2191.2627 | BX8: =BU8-BV8 -> -393.06144 | BY8: =BU8-BW8 -> -2.13258 | BZ8: =IFERROR((BU8-BV8)/ABS(BV8),0) -> -0.21832697 | CA8: =IFERROR((BU8-BW8)/ABS(BW8),0) -> -0.00097321969 | CC8: =SUBTOTAL(9,CC6:CC7) -> 3527.3906 | CD8: =SUBTOTAL(9,CD6:CD7) -> 3575.6008 | CE8: =SUBTOTAL(9,CE6:CE7) -> 2634.9726 | CF8: =CC8-CD8 -> -48.21021 | CG8: =CC8-CE8 -> 892.41799 | CH8: =IFERROR((CC8-CD8)/ABS(CD8),0) -> -0.013483108 | CI8: =IFERROR((CC8-CE8)/ABS(CE8),0) -> 0.33868208 | CK8: =SUBTOTAL(9,CK6:CK7) -> -1196.9374 | CL8: =SUBTOTAL(9,CL6:CL7) -> -1181.8782 | CM8: =SUBTOTAL(9,CM6:CM7) -> -1343.8944 | CN8: =CK8-CL8 -> -15.05919 | CO8: =CK8-CM8 -> 146.95709 | CP8: =IFERROR((CK8-CL8)/ABS(CL8),0) -> -0.012741745 | CQ8: =IFERROR((CK8-CM8)/ABS(CM8),0) -> 0.10935166 | CS8: =SUBTOTAL(9,CS6:CS7) -> 2330.4532 | CT8: =SUBTOTAL(9,CT6:CT7) -> 2393.7226 | CU8: =SUBTOTAL(9,CU6:CU7) -> 1291.0781 | CV8: =SUBTOTAL(9,CV6:CV7) -> -63.2694 | CW8: =SUBTOTAL(9,CW6:CW7) -> 1039.3751 | CX8: =IFERROR((CS8-CT8)/ABS(CT8),0) -> -0.026431383 | CY8: =IFERROR((CS8-CU8)/ABS(CU8),0) -> 0.80504428
B9: Central | C9: Riyadh - Nucleus | D9: 10003 | E9: Alia Mall Abo Baker (Takassosi) | F9: Hyper | G9: LFL | I9: =SUMIFS('P&L Data'!$N:$N,'P&L Data'!$B:$B,$D9,'P&L Data'!$C:$C,$I$4) -> 34145.193 | J9: =SUMIFS('P&L Data'!$P:$P,'P&L Data'!$B:$B,$D9,'P&L Data'!$C:$C,$I$4) -> 34354.519 | K9: =SUMIFS('P&L Data'!$T:$T,'P&L Data'!$B:$B,$D9,'P&L Data'!$C:$C,$I$4) -> 31998.823 | L9: =I9-J9 -> -209.32589 | M9: =I9-K9 -> 2146.3701 | N9: =IFERROR((I9-J9)/ABS(J9),0) -> -0.0060931107 | O9: =IFERROR((I9-K9)/ABS(K9),0) -> 0.067076533 | Q9: =SUMIFS('P&L Data'!$N:$N,'P&L Data'!$B:$B,$D9,'P&L Data'!$C:$C,$Q$4) -> 3240.5851 | R9: =SUMIFS('P&L Data'!$P:$P,'P&L Data'!$B:$B,$D9,'P&L Data'!$C:$C,$Q$4) -> 2739.9401 | S9: =SUMIFS('P&L Data'!$T:$T,'P&L Data'!$B:$B,$D9,'P&L Data'!$C:$C,$Q$4) -> 2925.3352 | T9: =Q9-R9 -> 500.64503 | U9: =Q9-S9 -> 315.24988 | V9: =IFERROR((Q9-R9)/ABS(R9),0) -> 0.18272116 | W9: =IFERROR((Q9-S9)/ABS(S9),0) -> 0.10776539 | Y9: =SUMIFS('P&L Data'!$N:$N,'P&L Data'!$B:$B,$D9,'P&L Data'!$C:$C,$Y$4) -> 10062.44 | Z9: =SUMIFS('P&L Data'!$P:$P,'P&L Data'!$B:$B,$D9,'P&L Data'!$C:$C,$Y$4) -> 9378.7189 | AA9: =SUMIFS('P&L Data'!$T:$T,'P&L Data'!$B:$B,$D9,'P&L Data'!$C:$C,$Y$4) -> 8827.104 | AB9: =Y9-Z9 -> 683.72109 | AC9: =Y9-AA9 -> 1235.336 | AD9: =IFERROR((Y9-Z9)/ABS(Z9),0) -> 0.072901331 | AE9: =IFERROR((Y9-AA9)/ABS(AA9),0) -> 0.13994805 | AG9: =SUMIFS('P&L Data'!$N:$N,'P&L Data'!$B:$B,$D9,'P&L Data'!$C:$C,$AG$4) -> -116.60088 | AH9: =SUMIFS('P&L Data'!$P:$P,'P&L Data'!$B:$B,$D9,'P&L Data'!$C:$C,$AG$4) -> -213.42851 | AI9: =SUMIFS('P&L Data'!$T:$T,'P&L Data'!$B:$B,$D9,'P&L Data'!$C:$C,$AG$4) -> -182.12539 | AJ9: =AG9-AH9 -> 96.82763 | AK9: =AG9-AI9 -> 65.52451 | AL9: =IFERROR((AG9-AH9)/ABS(AH9),0) -> 0.45367711 | AM9: =IFERROR((AG9-AI9)/ABS(AI9),0) -> 0.35977691 | AO9: =SUMIFS('P&L Data'!$N:$N,'P&L Data'!$B:$B,$D9,'P&L Data'!$C:$C,$AO$4) -> -585.98803 | AP9: =SUMIFS('P&L Data'!$P:$P,'P&L Data'!$B:$B,$D9,'P&L Data'!$C:$C,$AO$4) -> -642.59945 | AQ9: =SUMIFS('P&L Data'!$T:$T,'P&L Data'!$B:$B,$D9,'P&L Data'!$C:$C,$AO$4) -> -527.19259 | AR9: =AO9-AP9 -> 56.61142 | AS9: =AO9-AQ9 -> -58.795442 | AT9: =IFERROR((AO9-AP9)/ABS(AP9),0) -> 0.088097523 | AU9: =IFERROR((AO9-AQ9)/ABS(AQ9),0) -> -0.11152555 | AW9: =SUMIFS('P&L Data'!$N:$N,'P&L Data'!$B:$B,$D9,'P&L Data'!$C:$C,$AW$4) -> 9359.8511 | AX9: =SUMIFS('P&L Data'!$P:$P,'P&L Data'!$B:$B,$D9,'P&L Data'!$C:$C,$AW$4) -> 8522.691 | AY9: =SUMIFS('P&L Data'!$T:$T,'P&L Data'!$B:$B,$D9,'P&L Data'!$C:$C,$AW$4) -> 8117.786 | AZ9: =AW9-AX9 -> 837.16014 | BA9: =AW9-AY9 -> 1242.0651 | BB9: =IFERROR((AW9-AX9)/ABS(AX9),0) -> 0.098227208 | BC9: =IFERROR((AW9-AY9)/ABS(AY9),0) -> 0.1530054 | BE9: =SUMIFS('P&L Data'!$N:$N,'P&L Data'!$B:$B,$D9,'P&L Data'!$C:$C,$BE$4) -> -2290.0799 | BF9: =SUMIFS('P&L Data'!$P:$P,'P&L Data'!$B:$B,$D9,'P&L Data'!$C:$C,$BE$4) -> -2526.8343 | BG9: =SUMIFS('P&L Data'!$T:$T,'P&L Data'!$B:$B,$D9,'P&L Data'!$C:$C,$BE$4) -> -2193.1746 | BH9: =BE9-BF9 -> 236.75443 | BI9: =BE9-BG9 -> -96.9053 | BJ9: =IFERROR((BE9-BF9)/ABS(BF9),0) -> 0.093696064 | BK9: =IFERROR((BE9-BG9)/ABS(BG9),0) -> -0.044184945 | BM9: =SUMIFS('P&L Data'!$N:$N,'P&L Data'!$B:$B,$D9,'P&L Data'!$C:$C,$BM$4) -> -1038.9385 | BN9: =SUMIFS('P&L Data'!$P:$P,'P&L Data'!$B:$B,$D9,'P&L Data'!$C:$C,$BM$4) -> -1035.2243 | BO9: =SUMIFS('P&L Data'!$T:$T,'P&L Data'!$B:$B,$D9,'P&L Data'!$C:$C,$BM$4) -> -1121.4782 | BP9: =BM9-BN9 -> -3.71424 | BQ9: =BM9-BO9 -> 82.53972 | BR9: =IFERROR((BM9-BN9)/ABS(BN9),0) -> -0.0035878602 | BS9: =IFERROR((BM9-BO9)/ABS(BO9),0) -> 0.073599038 | BU9: =SUMIFS('P&L Data'!$N:$N,'P&L Data'!$B:$B,$D9,'P&L Data'!$C:$C,$BU$4) -> -2279.4567 | BV9: =SUMIFS('P&L Data'!$P:$P,'P&L Data'!$B:$B,$D9,'P&L Data'!$C:$C,$BU$4) -> -2279.4567 | BW9: =SUMIFS('P&L Data'!$T:$T,'P&L Data'!$B:$B,$D9,'P&L Data'!$C:$C,$BU$4) -> -2279.4567 | BX9: =BU9-BV9 -> 0 | BY9: =BU9-BW9 -> 0 | BZ9: =IFERROR((BU9-BV9)/ABS(BV9),0) -> 0 | CA9: =IFERROR((BU9-BW9)/ABS(BW9),0) -> 0 | CC9: =SUMIFS('P&L Data'!$N:$N,'P&L Data'!$B:$B,$D9,'P&L Data'!$C:$C,$CC$4) -> 3751.376 | CD9: =SUMIFS('P&L Data'!$P:$P,'P&L Data'!$B:$B,$D9,'P&L Data'!$C:$C,$CC$4) -> 2681.1757 | CE9: =SUMIFS('P&L Data'!$T:$T,'P&L Data'!$B:$B,$D9,'P&L Data'!$C:$C,$CC$4) -> 2523.6765 | CF9: =CC9-CD9 -> 1070.2003 | CG9: =CC9-CE9 -> 1227.6995 | CH9: =IFERROR((CC9-CD9)/ABS(CD9),0) -> 0.39915338 | CI9: =IFERROR((CC9-CE9)/ABS(CE9),0) -> 0.48647262 | CK9: =SUMIFS('P&L Data'!$N:$N,'P&L Data'!$B:$B,$D9,'P&L Data'!$C:$C,$CK$4) -> -1342.0394 | CL9: =SUMIFS('P&L Data'!$P:$P,'P&L Data'!$B:$B,$D9,'P&L Data'!$C:$C,$CK$4) -> -951.3892 | CM9: =SUMIFS('P&L Data'!$T:$T,'P&L Data'!$B:$B,$D9,'P&L Data'!$C:$C,$CK$4) -> -1133.7776 | CN9: =CK9-CL9 -> -390.65016 | CO9: =CK9-CM9 -> -208.26174 | CP9: =IFERROR((CK9-CL9)/ABS(CL9),0) -> -0.41061025 | CQ9: =IFERROR((CK9-CM9)/ABS(CM9),0) -> -0.18368835 | CS9: =SUMIFS('P&L Data'!$N:$N,'P&L Data'!$B:$B,$D9,'P&L Data'!$C:$C,$CS$4) -> 2409.3367 | CT9: =SUMIFS('P&L Data'!$P:$P,'P&L Data'!$B:$B,$D9,'P&L Data'!$C:$C,$CS$4) -> 1729.7865 | CU9: =SUMIFS('P&L Data'!$T:$T,'P&L Data'!$B:$B,$D9,'P&L Data'!$C:$C,$CS$4) -> 1389.8989 | CV9: =CS9-CT9 -> 679.55017 | CW9: =CS9-CU9 -> 1019.4378 | CX9: =IFERROR((CS9-CT9)/ABS(CT9),0) -> 0.39285205 | CY9: =IFERROR((CS9-CU9)/ABS(CU9),0) -> 0.73346183
B10: Central | C10: Riyadh - Nucleus Total | I10: =SUBTOTAL(9,I9:I9) -> 34145.193 | J10: =SUBTOTAL(9,J9:J9) -> 34354.519 | K10: =SUBTOTAL(9,K9:K9) -> 31998.823 | L10: =I10-J10 -> -209.32589 | M10: =I10-K10 -> 2146.3701 | N10: =IFERROR((I10-J10)/ABS(J10),0) -> -0.0060931107 | O10: =IFERROR((I10-K10)/ABS(K10),0) -> 0.067076533 | Q10: =SUBTOTAL(9,Q9:Q9) -> 3240.5851 | R10: =SUBTOTAL(9,R9:R9) -> 2739.9401 | S10: =SUBTOTAL(9,S9:S9) -> 2925.3352 | T10: =Q10-R10 -> 500.64503 | U10: =Q10-S10 -> 315.24988 | V10: =IFERROR((Q10-R10)/ABS(R10),0) -> 0.18272116 | W10: =IFERROR((Q10-S10)/ABS(S10),0) -> 0.10776539 | Y10: =SUBTOTAL(9,Y9:Y9) -> 10062.44 | Z10: =SUBTOTAL(9,Z9:Z9) -> 9378.7189 | AA10: =SUBTOTAL(9,AA9:AA9) -> 8827.104 | AB10: =Y10-Z10 -> 683.72109 | AC10: =Y10-AA10 -> 1235.336 | AD10: =IFERROR((Y10-Z10)/ABS(Z10),0) -> 0.072901331 | AE10: =IFERROR((Y10-AA10)/ABS(AA10),0) -> 0.13994805 | AG10: =SUBTOTAL(9,AG9:AG9) -> -116.60088 | AH10: =SUBTOTAL(9,AH9:AH9) -> -213.42851 | AI10: =SUBTOTAL(9,AI9:AI9) -> -182.12539 | AJ10: =AG10-AH10 -> 96.82763 | AK10: =AG10-AI10 -> 65.52451 | AL10: =IFERROR((AG10-AH10)/ABS(AH10),0) -> 0.45367711 | AM10: =IFERROR((AG10-AI10)/ABS(AI10),0) -> 0.35977691 | AO10: =SUBTOTAL(9,AO9:AO9) -> -585.98803 | AP10: =SUBTOTAL(9,AP9:AP9) -> -642.59945 | AQ10: =SUBTOTAL(9,AQ9:AQ9) -> -527.19259 | AR10: =AO10-AP10 -> 56.61142 | AS10: =AO10-AQ10 -> -58.795442 | AT10: =IFERROR((AO10-AP10)/ABS(AP10),0) -> 0.088097523 | AU10: =IFERROR((AO10-AQ10)/ABS(AQ10),0) -> -0.11152555 | AW10: =SUBTOTAL(9,AW9:AW9) -> 9359.8511 | AX10: =SUBTOTAL(9,AX9:AX9) -> 8522.691 | AY10: =SUBTOTAL(9,AY9:AY9) -> 8117.786 | AZ10: =AW10-AX10 -> 837.16014 | BA10: =AW10-AY10 -> 1242.0651 | BB10: =IFERROR((AW10-AX10)/ABS(AX10),0) -> 0.098227208 | BC10: =IFERROR((AW10-AY10)/ABS(AY10),0) -> 0.1530054 | BE10: =SUBTOTAL(9,BE9:BE9) -> -2290.0799 | BF10: =SUBTOTAL(9,BF9:BF9) -> -2526.8343 | BG10: =SUBTOTAL(9,BG9:BG9) -> -2193.1746 | BH10: =BE10-BF10 -> 236.75443 | BI10: =BE10-BG10 -> -96.9053 | BJ10: =IFERROR((BE10-BF10)/ABS(BF10),0) -> 0.093696064 | BK10: =IFERROR((BE10-BG10)/ABS(BG10),0) -> -0.044184945 | BM10: =SUBTOTAL(9,BM9:BM9) -> -1038.9385 | BN10: =SUBTOTAL(9,BN9:BN9) -> -1035.2243 | BO10: =SUBTOTAL(9,BO9:BO9) -> -1121.4782 | BP10: =BM10-BN10 -> -3.71424 | BQ10: =BM10-BO10 -> 82.53972 | BR10: =IFERROR((BM10-BN10)/ABS(BN10),0) -> -0.0035878602 | BS10: =IFERROR((BM10-BO10)/ABS(BO10),0) -> 0.073599038 | BU10: =SUBTOTAL(9,BU9:BU9) -> -2279.4567 | BV10: =SUBTOTAL(9,BV9:BV9) -> -2279.4567 | BW10: =SUBTOTAL(9,BW9:BW9) -> -2279.4567 | BX10: =BU10-BV10 -> 0 | BY10: =BU10-BW10 -> 0 | BZ10: =IFERROR((BU10-BV10)/ABS(BV10),0) -> 0 | CA10: =IFERROR((BU10-BW10)/ABS(BW10),0) -> 0 | CC10: =SUBTOTAL(9,CC9:CC9) -> 3751.376 | CD10: =SUBTOTAL(9,CD9:CD9) -> 2681.1757 | CE10: =SUBTOTAL(9,CE9:CE9) -> 2523.6765 | CF10: =CC10-CD10 -> 1070.2003 | CG10: =CC10-CE10 -> 1227.6995 | CH10: =IFERROR((CC10-CD10)/ABS(CD10),0) -> 0.39915338 | CI10: =IFERROR((CC10-CE10)/ABS(CE10),0) -> 0.48647262 | CK10: =SUBTOTAL(9,CK9:CK9) -> -1342.0394 | CL10: =SUBTOTAL(9,CL9:CL9) -> -951.3892 | CM10: =SUBTOTAL(9,CM9:CM9) -> -1133.7776 | CN10: =CK10-CL10 -> -390.65016 | CO10: =CK10-CM10 -> -208.26174 | CP10: =IFERROR((CK10-CL10)/ABS(CL10),0) -> -0.41061025 | CQ10: =IFERROR((CK10-CM10)/ABS(CM10),0) -> -0.18368835 | CS10: =SUBTOTAL(9,CS9:CS9) -> 2409.3367 | CT10: =SUBTOTAL(9,CT9:CT9) -> 1729.7865 | CU10: =SUBTOTAL(9,CU9:CU9) -> 1389.8989 | CV10: =SUBTOTAL(9,CV9:CV9) -> 679.55017 | CW10: =SUBTOTAL(9,CW9:CW9) -> 1019.4378 | CX10: =IFERROR((CS10-CT10)/ABS(CT10),0) -> 0.39285205 | CY10: =IFERROR((CS10-CU10)/ABS(CU10),0) -> 0.73346183
B11: Central | C11: Riyadh - South | D11: 102 | E11: Al Tarmathi | F11: Super | G11: LFL | I11: =SUMIFS('P&L Data'!$N:$N,'P&L Data'!$B:$B,$D11,'P&L Data'!$C:$C,$I$4) -> 10993.125 | J11: =SUMIFS('P&L Data'!$P:$P,'P&L Data'!$B:$B,$D11,'P&L Data'!$C:$C,$I$4) -> 11612.472 | K11: =SUMIFS('P&L Data'!$T:$T,'P&L Data'!$B:$B,$D11,'P&L Data'!$C:$C,$I$4) -> 11815.73 | L11: =I11-J11 -> -619.34621 | M11: =I11-K11 -> -822.60448 | N11: =IFERROR((I11-J11)/ABS(J11),0) -> -0.053334572 | O11: =IFERROR((I11-K11)/ABS(K11),0) -> -0.069619438 | Q11: =SUMIFS('P&L Data'!$N:$N,'P&L Data'!$B:$B,$D11,'P&L Data'!$C:$C,$Q$4) -> 395.85014 | R11: =SUMIFS('P&L Data'!$P:$P,'P&L Data'!$B:$B,$D11,'P&L Data'!$C:$C,$Q$4) -> 551.63802 | S11: =SUMIFS('P&L Data'!$T:$T,'P&L Data'!$B:$B,$D11,'P&L Data'!$C:$C,$Q$4) -> 661.04016 | T11: =Q11-R11 -> -155.78788 | U11: =Q11-S11 -> -265.19002 | V11: =IFERROR((Q11-R11)/ABS(R11),0) -> -0.28240961 | W11: =IFERROR((Q11-S11)/ABS(S11),0) -> -0.40117082 | Y11: =SUMIFS('P&L Data'!$N:$N,'P&L Data'!$B:$B,$D11,'P&L Data'!$C:$C,$Y$4) -> 2655.0971 | Z11: =SUMIFS('P&L Data'!$P:$P,'P&L Data'!$B:$B,$D11,'P&L Data'!$C:$C,$Y$4) -> 2773.7705 | AA11: =SUMIFS('P&L Data'!$T:$T,'P&L Data'!$B:$B,$D11,'P&L Data'!$C:$C,$Y$4) -> 2784.314 | AB11: =Y11-Z11 -> -118.67342 | AC11: =Y11-AA11 -> -129.21693 | AD11: =IFERROR((Y11-Z11)/ABS(Z11),0) -> -0.042784152 | AE11: =IFERROR((Y11-AA11)/ABS(AA11),0) -> -0.046408894 | AG11: =SUMIFS('P&L Data'!$N:$N,'P&L Data'!$B:$B,$D11,'P&L Data'!$C:$C,$AG$4) -> -5.22213 | AH11: =SUMIFS('P&L Data'!$P:$P,'P&L Data'!$B:$B,$D11,'P&L Data'!$C:$C,$AG$4) -> -70.92856 | AI11: =SUMIFS('P&L Data'!$T:$T,'P&L Data'!$B:$B,$D11,'P&L Data'!$C:$C,$AG$4) -> -52.02357 | AJ11: =AG11-AH11 -> 65.70643 | AK11: =AG11-AI11 -> 46.80144 | AL11: =IFERROR((AG11-AH11)/ABS(AH11),0) -> 0.92637479 | AM11: =IFERROR((AG11-AI11)/ABS(AI11),0) -> 0.89961992 | AO11: =SUMIFS('P&L Data'!$N:$N,'P&L Data'!$B:$B,$D11,'P&L Data'!$C:$C,$AO$4) -> -195.52834 | AP11: =SUMIFS('P&L Data'!$P:$P,'P&L Data'!$B:$B,$D11,'P&L Data'!$C:$C,$AO$4) -> -212.42066 | AQ11: =SUMIFS('P&L Data'!$T:$T,'P&L Data'!$B:$B,$D11,'P&L Data'!$C:$C,$AO$4) -> -190.27486 | AR11: =AO11-AP11 -> 16.89232 | AS11: =AO11-AQ11 -> -5.25348 | AT11: =IFERROR((AO11-AP11)/ABS(AP11),0) -> 0.079522962 | AU11: =IFERROR((AO11-AQ11)/ABS(AQ11),0) -> -0.027609953 | AW11: =SUMIFS('P&L Data'!$N:$N,'P&L Data'!$B:$B,$D11,'P&L Data'!$C:$C,$AW$4) -> 2454.3466 | AX11: =SUMIFS('P&L Data'!$P:$P,'P&L Data'!$B:$B,$D11,'P&L Data'!$C:$C,$AW$4) -> 2490.4213 | AY11: =SUMIFS('P&L Data'!$T:$T,'P&L Data'!$B:$B,$D11,'P&L Data'!$C:$C,$AW$4) -> 2542.0156 | AZ11: =AW11-AX11 -> -36.07467 | BA11: =AW11-AY11 -> -87.668973 | BB11: =IFERROR((AW11-AX11)/ABS(AX11),0) -> -0.014485368 | BC11: =IFERROR((AW11-AY11)/ABS(AY11),0) -> -0.034487976 | BE11: =SUMIFS('P&L Data'!$N:$N,'P&L Data'!$B:$B,$D11,'P&L Data'!$C:$C,$BE$4) -> -903.23325 | BF11: =SUMIFS('P&L Data'!$P:$P,'P&L Data'!$B:$B,$D11,'P&L Data'!$C:$C,$BE$4) -> -796.75625 | BG11: =SUMIFS('P&L Data'!$T:$T,'P&L Data'!$B:$B,$D11,'P&L Data'!$C:$C,$BE$4) -> -798.84041 | BH11: =BE11-BF11 -> -106.477 | BI11: =BE11-BG11 -> -104.39284 | BJ11: =IFERROR((BE11-BF11)/ABS(BF11),0) -> -0.13363811 | BK11: =IFERROR((BE11-BG11)/ABS(BG11),0) -> -0.13068047 | BM11: =SUMIFS('P&L Data'!$N:$N,'P&L Data'!$B:$B,$D11,'P&L Data'!$C:$C,$BM$4) -> -238.59393 | BN11: =SUMIFS('P&L Data'!$P:$P,'P&L Data'!$B:$B,$D11,'P&L Data'!$C:$C,$BM$4) -> -260.27438 | BO11: =SUMIFS('P&L Data'!$T:$T,'P&L Data'!$B:$B,$D11,'P&L Data'!$C:$C,$BM$4) -> -240.64897 | BP11: =BM11-BN11 -> 21.68045 | BQ11: =BM11-BO11 -> 2.05504 | BR11: =IFERROR((BM11-BN11)/ABS(BN11),0) -> 0.083298441 | BS11: =IFERROR((BM11-BO11)/ABS(BO11),0) -> 0.0085395753 | BU11: =SUMIFS('P&L Data'!$N:$N,'P&L Data'!$B:$B,$D11,'P&L Data'!$C:$C,$BU$4) -> -827.4336 | BV11: =SUMIFS('P&L Data'!$P:$P,'P&L Data'!$B:$B,$D11,'P&L Data'!$C:$C,$BU$4) -> -827.4336 | BW11: =SUMIFS('P&L Data'!$T:$T,'P&L Data'!$B:$B,$D11,'P&L Data'!$C:$C,$BU$4) -> -827.4336 | BX11: =BU11-BV11 -> 0 | BY11: =BU11-BW11 -> 0 | BZ11: =IFERROR((BU11-BV11)/ABS(BV11),0) -> 0 | CA11: =IFERROR((BU11-BW11)/ABS(BW11),0) -> 0 | CC11: =SUMIFS('P&L Data'!$N:$N,'P&L Data'!$B:$B,$D11,'P&L Data'!$C:$C,$CC$4) -> 485.08585 | CD11: =SUMIFS('P&L Data'!$P:$P,'P&L Data'!$B:$B,$D11,'P&L Data'!$C:$C,$CC$4) -> 605.95707 | CE11: =SUMIFS('P&L Data'!$T:$T,'P&L Data'!$B:$B,$D11,'P&L Data'!$C:$C,$CC$4) -> 675.09262 | CF11: =CC11-CD11 -> -120.87122 | CG11: =CC11-CE11 -> -190.00677 | CH11: =IFERROR((CC11-CD11)/ABS(CD11),0) -> -0.19947159 | CI11: =IFERROR((CC11-CE11)/ABS(CE11),0) -> -0.2814529 | CK11: =SUMIFS('P&L Data'!$N:$N,'P&L Data'!$B:$B,$D11,'P&L Data'!$C:$C,$CK$4) -> -88.80584 | CL11: =SUMIFS('P&L Data'!$P:$P,'P&L Data'!$B:$B,$D11,'P&L Data'!$C:$C,$CK$4) -> -292.64342 | CM11: =SUMIFS('P&L Data'!$T:$T,'P&L Data'!$B:$B,$D11,'P&L Data'!$C:$C,$CK$4) -> -63.60393 | CN11: =CK11-CL11 -> 203.83758 | CO11: =CK11-CM11 -> -25.20191 | CP11: =IFERROR((CK11-CL11)/ABS(CL11),0) -> 0.69653909 | CQ11: =IFERROR((CK11-CM11)/ABS(CM11),0) -> -0.39623196 | CS11: =SUMIFS('P&L Data'!$N:$N,'P&L Data'!$B:$B,$D11,'P&L Data'!$C:$C,$CS$4) -> 396.28001 | CT11: =SUMIFS('P&L Data'!$P:$P,'P&L Data'!$B:$B,$D11,'P&L Data'!$C:$C,$CS$4) -> 313.31365 | CU11: =SUMIFS('P&L Data'!$T:$T,'P&L Data'!$B:$B,$D11,'P&L Data'!$C:$C,$CS$4) -> 611.48869 | CV11: =CS11-CT11 -> 82.96636 | CW11: =CS11-CU11 -> -215.20868 | CX11: =IFERROR((CS11-CT11)/ABS(CT11),0) -> 0.26480289 | CY11: =IFERROR((CS11-CU11)/ABS(CU11),0) -> -0.35194221
B12: Central | C12: Riyadh - South | D12: 10006 | E12: Gs Riyadh Bilal Abn Rabah | F12: Hyper | G12: LFL | I12: =SUMIFS('P&L Data'!$N:$N,'P&L Data'!$B:$B,$D12,'P&L Data'!$C:$C,$I$4) -> 30028.574 | J12: =SUMIFS('P&L Data'!$P:$P,'P&L Data'!$B:$B,$D12,'P&L Data'!$C:$C,$I$4) -> 29761.367 | K12: =SUMIFS('P&L Data'!$T:$T,'P&L Data'!$B:$B,$D12,'P&L Data'!$C:$C,$I$4) -> 26778.883 | L12: =I12-J12 -> 267.20704 | M12: =I12-K12 -> 3249.6911 | N12: =IFERROR((I12-J12)/ABS(J12),0) -> 0.0089783187 | O12: =IFERROR((I12-K12)/ABS(K12),0) -> 0.12135275 | Q12: =SUMIFS('P&L Data'!$N:$N,'P&L Data'!$B:$B,$D12,'P&L Data'!$C:$C,$Q$4) -> 1738.5654 | R12: =SUMIFS('P&L Data'!$P:$P,'P&L Data'!$B:$B,$D12,'P&L Data'!$C:$C,$Q$4) -> 2048.3363 | S12: =SUMIFS('P&L Data'!$T:$T,'P&L Data'!$B:$B,$D12,'P&L Data'!$C:$C,$Q$4) -> 1408.0058 | T12: =Q12-R12 -> -309.77083 | U12: =Q12-S12 -> 330.55965 | V12: =IFERROR((Q12-R12)/ABS(R12),0) -> -0.15123046 | W12: =IFERROR((Q12-S12)/ABS(S12),0) -> 0.23477151 | Y12: =SUMIFS('P&L Data'!$N:$N,'P&L Data'!$B:$B,$D12,'P&L Data'!$C:$C,$Y$4) -> 7752.3435 | Z12: =SUMIFS('P&L Data'!$P:$P,'P&L Data'!$B:$B,$D12,'P&L Data'!$C:$C,$Y$4) -> 7845.5533 | AA12: =SUMIFS('P&L Data'!$T:$T,'P&L Data'!$B:$B,$D12,'P&L Data'!$C:$C,$Y$4) -> 6306.9863 | AB12: =Y12-Z12 -> -93.20983 | AC12: =Y12-AA12 -> 1445.3572 | AD12: =IFERROR((Y12-Z12)/ABS(Z12),0) -> -0.011880594 | AE12: =IFERROR((Y12-AA12)/ABS(AA12),0) -> 0.22916764 | AG12: =SUMIFS('P&L Data'!$N:$N,'P&L Data'!$B:$B,$D12,'P&L Data'!$C:$C,$AG$4) -> -142.56481 | AH12: =SUMIFS('P&L Data'!$P:$P,'P&L Data'!$B:$B,$D12,'P&L Data'!$C:$C,$AG$4) -> -179.24663 | AI12: =SUMIFS('P&L Data'!$T:$T,'P&L Data'!$B:$B,$D12,'P&L Data'!$C:$C,$AG$4) -> -216.39312 | AJ12: =AG12-AH12 -> 36.68182 | AK12: =AG12-AI12 -> 73.82831 | AL12: =IFERROR((AG12-AH12)/ABS(AH12),0) -> 0.20464441 | AM12: =IFERROR((AG12-AI12)/ABS(AI12),0) -> 0.34117679 | AO12: =SUMIFS('P&L Data'!$N:$N,'P&L Data'!$B:$B,$D12,'P&L Data'!$C:$C,$AO$4) -> -470.73721 | AP12: =SUMIFS('P&L Data'!$P:$P,'P&L Data'!$B:$B,$D12,'P&L Data'!$C:$C,$AO$4) -> -543.3718 | AQ12: =SUMIFS('P&L Data'!$T:$T,'P&L Data'!$B:$B,$D12,'P&L Data'!$C:$C,$AO$4) -> -403.45968 | AR12: =AO12-AP12 -> 72.63459 | AS12: =AO12-AQ12 -> -67.27753 | AT12: =IFERROR((AO12-AP12)/ABS(AP12),0) -> 0.13367383 | AU12: =IFERROR((AO12-AQ12)/ABS(AQ12),0) -> -0.16675156 | AW12: =SUMIFS('P&L Data'!$N:$N,'P&L Data'!$B:$B,$D12,'P&L Data'!$C:$C,$AW$4) -> 7139.0415 | AX12: =SUMIFS('P&L Data'!$P:$P,'P&L Data'!$B:$B,$D12,'P&L Data'!$C:$C,$AW$4) -> 7122.9349 | AY12: =SUMIFS('P&L Data'!$T:$T,'P&L Data'!$B:$B,$D12,'P&L Data'!$C:$C,$AW$4) -> 5687.1335 | AZ12: =AW12-AX12 -> 16.10658 | BA12: =AW12-AY12 -> 1451.908 | BB12: =IFERROR((AW12-AX12)/ABS(AX12),0) -> 0.002261228 | BC12: =IFERROR((AW12-AY12)/ABS(AY12),0) -> 0.25529697 | BE12: =SUMIFS('P&L Data'!$N:$N,'P&L Data'!$B:$B,$D12,'P&L Data'!$C:$C,$BE$4) -> -2316.1441 | BF12: =SUMIFS('P&L Data'!$P:$P,'P&L Data'!$B:$B,$D12,'P&L Data'!$C:$C,$BE$4) -> -2367.5976 | BG12: =SUMIFS('P&L Data'!$T:$T,'P&L Data'!$B:$B,$D12,'P&L Data'!$C:$C,$BE$4) -> -2336.4651 | BH12: =BE12-BF12 -> 51.45346 | BI12: =BE12-BG12 -> 20.32096 | BJ12: =IFERROR((BE12-BF12)/ABS(BF12),0) -> 0.02173235 | BK12: =IFERROR((BE12-BG12)/ABS(BG12),0) -> 0.0086973096 | BM12: =SUMIFS('P&L Data'!$N:$N,'P&L Data'!$B:$B,$D12,'P&L Data'!$C:$C,$BM$4) -> -384.97124 | BN12: =SUMIFS('P&L Data'!$P:$P,'P&L Data'!$B:$B,$D12,'P&L Data'!$C:$C,$BM$4) -> -504.2741 | BO12: =SUMIFS('P&L Data'!$T:$T,'P&L Data'!$B:$B,$D12,'P&L Data'!$C:$C,$BM$4) -> -549.56835 | BP12: =BM12-BN12 -> 119.30286 | BQ12: =BM12-BO12 -> 164.59711 | BR12: =IFERROR((BM12-BN12)/ABS(BN12),0) -> 0.23658336 | BS12: =IFERROR((BM12-BO12)/ABS(BO12),0) -> 0.29950253 | BU12: =SUMIFS('P&L Data'!$N:$N,'P&L Data'!$B:$B,$D12,'P&L Data'!$C:$C,$BU$4) -> -955.70293 | BV12: =SUMIFS('P&L Data'!$P:$P,'P&L Data'!$B:$B,$D12,'P&L Data'!$C:$C,$BU$4) -> -921.15968 | BW12: =SUMIFS('P&L Data'!$T:$T,'P&L Data'!$B:$B,$D12,'P&L Data'!$C:$C,$BU$4) -> -921.15968 | BX12: =BU12-BV12 -> -34.54325 | BY12: =BU12-BW12 -> -34.54325 | BZ12: =IFERROR((BU12-BV12)/ABS(BV12),0) -> -0.037499742 | CA12: =IFERROR((BU12-BW12)/ABS(BW12),0) -> -0.037499742 | CC12: =SUMIFS('P&L Data'!$N:$N,'P&L Data'!$B:$B,$D12,'P&L Data'!$C:$C,$CC$4) -> 3482.2232 | CD12: =SUMIFS('P&L Data'!$P:$P,'P&L Data'!$B:$B,$D12,'P&L Data'!$C:$C,$CC$4) -> 3329.9036 | CE12: =SUMIFS('P&L Data'!$T:$T,'P&L Data'!$B:$B,$D12,'P&L Data'!$C:$C,$CC$4) -> 1879.9404 | CF12: =CC12-CD12 -> 152.31965 | CG12: =CC12-CE12 -> 1602.2828 | CH12: =IFERROR((CC12-CD12)/ABS(CD12),0) -> 0.045742962 | CI12: =IFERROR((CC12-CE12)/ABS(CE12),0) -> 0.85230509 | CK12: =SUMIFS('P&L Data'!$N:$N,'P&L Data'!$B:$B,$D12,'P&L Data'!$C:$C,$CK$4) -> -1215.0372 | CL12: =SUMIFS('P&L Data'!$P:$P,'P&L Data'!$B:$B,$D12,'P&L Data'!$C:$C,$CK$4) -> -772.30307 | CM12: =SUMIFS('P&L Data'!$T:$T,'P&L Data'!$B:$B,$D12,'P&L Data'!$C:$C,$CK$4) -> -516.69898 | CN12: =CK12-CL12 -> -442.73417 | CO12: =CK12-CM12 -> -698.33826 | CP12: =IFERROR((CK12-CL12)/ABS(CL12),0) -> -0.57326481 | CQ12: =IFERROR((CK12-CM12)/ABS(CM12),0) -> -1.3515379 | CS12: =SUMIFS('P&L Data'!$N:$N,'P&L Data'!$B:$B,$D12,'P&L Data'!$C:$C,$CS$4) -> 2267.186 | CT12: =SUMIFS('P&L Data'!$P:$P,'P&L Data'!$B:$B,$D12,'P&L Data'!$C:$C,$CS$4) -> 2557.6005 | CU12: =SUMIFS('P&L Data'!$T:$T,'P&L Data'!$B:$B,$D12,'P&L Data'!$C:$C,$CS$4) -> 1363.2414 | CV12: =CS12-CT12 -> -290.41452 | CW12: =CS12-CU12 -> 903.94453 | CX12: =IFERROR((CS12-CT12)/ABS(CT12),0) -> -0.1135496 | CY12: =IFERROR((CS12-CU12)/ABS(CU12),0) -> 0.66308469
B13: Central | C13: Riyadh - South Total | I13: =SUBTOTAL(9,I11:I12) -> 41021.7 | J13: =SUBTOTAL(9,J11:J12) -> 41373.839 | K13: =SUBTOTAL(9,K11:K12) -> 38594.613 | L13: =I13-J13 -> -352.13917 | M13: =I13-K13 -> 2427.0866 | N13: =IFERROR((I13-J13)/ABS(J13),0) -> -0.0085111553 | O13: =IFERROR((I13-K13)/ABS(K13),0) -> 0.062886668 | Q13: =SUBTOTAL(9,Q11:Q12) -> 2134.4156 | R13: =SUBTOTAL(9,R11:R12) -> 2599.9743 | S13: =SUBTOTAL(9,S11:S12) -> 2069.046 | T13: =Q13-R13 -> -465.55871 | U13: =Q13-S13 -> 65.369625 | V13: =IFERROR((Q13-R13)/ABS(R13),0) -> -0.17906281 | W13: =IFERROR((Q13-S13)/ABS(S13),0) -> 0.031594091 | Y13: =SUBTOTAL(9,Y11:Y12) -> 10407.441 | Z13: =SUBTOTAL(9,Z11:Z12) -> 10619.324 | AA13: =SUBTOTAL(9,AA11:AA12) -> 9091.3003 | AB13: =Y13-Z13 -> -211.88325 | AC13: =Y13-AA13 -> 1316.1403 | AD13: =IFERROR((Y13-Z13)/ABS(Z13),0) -> -0.019952612 | AE13: =IFERROR((Y13-AA13)/ABS(AA13),0) -> 0.1447692 | AG13: =SUBTOTAL(9,AG11:AG12) -> -147.78694 | AH13: =SUBTOTAL(9,AH11:AH12) -> -250.17519 | AI13: =SUBTOTAL(9,AI11:AI12) -> -268.41669 | AJ13: =AG13-AH13 -> 102.38825 | AK13: =AG13-AI13 -> 120.62975 | AL13: =IFERROR((AG13-AH13)/ABS(AH13),0) -> 0.4092662 | AM13: =IFERROR((AG13-AI13)/ABS(AI13),0) -> 0.44941226 | AO13: =SUBTOTAL(9,AO11:AO12) -> -666.26555 | AP13: =SUBTOTAL(9,AP11:AP12) -> -755.79246 | AQ13: =SUBTOTAL(9,AQ11:AQ12) -> -593.73454 | AR13: =AO13-AP13 -> 89.52691 | AS13: =AO13-AQ13 -> -72.53101 | AT13: =IFERROR((AO13-AP13)/ABS(AP13),0) -> 0.11845436 | AU13: =IFERROR((AO13-AQ13)/ABS(AQ13),0) -> -0.12216067 | AW13: =SUBTOTAL(9,AW11:AW12) -> 9593.3881 | AX13: =SUBTOTAL(9,AX11:AX12) -> 9613.3562 | AY13: =SUBTOTAL(9,AY11:AY12) -> 8229.1491 | AZ13: =AW13-AX13 -> -19.96809 | BA13: =AW13-AY13 -> 1364.239 | BB13: =IFERROR((AW13-AX13)/ABS(AX13),0) -> -0.0020771195 | BC13: =IFERROR((AW13-AY13)/ABS(AY13),0) -> 0.16578129 | BE13: =SUBTOTAL(9,BE11:BE12) -> -3219.3773 | BF13: =SUBTOTAL(9,BF11:BF12) -> -3164.3538 | BG13: =SUBTOTAL(9,BG11:BG12) -> -3135.3055 | BH13: =BE13-BF13 -> -55.02354 | BI13: =BE13-BG13 -> -84.07188 | BJ13: =IFERROR((BE13-BF13)/ABS(BF13),0) -> -0.017388555 | BK13: =IFERROR((BE13-BG13)/ABS(BG13),0) -> -0.026814574 | BM13: =SUBTOTAL(9,BM11:BM12) -> -623.56517 | BN13: =SUBTOTAL(9,BN11:BN12) -> -764.54848 | BO13: =SUBTOTAL(9,BO11:BO12) -> -790.21732 | BP13: =BM13-BN13 -> 140.98331 | BQ13: =BM13-BO13 -> 166.65215 | BR13: =IFERROR((BM13-BN13)/ABS(BN13),0) -> 0.18440075 | BS13: =IFERROR((BM13-BO13)/ABS(BO13),0) -> 0.21089407 | BU13: =SUBTOTAL(9,BU11:BU12) -> -1783.1365 | BV13: =SUBTOTAL(9,BV11:BV12) -> -1748.5933 | BW13: =SUBTOTAL(9,BW11:BW12) -> -1748.5933 | BX13: =BU13-BV13 -> -34.54325 | BY13: =BU13-BW13 -> -34.54325 | BZ13: =IFERROR((BU13-BV13)/ABS(BV13),0) -> -0.01975488 | CA13: =IFERROR((BU13-BW13)/ABS(BW13),0) -> -0.01975488 | CC13: =SUBTOTAL(9,CC11:CC12) -> 3967.3091 | CD13: =SUBTOTAL(9,CD11:CD12) -> 3935.8606 | CE13: =SUBTOTAL(9,CE11:CE12) -> 2555.033 | CF13: =CC13-CD13 -> 31.44843 | CG13: =CC13-CE13 -> 1412.276 | CH13: =IFERROR((CC13-CD13)/ABS(CD13),0) -> 0.0079902296 | CI13: =IFERROR((CC13-CE13)/ABS(CE13),0) -> 0.55274276 | CK13: =SUBTOTAL(9,CK11:CK12) -> -1303.8431 | CL13: =SUBTOTAL(9,CL11:CL12) -> -1064.9465 | CM13: =SUBTOTAL(9,CM11:CM12) -> -580.30291 | CN13: =CK13-CL13 -> -238.89659 | CO13: =CK13-CM13 -> -723.54017 | CP13: =IFERROR((CK13-CL13)/ABS(CL13),0) -> -0.22432732 | CQ13: =IFERROR((CK13-CM13)/ABS(CM13),0) -> -1.2468319 | CS13: =SUBTOTAL(9,CS11:CS12) -> 2663.466 | CT13: =SUBTOTAL(9,CT11:CT12) -> 2870.9141 | CU13: =SUBTOTAL(9,CU11:CU12) -> 1974.7301 | CV13: =SUBTOTAL(9,CV11:CV12) -> -207.44816 | CW13: =SUBTOTAL(9,CW11:CW12) -> 688.73584 | CX13: =IFERROR((CS13-CT13)/ABS(CT13),0) -> -0.072258574 | CY13: =IFERROR((CS13-CU13)/ABS(CU13),0) -> 0.34877467
B14: Central | C14: Qassim | D14: 301 | E14: Onaizah | F14: Hyper | G14: LFL | I14: =SUMIFS('P&L Data'!$N:$N,'P&L Data'!$B:$B,$D14,'P&L Data'!$C:$C,$I$4) -> 20166.618 | J14: =SUMIFS('P&L Data'!$P:$P,'P&L Data'!$B:$B,$D14,'P&L Data'!$C:$C,$I$4) -> 20608.775 | K14: =SUMIFS('P&L Data'!$T:$T,'P&L Data'!$B:$B,$D14,'P&L Data'!$C:$C,$I$4) -> 20798.271 | L14: =I14-J14 -> -442.15676 | M14: =I14-K14 -> -631.65294 | N14: =IFERROR((I14-J14)/ABS(J14),0) -> -0.021454781 | O14: =IFERROR((I14-K14)/ABS(K14),0) -> -0.030370454 | Q14: =SUMIFS('P&L Data'!$N:$N,'P&L Data'!$B:$B,$D14,'P&L Data'!$C:$C,$Q$4) -> 142.45983 | R14: =SUMIFS('P&L Data'!$P:$P,'P&L Data'!$B:$B,$D14,'P&L Data'!$C:$C,$Q$4) -> 788.26615 | S14: =SUMIFS('P&L Data'!$T:$T,'P&L Data'!$B:$B,$D14,'P&L Data'!$C:$C,$Q$4) -> 1019.4979 | T14: =Q14-R14 -> -645.80632 | U14: =Q14-S14 -> -877.03808 | V14: =IFERROR((Q14-R14)/ABS(R14),0) -> -0.81927445 | W14: =IFERROR((Q14-S14)/ABS(S14),0) -> -0.86026472 | Y14: =SUMIFS('P&L Data'!$N:$N,'P&L Data'!$B:$B,$D14,'P&L Data'!$C:$C,$Y$4) -> 4155.4767 | Z14: =SUMIFS('P&L Data'!$P:$P,'P&L Data'!$B:$B,$D14,'P&L Data'!$C:$C,$Y$4) -> 4738.9749 | AA14: =SUMIFS('P&L Data'!$T:$T,'P&L Data'!$B:$B,$D14,'P&L Data'!$C:$C,$Y$4) -> 4786.886 | AB14: =Y14-Z14 -> -583.49819 | AC14: =Y14-AA14 -> -631.40932 | AD14: =IFERROR((Y14-Z14)/ABS(Z14),0) -> -0.12312751 | AE14: =IFERROR((Y14-AA14)/ABS(AA14),0) -> -0.13190398 | AG14: =SUMIFS('P&L Data'!$N:$N,'P&L Data'!$B:$B,$D14,'P&L Data'!$C:$C,$AG$4) -> -64.47421 | AH14: =SUMIFS('P&L Data'!$P:$P,'P&L Data'!$B:$B,$D14,'P&L Data'!$C:$C,$AG$4) -> -127.8963 | AI14: =SUMIFS('P&L Data'!$T:$T,'P&L Data'!$B:$B,$D14,'P&L Data'!$C:$C,$AG$4) -> -83.77442 | AJ14: =AG14-AH14 -> 63.42209 | AK14: =AG14-AI14 -> 19.30021 | AL14: =IFERROR((AG14-AH14)/ABS(AH14),0) -> 0.49588682 | AM14: =IFERROR((AG14-AI14)/ABS(AI14),0) -> 0.23038309 | AO14: =SUMIFS('P&L Data'!$N:$N,'P&L Data'!$B:$B,$D14,'P&L Data'!$C:$C,$AO$4) -> -345.70857 | AP14: =SUMIFS('P&L Data'!$P:$P,'P&L Data'!$B:$B,$D14,'P&L Data'!$C:$C,$AO$4) -> -383.32547 | AQ14: =SUMIFS('P&L Data'!$T:$T,'P&L Data'!$B:$B,$D14,'P&L Data'!$C:$C,$AO$4) -> -347.02352 | AR14: =AO14-AP14 -> 37.6169 | AS14: =AO14-AQ14 -> 1.31495 | AT14: =IFERROR((AO14-AP14)/ABS(AP14),0) -> 0.098133056 | AU14: =IFERROR((AO14-AQ14)/ABS(AQ14),0) -> 0.0037892244 | AW14: =SUMIFS('P&L Data'!$N:$N,'P&L Data'!$B:$B,$D14,'P&L Data'!$C:$C,$AW$4) -> 3745.2939 | AX14: =SUMIFS('P&L Data'!$P:$P,'P&L Data'!$B:$B,$D14,'P&L Data'!$C:$C,$AW$4) -> 4227.7532 | AY14: =SUMIFS('P&L Data'!$T:$T,'P&L Data'!$B:$B,$D14,'P&L Data'!$C:$C,$AW$4) -> 4356.0881 | AZ14: =AW14-AX14 -> -482.4592 | BA14: =AW14-AY14 -> -610.79416 | BB14: =IFERROR((AW14-AX14)/ABS(AX14),0) -> -0.11411716 | BC14: =IFERROR((AW14-AY14)/ABS(AY14),0) -> -0.14021621 | BE14: =SUMIFS('P&L Data'!$N:$N,'P&L Data'!$B:$B,$D14,'P&L Data'!$C:$C,$BE$4) -> -1635.6885 | BF14: =SUMIFS('P&L Data'!$P:$P,'P&L Data'!$B:$B,$D14,'P&L Data'!$C:$C,$BE$4) -> -1420.4467 | BG14: =SUMIFS('P&L Data'!$T:$T,'P&L Data'!$B:$B,$D14,'P&L Data'!$C:$C,$BE$4) -> -1572.5023 | BH14: =BE14-BF14 -> -215.24186 | BI14: =BE14-BG14 -> -63.18625 | BJ14: =IFERROR((BE14-BF14)/ABS(BF14),0) -> -0.15153111 | BK14: =IFERROR((BE14-BG14)/ABS(BG14),0) -> -0.040181977 | BM14: =SUMIFS('P&L Data'!$N:$N,'P&L Data'!$B:$B,$D14,'P&L Data'!$C:$C,$BM$4) -> -388.83962 | BN14: =SUMIFS('P&L Data'!$P:$P,'P&L Data'!$B:$B,$D14,'P&L Data'!$C:$C,$BM$4) -> -475.52009 | BO14: =SUMIFS('P&L Data'!$T:$T,'P&L Data'!$B:$B,$D14,'P&L Data'!$C:$C,$BM$4) -> -473.40409 | BP14: =BM14-BN14 -> 86.68047 | BQ14: =BM14-BO14 -> 84.56447 | BR14: =IFERROR((BM14-BN14)/ABS(BN14),0) -> 0.18228561 | BS14: =IFERROR((BM14-BO14)/ABS(BO14),0) -> 0.17863063 | BU14: =SUMIFS('P&L Data'!$N:$N,'P&L Data'!$B:$B,$D14,'P&L Data'!$C:$C,$BU$4) -> -900 | BV14: =SUMIFS('P&L Data'!$P:$P,'P&L Data'!$B:$B,$D14,'P&L Data'!$C:$C,$BU$4) -> -900 | BW14: =SUMIFS('P&L Data'!$T:$T,'P&L Data'!$B:$B,$D14,'P&L Data'!$C:$C,$BU$4) -> -900 | BX14: =BU14-BV14 -> 0 | BY14: =BU14-BW14 -> 0 | BZ14: =IFERROR((BU14-BV14)/ABS(BV14),0) -> 0 | CA14: =IFERROR((BU14-BW14)/ABS(BW14),0) -> 0 | CC14: =SUMIFS('P&L Data'!$N:$N,'P&L Data'!$B:$B,$D14,'P&L Data'!$C:$C,$CC$4) -> 820.76581 | CD14: =SUMIFS('P&L Data'!$P:$P,'P&L Data'!$B:$B,$D14,'P&L Data'!$C:$C,$CC$4) -> 1431.7864 | CE14: =SUMIFS('P&L Data'!$T:$T,'P&L Data'!$B:$B,$D14,'P&L Data'!$C:$C,$CC$4) -> 1410.1817 | CF14: =CC14-CD14 -> -611.02059 | CG14: =CC14-CE14 -> -589.41594 | CH14: =IFERROR((CC14-CD14)/ABS(CD14),0) -> -0.42675401 | CI14: =IFERROR((CC14-CE14)/ABS(CE14),0) -> -0.41797161 | CK14: =SUMIFS('P&L Data'!$N:$N,'P&L Data'!$B:$B,$D14,'P&L Data'!$C:$C,$CK$4) -> -680.79158 | CL14: =SUMIFS('P&L Data'!$P:$P,'P&L Data'!$B:$B,$D14,'P&L Data'!$C:$C,$CK$4) -> -587.51643 | CM14: =SUMIFS('P&L Data'!$T:$T,'P&L Data'!$B:$B,$D14,'P&L Data'!$C:$C,$CK$4) -> -282.33336 | CN14: =CK14-CL14 -> -93.27515 | CO14: =CK14-CM14 -> -398.45822 | CP14: =IFERROR((CK14-CL14)/ABS(CL14),0) -> -0.15876177 | CQ14: =IFERROR((CK14-CM14)/ABS(CM14),0) -> -1.4113041 | CS14: =SUMIFS('P&L Data'!$N:$N,'P&L Data'!$B:$B,$D14,'P&L Data'!$C:$C,$CS$4) -> 139.97423 | CT14: =SUMIFS('P&L Data'!$P:$P,'P&L Data'!$B:$B,$D14,'P&L Data'!$C:$C,$CS$4) -> 844.26997 | CU14: =SUMIFS('P&L Data'!$T:$T,'P&L Data'!$B:$B,$D14,'P&L Data'!$C:$C,$CS$4) -> 1127.8484 | CV14: =CS14-CT14 -> -704.29574 | CW14: =CS14-CU14 -> -987.87416 | CX14: =IFERROR((CS14-CT14)/ABS(CT14),0) -> -0.83420679 | CY14: =IFERROR((CS14-CU14)/ABS(CU14),0) -> -0.87589269
B15: Central | C15: Qassim | D15: 30001 | E15: Shahinat | F15: Hyper | G15: LFL | I15: =SUMIFS('P&L Data'!$N:$N,'P&L Data'!$B:$B,$D15,'P&L Data'!$C:$C,$I$4) -> 24579.436 | J15: =SUMIFS('P&L Data'!$P:$P,'P&L Data'!$B:$B,$D15,'P&L Data'!$C:$C,$I$4) -> 21051.442 | K15: =SUMIFS('P&L Data'!$T:$T,'P&L Data'!$B:$B,$D15,'P&L Data'!$C:$C,$I$4) -> 21915.011 | L15: =I15-J15 -> 3527.9944 | M15: =I15-K15 -> 2664.4253 | N15: =IFERROR((I15-J15)/ABS(J15),0) -> 0.16758921 | O15: =IFERROR((I15-K15)/ABS(K15),0) -> 0.12157992 | Q15: =SUMIFS('P&L Data'!$N:$N,'P&L Data'!$B:$B,$D15,'P&L Data'!$C:$C,$Q$4) -> -682.91545 | R15: =SUMIFS('P&L Data'!$P:$P,'P&L Data'!$B:$B,$D15,'P&L Data'!$C:$C,$Q$4) -> 424.78107 | S15: =SUMIFS('P&L Data'!$T:$T,'P&L Data'!$B:$B,$D15,'P&L Data'!$C:$C,$Q$4) -> 172.64294 | T15: =Q15-R15 -> -1107.6965 | U15: =Q15-S15 -> -855.55839 | V15: =IFERROR((Q15-R15)/ABS(R15),0) -> -2.607688 | W15: =IFERROR((Q15-S15)/ABS(S15),0) -> -4.9556522 | Y15: =SUMIFS('P&L Data'!$N:$N,'P&L Data'!$B:$B,$D15,'P&L Data'!$C:$C,$Y$4) -> 4328.5222 | Z15: =SUMIFS('P&L Data'!$P:$P,'P&L Data'!$B:$B,$D15,'P&L Data'!$C:$C,$Y$4) -> 4502.6572 | AA15: =SUMIFS('P&L Data'!$T:$T,'P&L Data'!$B:$B,$D15,'P&L Data'!$C:$C,$Y$4) -> 4134.3655 | AB15: =Y15-Z15 -> -174.13499 | AC15: =Y15-AA15 -> 194.15671 | AD15: =IFERROR((Y15-Z15)/ABS(Z15),0) -> -0.038673828 | AE15: =IFERROR((Y15-AA15)/ABS(AA15),0) -> 0.046961669 | AG15: =SUMIFS('P&L Data'!$N:$N,'P&L Data'!$B:$B,$D15,'P&L Data'!$C:$C,$AG$4) -> -114.11238 | AH15: =SUMIFS('P&L Data'!$P:$P,'P&L Data'!$B:$B,$D15,'P&L Data'!$C:$C,$AG$4) -> -133.42294 | AI15: =SUMIFS('P&L Data'!$T:$T,'P&L Data'!$B:$B,$D15,'P&L Data'!$C:$C,$AG$4) -> -144.53654 | AJ15: =AG15-AH15 -> 19.31056 | AK15: =AG15-AI15 -> 30.42416 | AL15: =IFERROR((AG15-AH15)/ABS(AH15),0) -> 0.14473193 | AM15: =IFERROR((AG15-AI15)/ABS(AI15),0) -> 0.21049459 | AO15: =SUMIFS('P&L Data'!$N:$N,'P&L Data'!$B:$B,$D15,'P&L Data'!$C:$C,$AO$4) -> -368.66323 | AP15: =SUMIFS('P&L Data'!$P:$P,'P&L Data'!$B:$B,$D15,'P&L Data'!$C:$C,$AO$4) -> -380.34316 | AQ15: =SUMIFS('P&L Data'!$T:$T,'P&L Data'!$B:$B,$D15,'P&L Data'!$C:$C,$AO$4) -> -334.17028 | AR15: =AO15-AP15 -> 11.67993 | AS15: =AO15-AQ15 -> -34.49295 | AT15: =IFERROR((AO15-AP15)/ABS(AP15),0) -> 0.030708926 | AU15: =IFERROR((AO15-AQ15)/ABS(AQ15),0) -> -0.10321968 | AW15: =SUMIFS('P&L Data'!$N:$N,'P&L Data'!$B:$B,$D15,'P&L Data'!$C:$C,$AW$4) -> 3845.7466 | AX15: =SUMIFS('P&L Data'!$P:$P,'P&L Data'!$B:$B,$D15,'P&L Data'!$C:$C,$AW$4) -> 3988.8911 | AY15: =SUMIFS('P&L Data'!$T:$T,'P&L Data'!$B:$B,$D15,'P&L Data'!$C:$C,$AW$4) -> 3655.6587 | AZ15: =AW15-AX15 -> -143.1445 | BA15: =AW15-AY15 -> 190.08792 | BB15: =IFERROR((AW15-AX15)/ABS(AX15),0) -> -0.035885788 | BC15: =IFERROR((AW15-AY15)/ABS(AY15),0) -> 0.051998266 | BE15: =SUMIFS('P&L Data'!$N:$N,'P&L Data'!$B:$B,$D15,'P&L Data'!$C:$C,$BE$4) -> -1663.3596 | BF15: =SUMIFS('P&L Data'!$P:$P,'P&L Data'!$B:$B,$D15,'P&L Data'!$C:$C,$BE$4) -> -1512.2225 | BG15: =SUMIFS('P&L Data'!$T:$T,'P&L Data'!$B:$B,$D15,'P&L Data'!$C:$C,$BE$4) -> -1601.4968 | BH15: =BE15-BF15 -> -151.13714 | BI15: =BE15-BG15 -> -61.86286 | BJ15: =IFERROR((BE15-BF15)/ABS(BF15),0) -> -0.09994372 | BK15: =IFERROR((BE15-BG15)/ABS(BG15),0) -> -0.038628152 | BM15: =SUMIFS('P&L Data'!$N:$N,'P&L Data'!$B:$B,$D15,'P&L Data'!$C:$C,$BM$4) -> -811.59696 | BN15: =SUMIFS('P&L Data'!$P:$P,'P&L Data'!$B:$B,$D15,'P&L Data'!$C:$C,$BM$4) -> -779.42964 | BO15: =SUMIFS('P&L Data'!$T:$T,'P&L Data'!$B:$B,$D15,'P&L Data'!$C:$C,$BM$4) -> -809.01016 | BP15: =BM15-BN15 -> -32.16732 | BQ15: =BM15-BO15 -> -2.5868 | BR15: =IFERROR((BM15-BN15)/ABS(BN15),0) -> -0.041270332 | BS15: =IFERROR((BM15-BO15)/ABS(BO15),0) -> -0.0031974877 | BU15: =SUMIFS('P&L Data'!$N:$N,'P&L Data'!$B:$B,$D15,'P&L Data'!$C:$C,$BU$4) -> -1334.5253 | BV15: =SUMIFS('P&L Data'!$P:$P,'P&L Data'!$B:$B,$D15,'P&L Data'!$C:$C,$BU$4) -> -1142.817 | BW15: =SUMIFS('P&L Data'!$T:$T,'P&L Data'!$B:$B,$D15,'P&L Data'!$C:$C,$BU$4) -> -1137.585 | BX15: =BU15-BV15 -> -191.70833 | BY15: =BU15-BW15 -> -196.94039 | BZ15: =IFERROR((BU15-BV15)/ABS(BV15),0) -> -0.16775068 | CA15: =IFERROR((BU15-BW15)/ABS(BW15),0) -> -0.17312148 | CC15: =SUMIFS('P&L Data'!$N:$N,'P&L Data'!$B:$B,$D15,'P&L Data'!$C:$C,$CC$4) -> 36.2647 | CD15: =SUMIFS('P&L Data'!$P:$P,'P&L Data'!$B:$B,$D15,'P&L Data'!$C:$C,$CC$4) -> 554.42199 | CE15: =SUMIFS('P&L Data'!$T:$T,'P&L Data'!$B:$B,$D15,'P&L Data'!$C:$C,$CC$4) -> 107.56683 | CF15: =CC15-CD15 -> -518.15729 | CG15: =CC15-CE15 -> -71.302135 | CH15: =IFERROR((CC15-CD15)/ABS(CD15),0) -> -0.93459008 | CI15: =IFERROR((CC15-CE15)/ABS(CE15),0) -> -0.66286356 | CK15: =SUMIFS('P&L Data'!$N:$N,'P&L Data'!$B:$B,$D15,'P&L Data'!$C:$C,$CK$4) -> -11.08543 | CL15: =SUMIFS('P&L Data'!$P:$P,'P&L Data'!$B:$B,$D15,'P&L Data'!$C:$C,$CK$4) -> -152.68445 | CM15: =SUMIFS('P&L Data'!$T:$T,'P&L Data'!$B:$B,$D15,'P&L Data'!$C:$C,$CK$4) -> -101.86592 | CN15: =CK15-CL15 -> 141.59902 | CO15: =CK15-CM15 -> 90.78049 | CP15: =IFERROR((CK15-CL15)/ABS(CL15),0) -> 0.92739647 | CQ15: =IFERROR((CK15-CM15)/ABS(CM15),0) -> 0.89117626 | CS15: =SUMIFS('P&L Data'!$N:$N,'P&L Data'!$B:$B,$D15,'P&L Data'!$C:$C,$CS$4) -> 25.17927 | CT15: =SUMIFS('P&L Data'!$P:$P,'P&L Data'!$B:$B,$D15,'P&L Data'!$C:$C,$CS$4) -> 401.73754 | CU15: =SUMIFS('P&L Data'!$T:$T,'P&L Data'!$B:$B,$D15,'P&L Data'!$C:$C,$CS$4) -> 5.7009149 | CV15: =CS15-CT15 -> -376.55827 | CW15: =CS15-CU15 -> 19.478355 | CX15: =IFERROR((CS15-CT15)/ABS(CT15),0) -> -0.93732408 | CY15: =IFERROR((CS15-CU15)/ABS(CU15),0) -> 3.4167069
B16: Central | C16: Qassim Total | I16: =SUBTOTAL(9,I14:I15) -> 44746.055 | J16: =SUBTOTAL(9,J14:J15) -> 41660.217 | K16: =SUBTOTAL(9,K14:K15) -> 42713.282 | L16: =I16-J16 -> 3085.8377 | M16: =I16-K16 -> 2032.7723 | N16: =IFERROR((I16-J16)/ABS(J16),0) -> 0.07407157 | O16: =IFERROR((I16-K16)/ABS(K16),0) -> 0.047591106 | Q16: =SUBTOTAL(9,Q14:Q15) -> -540.45562 | R16: =SUBTOTAL(9,R14:R15) -> 1213.0472 | S16: =SUBTOTAL(9,S14:S15) -> 1192.1409 | T16: =Q16-R16 -> -1753.5028 | U16: =Q16-S16 -> -1732.5965 | V16: =IFERROR((Q16-R16)/ABS(R16),0) -> -1.4455355 | W16: =IFERROR((Q16-S16)/ABS(S16),0) -> -1.4533488 | Y16: =SUBTOTAL(9,Y14:Y15) -> 8483.999 | Z16: =SUBTOTAL(9,Z14:Z15) -> 9241.6322 | AA16: =SUBTOTAL(9,AA14:AA15) -> 8921.2516 | AB16: =Y16-Z16 -> -757.63318 | AC16: =Y16-AA16 -> -437.25261 | AD16: =IFERROR((Y16-Z16)/ABS(Z16),0) -> -0.081980452 | AE16: =IFERROR((Y16-AA16)/ABS(AA16),0) -> -0.049012474 | AG16: =SUBTOTAL(9,AG14:AG15) -> -178.58659 | AH16: =SUBTOTAL(9,AH14:AH15) -> -261.31924 | AI16: =SUBTOTAL(9,AI14:AI15) -> -228.31096 | AJ16: =AG16-AH16 -> 82.73265 | AK16: =AG16-AI16 -> 49.72437 | AL16: =IFERROR((AG16-AH16)/ABS(AH16),0) -> 0.31659609 | AM16: =IFERROR((AG16-AI16)/ABS(AI16),0) -> 0.2177923 | AO16: =SUBTOTAL(9,AO14:AO15) -> -714.3718 | AP16: =SUBTOTAL(9,AP14:AP15) -> -763.66863 | AQ16: =SUBTOTAL(9,AQ14:AQ15) -> -681.1938 | AR16: =AO16-AP16 -> 49.29683 | AS16: =AO16-AQ16 -> -33.178 | AT16: =IFERROR((AO16-AP16)/ABS(AP16),0) -> 0.064552645 | AU16: =IFERROR((AO16-AQ16)/ABS(AQ16),0) -> -0.048705669 | AW16: =SUBTOTAL(9,AW14:AW15) -> 7591.0406 | AX16: =SUBTOTAL(9,AX14:AX15) -> 8216.6443 | AY16: =SUBTOTAL(9,AY14:AY15) -> 8011.7468 | AZ16: =AW16-AX16 -> -625.6037 | BA16: =AW16-AY16 -> -420.70624 | BB16: =IFERROR((AW16-AX16)/ABS(AX16),0) -> -0.076138589 | BC16: =IFERROR((AW16-AY16)/ABS(AY16),0) -> -0.052511175 | BE16: =SUBTOTAL(9,BE14:BE15) -> -3299.0481 | BF16: =SUBTOTAL(9,BF14:BF15) -> -2932.6691 | BG16: =SUBTOTAL(9,BG14:BG15) -> -3173.999 | BH16: =BE16-BF16 -> -366.379 | BI16: =BE16-BG16 -> -125.04911 | BJ16: =IFERROR((BE16-BF16)/ABS(BF16),0) -> -0.12493022 | BK16: =IFERROR((BE16-BG16)/ABS(BG16),0) -> -0.039397967 | BM16: =SUBTOTAL(9,BM14:BM15) -> -1200.4366 | BN16: =SUBTOTAL(9,BN14:BN15) -> -1254.9497 | BO16: =SUBTOTAL(9,BO14:BO15) -> -1282.4142 | BP16: =BM16-BN16 -> 54.51315 | BQ16: =BM16-BO16 -> 81.97767 | BR16: =IFERROR((BM16-BN16)/ABS(BN16),0) -> 0.043438513 | BS16: =IFERROR((BM16-BO16)/ABS(BO16),0) -> 0.063924485 | BU16: =SUBTOTAL(9,BU14:BU15) -> -2234.5253 | BV16: =SUBTOTAL(9,BV14:BV15) -> -2042.817 | BW16: =SUBTOTAL(9,BW14:BW15) -> -2037.585 | BX16: =BU16-BV16 -> -191.70833 | BY16: =BU16-BW16 -> -196.94039 | BZ16: =IFERROR((BU16-BV16)/ABS(BV16),0) -> -0.093845082 | CA16: =IFERROR((BU16-BW16)/ABS(BW16),0) -> -0.09665383 | CC16: =SUBTOTAL(9,CC14:CC15) -> 857.03051 | CD16: =SUBTOTAL(9,CD14:CD15) -> 1986.2084 | CE16: =SUBTOTAL(9,CE14:CE15) -> 1517.7486 | CF16: =CC16-CD16 -> -1129.1779 | CG16: =CC16-CE16 -> -660.71807 | CH16: =IFERROR((CC16-CD16)/ABS(CD16),0) -> -0.56850927 | CI16: =IFERROR((CC16-CE16)/ABS(CE16),0) -> -0.43532775 | CK16: =SUBTOTAL(9,CK14:CK15) -> -691.87701 | CL16: =SUBTOTAL(9,CL14:CL15) -> -740.20088 | CM16: =SUBTOTAL(9,CM14:CM15) -> -384.19928 | CN16: =CK16-CL16 -> 48.32387 | CO16: =CK16-CM16 -> -307.67773 | CP16: =IFERROR((CK16-CL16)/ABS(CL16),0) -> 0.065284805 | CQ16: =IFERROR((CK16-CM16)/ABS(CM16),0) -> -0.80082849 | CS16: =SUBTOTAL(9,CS14:CS15) -> 165.1535 | CT16: =SUBTOTAL(9,CT14:CT15) -> 1246.0075 | CU16: =SUBTOTAL(9,CU14:CU15) -> 1133.5493 | CV16: =SUBTOTAL(9,CV14:CV15) -> -1080.854 | CW16: =SUBTOTAL(9,CW14:CW15) -> -968.3958 | CX16: =IFERROR((CS16-CT16)/ABS(CT16),0) -> -0.86745385 | CY16: =IFERROR((CS16-CU16)/ABS(CU16),0) -> -0.85430409
B17: Central Total | I17: =SUBTOTAL(9,I6:I16) -> 170116.49 | J17: =SUBTOTAL(9,J6:J16) -> 164055.49 | K17: =SUBTOTAL(9,K6:K16) -> 161484.91 | L17: =I17-J17 -> 6061.0004 | M17: =I17-K17 -> 8631.5816 | N17: =IFERROR((I17-J17)/ABS(J17),0) -> 0.036944819 | O17: =IFERROR((I17-K17)/ABS(K17),0) -> 0.05345132 | Q17: =SUBTOTAL(9,Q6:Q16) -> 7240.0801 | R17: =SUBTOTAL(9,R6:R16) -> 9427.9145 | S17: =SUBTOTAL(9,S6:S16) -> 8978.8421 | T17: =Q17-R17 -> -2187.8344 | U17: =Q17-S17 -> -1738.762 | V17: =IFERROR((Q17-R17)/ABS(R17),0) -> -0.23205921 | W17: =IFERROR((Q17-S17)/ABS(S17),0) -> -0.19365103 | Y17: =SUBTOTAL(9,Y6:Y16) -> 41294.318 | Z17: =SUBTOTAL(9,Z6:Z16) -> 41079.44 | AA17: =SUBTOTAL(9,AA6:AA16) -> 38311.266 | AB17: =Y17-Z17 -> 214.87883 | AC17: =Y17-AA17 -> 2983.0522 | AD17: =IFERROR((Y17-Z17)/ABS(Z17),0) -> 0.0052308121 | AE17: =IFERROR((Y17-AA17)/ABS(AA17),0) -> 0.077863575 | AG17: =SUBTOTAL(9,AG6:AG16) -> -651.57557 | AH17: =SUBTOTAL(9,AH6:AH16) -> -1003.0432 | AI17: =SUBTOTAL(9,AI6:AI16) -> -935.56187 | AJ17: =AG17-AH17 -> 351.46766 | AK17: =AG17-AI17 -> 283.9863 | AL17: =IFERROR((AG17-AH17)/ABS(AH17),0) -> 0.35040131 | AM17: =IFERROR((AG17-AI17)/ABS(AI17),0) -> 0.30354625 | AO17: =SUBTOTAL(9,AO6:AO16) -> -2803.2503 | AP17: =SUBTOTAL(9,AP6:AP16) -> -3034.7315 | AQ17: =SUBTOTAL(9,AQ6:AQ16) -> -2536.253 | AR17: =AO17-AP17 -> 231.48118 | AS17: =AO17-AQ17 -> -266.99726 | AT17: =IFERROR((AO17-AP17)/ABS(AP17),0) -> 0.076277319 | AU17: =IFERROR((AO17-AQ17)/ABS(AQ17),0) -> -0.10527233 | AW17: =SUBTOTAL(9,AW6:AW16) -> 37839.492 | AX17: =SUBTOTAL(9,AX6:AX16) -> 37041.665 | AY17: =SUBTOTAL(9,AY6:AY16) -> 34839.451 | AZ17: =AW17-AX17 -> 797.82767 | BA17: =AW17-AY17 -> 3000.0412 | BB17: =IFERROR((AW17-AX17)/ABS(AX17),0) -> 0.021538656 | BC17: =IFERROR((AW17-AY17)/ABS(AY17),0) -> 0.086110461 | BE17: =SUBTOTAL(9,BE6:BE16) -> -12574.453 | BF17: =SUBTOTAL(9,BF6:BF16) -> -12098.019 | BG17: =SUBTOTAL(9,BG6:BG16) -> -12277.018 | BH17: =BE17-BF17 -> -476.43417 | BI17: =BE17-BG17 -> -297.43511 | BJ17: =IFERROR((BE17-BF17)/ABS(BF17),0) -> -0.039381172 | BK17: =IFERROR((BE17-BG17)/ABS(BG17),0) -> -0.024226983 | BM17: =SUBTOTAL(9,BM6:BM16) -> -4671.4194 | BN17: =SUBTOTAL(9,BN6:BN16) -> -4893.5996 | BO17: =SUBTOTAL(9,BO6:BO16) -> -5074.1049 | BP17: =BM17-BN17 -> 222.18019 | BQ17: =BM17-BO17 -> 402.68558 | BR17: =IFERROR((BM17-BN17)/ABS(BN17),0) -> 0.045402201 | BS17: =IFERROR((BM17-BO17)/ABS(BO17),0) -> 0.079360909 | BU17: =SUBTOTAL(9,BU6:BU16) -> -8490.5138 | BV17: =SUBTOTAL(9,BV6:BV16) -> -7871.2008 | BW17: =SUBTOTAL(9,BW6:BW16) -> -8256.8976 | BX17: =BU17-BV17 -> -619.31302 | BY17: =BU17-BW17 -> -233.61622 | BZ17: =IFERROR((BU17-BV17)/ABS(BV17),0) -> -0.078680882 | CA17: =IFERROR((BU17-BW17)/ABS(BW17),0) -> -0.028293462 | CC17: =SUBTOTAL(9,CC6:CC16) -> 12103.106 | CD17: =SUBTOTAL(9,CD6:CD16) -> 12178.845 | CE17: =SUBTOTAL(9,CE6:CE16) -> 9231.4307 | CF17: =CC17-CD17 -> -75.73933 | CG17: =CC17-CE17 -> 2871.6755 | CH17: =IFERROR((CC17-CD17)/ABS(CD17),0) -> -0.0062189253 | CI17: =IFERROR((CC17-CE17)/ABS(CE17),0) -> 0.31107588 | CK17: =SUBTOTAL(9,CK6:CK16) -> -4534.6968 | CL17: =SUBTOTAL(9,CL6:CL16) -> -3938.4147 | CM17: =SUBTOTAL(9,CM6:CM16) -> -3442.1743 | CN17: =CK17-CL17 -> -596.28207 | CO17: =CK17-CM17 -> -1092.5225 | CP17: =IFERROR((CK17-CL17)/ABS(CL17),0) -> -0.15140154 | CQ17: =IFERROR((CK17-CM17)/ABS(CM17),0) -> -0.31739316 | CS17: =SUBTOTAL(9,CS6:CS16) -> 7568.4094 | CT17: =SUBTOTAL(9,CT6:CT16) -> 8240.4308 | CU17: =SUBTOTAL(9,CU6:CU16) -> 5789.2564 | CV17: =SUBTOTAL(9,CV6:CV16) -> -672.0214 | CW17: =SUBTOTAL(9,CW6:CW16) -> 1779.1529 | CX17: =IFERROR((CS17-CT17)/ABS(CT17),0) -> -0.081551732 | CY17: =IFERROR((CS17-CU17)/ABS(CU17),0) -> 0.30731976
